[2024-05-21T15:28:43.462+0000] {processor.py:156} INFO - Started process (PID=35) to work on /opt/airflow/dags/dags1.py
[2024-05-21T15:28:43.462+0000] {processor.py:758} INFO - Processing file /opt/airflow/dags/dags1.py for tasks to queue
[2024-05-21T15:28:43.463+0000] {logging_mixin.py:117} INFO - [2024-05-21T15:28:43.462+0000] {dagbag.py:525} INFO - Filling up the DagBag from /opt/airflow/dags/dags1.py
[2024-05-21T15:28:45.230+0000] {logging_mixin.py:117} INFO - [2024-05-21T15:28:45.226+0000] {dagbag.py:330} ERROR - Failed to import: /opt/airflow/dags/dags1.py
Traceback (most recent call last):
  File "/home/airflow/.local/lib/python3.7/site-packages/airflow/models/dagbag.py", line 326, in parse
    loader.exec_module(new_module)
  File "<frozen importlib._bootstrap_external>", line 728, in exec_module
  File "<frozen importlib._bootstrap>", line 219, in _call_with_frames_removed
  File "/opt/airflow/dags/dags1.py", line 10, in <module>
    from dags.transform_script import transfrom
ModuleNotFoundError: No module named 'dags'
[2024-05-21T15:28:45.231+0000] {processor.py:770} WARNING - No viable dags retrieved from /opt/airflow/dags/dags1.py
[2024-05-21T15:28:45.258+0000] {processor.py:178} INFO - Processing /opt/airflow/dags/dags1.py took 1.797 seconds
[2024-05-21T15:29:15.445+0000] {processor.py:156} INFO - Started process (PID=49) to work on /opt/airflow/dags/dags1.py
[2024-05-21T15:29:15.465+0000] {processor.py:758} INFO - Processing file /opt/airflow/dags/dags1.py for tasks to queue
[2024-05-21T15:29:15.476+0000] {logging_mixin.py:117} INFO - [2024-05-21T15:29:15.475+0000] {dagbag.py:525} INFO - Filling up the DagBag from /opt/airflow/dags/dags1.py
[2024-05-21T15:29:27.018+0000] {logging_mixin.py:117} INFO - [2024-05-21T15:29:26.984+0000] {dagbag.py:330} ERROR - Failed to import: /opt/airflow/dags/dags1.py
Traceback (most recent call last):
  File "/home/airflow/.local/lib/python3.7/site-packages/airflow/models/dagbag.py", line 326, in parse
    loader.exec_module(new_module)
  File "<frozen importlib._bootstrap_external>", line 728, in exec_module
  File "<frozen importlib._bootstrap>", line 219, in _call_with_frames_removed
  File "/opt/airflow/dags/dags1.py", line 10, in <module>
    from dags.transform_script import transfrom
ModuleNotFoundError: No module named 'dags'
[2024-05-21T15:29:27.044+0000] {processor.py:770} WARNING - No viable dags retrieved from /opt/airflow/dags/dags1.py
[2024-05-21T15:29:58.589+0000] {processor.py:156} INFO - Started process (PID=63) to work on /opt/airflow/dags/dags1.py
[2024-05-21T15:29:58.596+0000] {processor.py:758} INFO - Processing file /opt/airflow/dags/dags1.py for tasks to queue
[2024-05-21T15:29:58.601+0000] {logging_mixin.py:117} INFO - [2024-05-21T15:29:58.600+0000] {dagbag.py:525} INFO - Filling up the DagBag from /opt/airflow/dags/dags1.py
[2024-05-21T15:30:53.870+0000] {processor.py:156} INFO - Started process (PID=76) to work on /opt/airflow/dags/dags1.py
[2024-05-21T15:30:53.888+0000] {processor.py:758} INFO - Processing file /opt/airflow/dags/dags1.py for tasks to queue
[2024-05-21T15:30:53.900+0000] {logging_mixin.py:117} INFO - [2024-05-21T15:30:53.899+0000] {dagbag.py:525} INFO - Filling up the DagBag from /opt/airflow/dags/dags1.py
[2024-05-21T15:34:10.686+0000] {processor.py:156} INFO - Started process (PID=81) to work on /opt/airflow/dags/dags1.py
[2024-05-21T15:34:10.710+0000] {processor.py:758} INFO - Processing file /opt/airflow/dags/dags1.py for tasks to queue
[2024-05-21T15:34:10.741+0000] {logging_mixin.py:117} INFO - [2024-05-21T15:34:10.725+0000] {dagbag.py:525} INFO - Filling up the DagBag from /opt/airflow/dags/dags1.py
[2024-05-21T15:34:40.849+0000] {logging_mixin.py:117} INFO - [2024-05-21T15:34:40.844+0000] {timeout.py:68} ERROR - Process timed out, PID: 81
[2024-05-21T15:34:40.858+0000] {logging_mixin.py:117} WARNING - Exception ignored in: <module 'collections.abc' from '/usr/local/lib/python3.7/collections/abc.py'>
[2024-05-21T15:34:40.866+0000] {logging_mixin.py:117} WARNING - Traceback (most recent call last):
[2024-05-21T15:34:40.869+0000] {logging_mixin.py:117} WARNING -   File "<string>", line 1, in <module>
[2024-05-21T15:34:40.896+0000] {logging_mixin.py:117} WARNING -   File "/home/airflow/.local/lib/python3.7/site-packages/airflow/utils/timeout.py", line 69, in handle_timeout
[2024-05-21T15:34:40.900+0000] {logging_mixin.py:117} WARNING -     raise AirflowTaskTimeout(self.error_message)
[2024-05-21T15:34:40.901+0000] {logging_mixin.py:117} WARNING - airflow.exceptions.AirflowTaskTimeout: DagBag import timeout for /opt/airflow/dags/dags1.py after 30.0s.
Please take a look at these docs to improve your DAG import time:
* https://airflow.apache.org/docs/apache-airflow/2.4.1/best-practices.html#top-level-python-code
* https://airflow.apache.org/docs/apache-airflow/2.4.1/best-practices.html#reducing-dag-complexity, PID: 81
[2024-05-21T15:34:40.959+0000] {logging_mixin.py:117} WARNING - /usr/local/lib/python3.7/importlib/_bootstrap.py:219 RuntimeWarning: Cython module failed to patch module with custom type
[2024-05-21T15:34:43.718+0000] {logging_mixin.py:117} INFO - [2024-05-21T15:34:43.589+0000] {dagbag.py:330} ERROR - Failed to import: /opt/airflow/dags/dags1.py
Traceback (most recent call last):
  File "/home/airflow/.local/lib/python3.7/site-packages/airflow/models/dagbag.py", line 326, in parse
    loader.exec_module(new_module)
  File "<frozen importlib._bootstrap_external>", line 728, in exec_module
  File "<frozen importlib._bootstrap>", line 219, in _call_with_frames_removed
  File "/opt/airflow/dags/dags1.py", line 10, in <module>
    from dags.transform_script import transfrom
ModuleNotFoundError: No module named 'dags'
[2024-05-21T15:34:43.723+0000] {processor.py:770} WARNING - No viable dags retrieved from /opt/airflow/dags/dags1.py
[2024-05-21T15:34:44.087+0000] {processor.py:178} INFO - Processing /opt/airflow/dags/dags1.py took 33.695 seconds
[2024-05-21T15:35:18.232+0000] {processor.py:156} INFO - Started process (PID=105) to work on /opt/airflow/dags/dags1.py
[2024-05-21T15:35:18.243+0000] {processor.py:758} INFO - Processing file /opt/airflow/dags/dags1.py for tasks to queue
[2024-05-21T15:35:18.246+0000] {logging_mixin.py:117} INFO - [2024-05-21T15:35:18.245+0000] {dagbag.py:525} INFO - Filling up the DagBag from /opt/airflow/dags/dags1.py
[2024-05-21T15:35:57.706+0000] {processor.py:156} INFO - Started process (PID=118) to work on /opt/airflow/dags/dags1.py
[2024-05-21T15:35:57.709+0000] {processor.py:758} INFO - Processing file /opt/airflow/dags/dags1.py for tasks to queue
[2024-05-21T15:35:57.712+0000] {logging_mixin.py:117} INFO - [2024-05-21T15:35:57.712+0000] {dagbag.py:525} INFO - Filling up the DagBag from /opt/airflow/dags/dags1.py
[2024-05-21T15:35:58.732+0000] {logging_mixin.py:117} INFO - [2024-05-21T15:35:58.720+0000] {dagbag.py:330} ERROR - Failed to import: /opt/airflow/dags/dags1.py
Traceback (most recent call last):
  File "/home/airflow/.local/lib/python3.7/site-packages/airflow/models/dagbag.py", line 326, in parse
    loader.exec_module(new_module)
  File "<frozen importlib._bootstrap_external>", line 728, in exec_module
  File "<frozen importlib._bootstrap>", line 219, in _call_with_frames_removed
  File "/opt/airflow/dags/dags1.py", line 10, in <module>
    from dags.transform_script import transfrom
ModuleNotFoundError: No module named 'dags'
[2024-05-21T15:35:58.733+0000] {processor.py:770} WARNING - No viable dags retrieved from /opt/airflow/dags/dags1.py
[2024-05-21T15:35:58.778+0000] {processor.py:178} INFO - Processing /opt/airflow/dags/dags1.py took 1.085 seconds
[2024-05-21T15:36:29.740+0000] {processor.py:156} INFO - Started process (PID=123) to work on /opt/airflow/dags/dags1.py
[2024-05-21T15:36:29.743+0000] {processor.py:758} INFO - Processing file /opt/airflow/dags/dags1.py for tasks to queue
[2024-05-21T15:36:29.744+0000] {logging_mixin.py:117} INFO - [2024-05-21T15:36:29.744+0000] {dagbag.py:525} INFO - Filling up the DagBag from /opt/airflow/dags/dags1.py
[2024-05-21T15:37:24.261+0000] {processor.py:156} INFO - Started process (PID=127) to work on /opt/airflow/dags/dags1.py
[2024-05-21T15:37:24.308+0000] {processor.py:758} INFO - Processing file /opt/airflow/dags/dags1.py for tasks to queue
[2024-05-21T15:37:24.352+0000] {logging_mixin.py:117} INFO - [2024-05-21T15:37:24.340+0000] {dagbag.py:525} INFO - Filling up the DagBag from /opt/airflow/dags/dags1.py
[2024-05-21T15:37:43.005+0000] {logging_mixin.py:117} INFO - [2024-05-21T15:37:42.773+0000] {dagbag.py:330} ERROR - Failed to import: /opt/airflow/dags/dags1.py
Traceback (most recent call last):
  File "/home/airflow/.local/lib/python3.7/site-packages/airflow/models/dagbag.py", line 326, in parse
    loader.exec_module(new_module)
  File "<frozen importlib._bootstrap_external>", line 728, in exec_module
  File "<frozen importlib._bootstrap>", line 219, in _call_with_frames_removed
  File "/opt/airflow/dags/dags1.py", line 10, in <module>
    from dags.transform_script import transfrom
ModuleNotFoundError: No module named 'dags'
[2024-05-21T15:37:43.117+0000] {processor.py:770} WARNING - No viable dags retrieved from /opt/airflow/dags/dags1.py
[2024-05-21T15:38:16.595+0000] {processor.py:156} INFO - Started process (PID=141) to work on /opt/airflow/dags/dags1.py
[2024-05-21T15:38:16.608+0000] {processor.py:758} INFO - Processing file /opt/airflow/dags/dags1.py for tasks to queue
[2024-05-21T15:38:16.616+0000] {logging_mixin.py:117} INFO - [2024-05-21T15:38:16.615+0000] {dagbag.py:525} INFO - Filling up the DagBag from /opt/airflow/dags/dags1.py
[2024-05-21T15:39:06.460+0000] {processor.py:156} INFO - Started process (PID=155) to work on /opt/airflow/dags/dags1.py
[2024-05-21T15:39:06.472+0000] {processor.py:758} INFO - Processing file /opt/airflow/dags/dags1.py for tasks to queue
[2024-05-21T15:39:06.481+0000] {logging_mixin.py:117} INFO - [2024-05-21T15:39:06.481+0000] {dagbag.py:525} INFO - Filling up the DagBag from /opt/airflow/dags/dags1.py
[2024-05-21T15:40:47.139+0000] {processor.py:156} INFO - Started process (PID=161) to work on /opt/airflow/dags/dags1.py
[2024-05-21T15:40:47.146+0000] {processor.py:758} INFO - Processing file /opt/airflow/dags/dags1.py for tasks to queue
[2024-05-21T15:40:47.147+0000] {logging_mixin.py:117} INFO - [2024-05-21T15:40:47.147+0000] {dagbag.py:525} INFO - Filling up the DagBag from /opt/airflow/dags/dags1.py
[2024-05-21T15:40:53.791+0000] {logging_mixin.py:117} INFO - [2024-05-21T15:40:53.743+0000] {dagbag.py:330} ERROR - Failed to import: /opt/airflow/dags/dags1.py
Traceback (most recent call last):
  File "/home/airflow/.local/lib/python3.7/site-packages/airflow/models/dagbag.py", line 326, in parse
    loader.exec_module(new_module)
  File "<frozen importlib._bootstrap_external>", line 728, in exec_module
  File "<frozen importlib._bootstrap>", line 219, in _call_with_frames_removed
  File "/opt/airflow/dags/dags1.py", line 10, in <module>
    from dags.transform_script import transfrom
ModuleNotFoundError: No module named 'dags'
[2024-05-21T15:40:53.796+0000] {processor.py:770} WARNING - No viable dags retrieved from /opt/airflow/dags/dags1.py
[2024-05-21T15:40:53.884+0000] {processor.py:178} INFO - Processing /opt/airflow/dags/dags1.py took 6.750 seconds
[2024-05-21T15:41:23.991+0000] {processor.py:156} INFO - Started process (PID=174) to work on /opt/airflow/dags/dags1.py
[2024-05-21T15:41:23.995+0000] {processor.py:758} INFO - Processing file /opt/airflow/dags/dags1.py for tasks to queue
[2024-05-21T15:41:23.996+0000] {logging_mixin.py:117} INFO - [2024-05-21T15:41:23.996+0000] {dagbag.py:525} INFO - Filling up the DagBag from /opt/airflow/dags/dags1.py
[2024-05-21T15:42:55.695+0000] {processor.py:156} INFO - Started process (PID=177) to work on /opt/airflow/dags/dags1.py
[2024-05-21T15:42:55.697+0000] {processor.py:758} INFO - Processing file /opt/airflow/dags/dags1.py for tasks to queue
[2024-05-21T15:42:55.699+0000] {logging_mixin.py:117} INFO - [2024-05-21T15:42:55.699+0000] {dagbag.py:525} INFO - Filling up the DagBag from /opt/airflow/dags/dags1.py
[2024-05-21T15:42:57.918+0000] {logging_mixin.py:117} INFO - [2024-05-21T15:42:57.825+0000] {dagbag.py:330} ERROR - Failed to import: /opt/airflow/dags/dags1.py
Traceback (most recent call last):
  File "/home/airflow/.local/lib/python3.7/site-packages/airflow/models/dagbag.py", line 326, in parse
    loader.exec_module(new_module)
  File "<frozen importlib._bootstrap_external>", line 728, in exec_module
  File "<frozen importlib._bootstrap>", line 219, in _call_with_frames_removed
  File "/opt/airflow/dags/dags1.py", line 10, in <module>
    from transform_script import transfrom
  File "/opt/airflow/dags/transform_script.py", line 2, in <module>
    from tqdm import tqdm
ModuleNotFoundError: No module named 'tqdm'
[2024-05-21T15:42:57.921+0000] {processor.py:770} WARNING - No viable dags retrieved from /opt/airflow/dags/dags1.py
[2024-05-21T15:43:07.967+0000] {processor.py:181} ERROR - Got an exception! Propagating...
Traceback (most recent call last):
  File "/home/airflow/.local/lib/python3.7/site-packages/sqlalchemy/engine/base.py", line 3243, in _wrap_pool_connect
    return fn()
  File "/home/airflow/.local/lib/python3.7/site-packages/sqlalchemy/pool/base.py", line 310, in connect
    return _ConnectionFairy._checkout(self)
  File "/home/airflow/.local/lib/python3.7/site-packages/sqlalchemy/pool/base.py", line 868, in _checkout
    fairy = _ConnectionRecord.checkout(pool)
  File "/home/airflow/.local/lib/python3.7/site-packages/sqlalchemy/pool/base.py", line 476, in checkout
    rec = pool._do_get()
  File "/home/airflow/.local/lib/python3.7/site-packages/sqlalchemy/pool/impl.py", line 146, in _do_get
    self._dec_overflow()
  File "/home/airflow/.local/lib/python3.7/site-packages/sqlalchemy/util/langhelpers.py", line 72, in __exit__
    with_traceback=exc_tb,
  File "/home/airflow/.local/lib/python3.7/site-packages/sqlalchemy/util/compat.py", line 207, in raise_
    raise exception
  File "/home/airflow/.local/lib/python3.7/site-packages/sqlalchemy/pool/impl.py", line 143, in _do_get
    return self._create_connection()
  File "/home/airflow/.local/lib/python3.7/site-packages/sqlalchemy/pool/base.py", line 256, in _create_connection
    return _ConnectionRecord(self)
  File "/home/airflow/.local/lib/python3.7/site-packages/sqlalchemy/pool/base.py", line 371, in __init__
    self.__connect()
  File "/home/airflow/.local/lib/python3.7/site-packages/sqlalchemy/pool/base.py", line 666, in __connect
    pool.logger.debug("Error on connect(): %s", e)
  File "/home/airflow/.local/lib/python3.7/site-packages/sqlalchemy/util/langhelpers.py", line 72, in __exit__
    with_traceback=exc_tb,
  File "/home/airflow/.local/lib/python3.7/site-packages/sqlalchemy/util/compat.py", line 207, in raise_
    raise exception
  File "/home/airflow/.local/lib/python3.7/site-packages/sqlalchemy/pool/base.py", line 661, in __connect
    self.dbapi_connection = connection = pool._invoke_creator(self)
  File "/home/airflow/.local/lib/python3.7/site-packages/sqlalchemy/engine/create.py", line 590, in connect
    return dialect.connect(*cargs, **cparams)
  File "/home/airflow/.local/lib/python3.7/site-packages/sqlalchemy/engine/default.py", line 584, in connect
    return self.dbapi.connect(*cargs, **cparams)
  File "/home/airflow/.local/lib/python3.7/site-packages/psycopg2/__init__.py", line 122, in connect
    conn = _connect(dsn, connection_factory=connection_factory, **kwasync)
psycopg2.OperationalError: could not translate host name "postgres" to address: Temporary failure in name resolution


The above exception was the direct cause of the following exception:

Traceback (most recent call last):
  File "/home/airflow/.local/lib/python3.7/site-packages/airflow/dag_processing/processor.py", line 177, in _run_file_processor
    _handle_dag_file_processing()
  File "/home/airflow/.local/lib/python3.7/site-packages/airflow/dag_processing/processor.py", line 161, in _handle_dag_file_processing
    callback_requests=callback_requests,
  File "/home/airflow/.local/lib/python3.7/site-packages/airflow/utils/session.py", line 75, in wrapper
    return func(*args, session=session, **kwargs)
  File "/home/airflow/.local/lib/python3.7/site-packages/airflow/dag_processing/processor.py", line 771, in process_file
    self.update_import_errors(session, dagbag)
  File "/home/airflow/.local/lib/python3.7/site-packages/airflow/dag_processing/processor.py", line 558, in update_import_errors
    existing_import_error_files = [x.filename for x in session.query(errors.ImportError.filename).all()]
  File "/home/airflow/.local/lib/python3.7/site-packages/sqlalchemy/orm/query.py", line 2759, in all
    return self._iter().all()
  File "/home/airflow/.local/lib/python3.7/site-packages/sqlalchemy/orm/query.py", line 2897, in _iter
    execution_options={"_sa_orm_load_options": self.load_options},
  File "/home/airflow/.local/lib/python3.7/site-packages/sqlalchemy/orm/session.py", line 1688, in execute
    conn = self._connection_for_bind(bind)
  File "/home/airflow/.local/lib/python3.7/site-packages/sqlalchemy/orm/session.py", line 1530, in _connection_for_bind
    engine, execution_options
  File "/home/airflow/.local/lib/python3.7/site-packages/sqlalchemy/orm/session.py", line 747, in _connection_for_bind
    conn = bind.connect()
  File "/home/airflow/.local/lib/python3.7/site-packages/sqlalchemy/engine/base.py", line 3197, in connect
    return self._connection_cls(self, close_with_result=close_with_result)
  File "/home/airflow/.local/lib/python3.7/site-packages/sqlalchemy/engine/base.py", line 96, in __init__
    else engine.raw_connection()
  File "/home/airflow/.local/lib/python3.7/site-packages/sqlalchemy/engine/base.py", line 3276, in raw_connection
    return self._wrap_pool_connect(self.pool.connect, _connection)
  File "/home/airflow/.local/lib/python3.7/site-packages/sqlalchemy/engine/base.py", line 3247, in _wrap_pool_connect
    e, dialect, self
  File "/home/airflow/.local/lib/python3.7/site-packages/sqlalchemy/engine/base.py", line 2101, in _handle_dbapi_exception_noconnection
    sqlalchemy_exception, with_traceback=exc_info[2], from_=e
  File "/home/airflow/.local/lib/python3.7/site-packages/sqlalchemy/util/compat.py", line 207, in raise_
    raise exception
  File "/home/airflow/.local/lib/python3.7/site-packages/sqlalchemy/engine/base.py", line 3243, in _wrap_pool_connect
    return fn()
  File "/home/airflow/.local/lib/python3.7/site-packages/sqlalchemy/pool/base.py", line 310, in connect
    return _ConnectionFairy._checkout(self)
  File "/home/airflow/.local/lib/python3.7/site-packages/sqlalchemy/pool/base.py", line 868, in _checkout
    fairy = _ConnectionRecord.checkout(pool)
  File "/home/airflow/.local/lib/python3.7/site-packages/sqlalchemy/pool/base.py", line 476, in checkout
    rec = pool._do_get()
  File "/home/airflow/.local/lib/python3.7/site-packages/sqlalchemy/pool/impl.py", line 146, in _do_get
    self._dec_overflow()
  File "/home/airflow/.local/lib/python3.7/site-packages/sqlalchemy/util/langhelpers.py", line 72, in __exit__
    with_traceback=exc_tb,
  File "/home/airflow/.local/lib/python3.7/site-packages/sqlalchemy/util/compat.py", line 207, in raise_
    raise exception
  File "/home/airflow/.local/lib/python3.7/site-packages/sqlalchemy/pool/impl.py", line 143, in _do_get
    return self._create_connection()
  File "/home/airflow/.local/lib/python3.7/site-packages/sqlalchemy/pool/base.py", line 256, in _create_connection
    return _ConnectionRecord(self)
  File "/home/airflow/.local/lib/python3.7/site-packages/sqlalchemy/pool/base.py", line 371, in __init__
    self.__connect()
  File "/home/airflow/.local/lib/python3.7/site-packages/sqlalchemy/pool/base.py", line 666, in __connect
    pool.logger.debug("Error on connect(): %s", e)
  File "/home/airflow/.local/lib/python3.7/site-packages/sqlalchemy/util/langhelpers.py", line 72, in __exit__
    with_traceback=exc_tb,
  File "/home/airflow/.local/lib/python3.7/site-packages/sqlalchemy/util/compat.py", line 207, in raise_
    raise exception
  File "/home/airflow/.local/lib/python3.7/site-packages/sqlalchemy/pool/base.py", line 661, in __connect
    self.dbapi_connection = connection = pool._invoke_creator(self)
  File "/home/airflow/.local/lib/python3.7/site-packages/sqlalchemy/engine/create.py", line 590, in connect
    return dialect.connect(*cargs, **cparams)
  File "/home/airflow/.local/lib/python3.7/site-packages/sqlalchemy/engine/default.py", line 584, in connect
    return self.dbapi.connect(*cargs, **cparams)
  File "/home/airflow/.local/lib/python3.7/site-packages/psycopg2/__init__.py", line 122, in connect
    conn = _connect(dsn, connection_factory=connection_factory, **kwasync)
sqlalchemy.exc.OperationalError: (psycopg2.OperationalError) could not translate host name "postgres" to address: Temporary failure in name resolution

(Background on this error at: https://sqlalche.me/e/14/e3q8)
[2024-05-21T15:43:38.889+0000] {processor.py:156} INFO - Started process (PID=189) to work on /opt/airflow/dags/dags1.py
[2024-05-21T15:43:38.927+0000] {processor.py:758} INFO - Processing file /opt/airflow/dags/dags1.py for tasks to queue
[2024-05-21T15:43:39.220+0000] {logging_mixin.py:117} INFO - [2024-05-21T15:43:39.092+0000] {dagbag.py:525} INFO - Filling up the DagBag from /opt/airflow/dags/dags1.py
[2024-05-21T15:43:58.114+0000] {logging_mixin.py:117} INFO - [2024-05-21T15:43:57.948+0000] {dagbag.py:330} ERROR - Failed to import: /opt/airflow/dags/dags1.py
Traceback (most recent call last):
  File "/home/airflow/.local/lib/python3.7/site-packages/airflow/models/dagbag.py", line 326, in parse
    loader.exec_module(new_module)
  File "<frozen importlib._bootstrap_external>", line 728, in exec_module
  File "<frozen importlib._bootstrap>", line 219, in _call_with_frames_removed
  File "/opt/airflow/dags/dags1.py", line 10, in <module>
    from transform_script import transfrom
  File "/opt/airflow/dags/transform_script.py", line 2, in <module>
    from tqdm import tqdm
ModuleNotFoundError: No module named 'tqdm'
[2024-05-21T15:43:58.140+0000] {processor.py:770} WARNING - No viable dags retrieved from /opt/airflow/dags/dags1.py
[2024-05-21T15:44:28.974+0000] {processor.py:156} INFO - Started process (PID=194) to work on /opt/airflow/dags/dags1.py
[2024-05-21T15:44:28.988+0000] {processor.py:758} INFO - Processing file /opt/airflow/dags/dags1.py for tasks to queue
[2024-05-21T15:44:29.129+0000] {logging_mixin.py:117} INFO - [2024-05-21T15:44:28.998+0000] {dagbag.py:525} INFO - Filling up the DagBag from /opt/airflow/dags/dags1.py
[2024-05-21T15:45:05.453+0000] {processor.py:156} INFO - Started process (PID=217) to work on /opt/airflow/dags/dags1.py
[2024-05-21T15:45:05.455+0000] {processor.py:758} INFO - Processing file /opt/airflow/dags/dags1.py for tasks to queue
[2024-05-21T15:45:05.456+0000] {logging_mixin.py:117} INFO - [2024-05-21T15:45:05.456+0000] {dagbag.py:525} INFO - Filling up the DagBag from /opt/airflow/dags/dags1.py
[2024-05-21T15:45:06.804+0000] {logging_mixin.py:117} INFO - [2024-05-21T15:45:06.773+0000] {dagbag.py:330} ERROR - Failed to import: /opt/airflow/dags/dags1.py
Traceback (most recent call last):
  File "/home/airflow/.local/lib/python3.7/site-packages/airflow/models/dagbag.py", line 326, in parse
    loader.exec_module(new_module)
  File "<frozen importlib._bootstrap_external>", line 728, in exec_module
  File "<frozen importlib._bootstrap>", line 219, in _call_with_frames_removed
  File "/opt/airflow/dags/dags1.py", line 10, in <module>
    from transform_script import transfrom
  File "/opt/airflow/dags/transform_script.py", line 2, in <module>
    from tqdm import tqdm
ModuleNotFoundError: No module named 'tqdm'
[2024-05-21T15:45:06.818+0000] {processor.py:770} WARNING - No viable dags retrieved from /opt/airflow/dags/dags1.py
[2024-05-21T15:45:43.937+0000] {processor.py:156} INFO - Started process (PID=222) to work on /opt/airflow/dags/dags1.py
[2024-05-21T15:45:43.942+0000] {processor.py:758} INFO - Processing file /opt/airflow/dags/dags1.py for tasks to queue
[2024-05-21T15:45:43.943+0000] {logging_mixin.py:117} INFO - [2024-05-21T15:45:43.943+0000] {dagbag.py:525} INFO - Filling up the DagBag from /opt/airflow/dags/dags1.py
[2024-05-21T15:45:49.492+0000] {logging_mixin.py:117} INFO - [2024-05-21T15:45:49.486+0000] {dagbag.py:330} ERROR - Failed to import: /opt/airflow/dags/dags1.py
Traceback (most recent call last):
  File "/home/airflow/.local/lib/python3.7/site-packages/airflow/models/dagbag.py", line 326, in parse
    loader.exec_module(new_module)
  File "<frozen importlib._bootstrap_external>", line 728, in exec_module
  File "<frozen importlib._bootstrap>", line 219, in _call_with_frames_removed
  File "/opt/airflow/dags/dags1.py", line 10, in <module>
    from transform_script import transfrom
  File "/opt/airflow/dags/transform_script.py", line 2, in <module>
    from tqdm import tqdm
ModuleNotFoundError: No module named 'tqdm'
[2024-05-21T15:45:49.493+0000] {processor.py:770} WARNING - No viable dags retrieved from /opt/airflow/dags/dags1.py
[2024-05-21T15:45:49.521+0000] {processor.py:178} INFO - Processing /opt/airflow/dags/dags1.py took 5.600 seconds
[2024-05-21T15:46:20.011+0000] {processor.py:156} INFO - Started process (PID=235) to work on /opt/airflow/dags/dags1.py
[2024-05-21T15:46:20.506+0000] {processor.py:758} INFO - Processing file /opt/airflow/dags/dags1.py for tasks to queue
[2024-05-21T15:46:20.507+0000] {logging_mixin.py:117} INFO - [2024-05-21T15:46:20.507+0000] {dagbag.py:525} INFO - Filling up the DagBag from /opt/airflow/dags/dags1.py
[2024-05-21T15:47:04.646+0000] {processor.py:156} INFO - Started process (PID=239) to work on /opt/airflow/dags/dags1.py
[2024-05-21T15:47:04.651+0000] {processor.py:758} INFO - Processing file /opt/airflow/dags/dags1.py for tasks to queue
[2024-05-21T15:47:04.652+0000] {logging_mixin.py:117} INFO - [2024-05-21T15:47:04.652+0000] {dagbag.py:525} INFO - Filling up the DagBag from /opt/airflow/dags/dags1.py
[2024-05-21T15:49:56.322+0000] {logging_mixin.py:117} INFO - [2024-05-21T15:49:56.214+0000] {timeout.py:68} ERROR - Process timed out, PID: 239
[2024-05-21T15:49:56.388+0000] {logging_mixin.py:117} INFO - [2024-05-21T15:49:56.327+0000] {dagbag.py:330} ERROR - Failed to import: /opt/airflow/dags/dags1.py
Traceback (most recent call last):
  File "/home/airflow/.local/lib/python3.7/site-packages/airflow/models/dagbag.py", line 326, in parse
    loader.exec_module(new_module)
  File "<frozen importlib._bootstrap_external>", line 728, in exec_module
  File "<frozen importlib._bootstrap>", line 219, in _call_with_frames_removed
  File "/opt/airflow/dags/dags1.py", line 9, in <module>
    import pandas as pd
  File "/home/airflow/.local/lib/python3.7/site-packages/pandas/__init__.py", line 50, in <module>
    from pandas.core.api import (
  File "/home/airflow/.local/lib/python3.7/site-packages/pandas/core/api.py", line 29, in <module>
    from pandas.core.arrays import Categorical
  File "/home/airflow/.local/lib/python3.7/site-packages/pandas/core/arrays/__init__.py", line 20, in <module>
    from pandas.core.arrays.string_arrow import ArrowStringArray
  File "/home/airflow/.local/lib/python3.7/site-packages/pandas/core/arrays/string_arrow.py", line 65, in <module>
    import pyarrow.compute as pc
  File "/home/airflow/.local/lib/python3.7/site-packages/pyarrow/compute.py", line 18, in <module>
    from pyarrow._compute import (  # noqa
  File "<frozen importlib._bootstrap>", line 416, in parent
  File "/home/airflow/.local/lib/python3.7/site-packages/airflow/utils/timeout.py", line 69, in handle_timeout
    raise AirflowTaskTimeout(self.error_message)
airflow.exceptions.AirflowTaskTimeout: DagBag import timeout for /opt/airflow/dags/dags1.py after 30.0s.
Please take a look at these docs to improve your DAG import time:
* https://airflow.apache.org/docs/apache-airflow/2.4.1/best-practices.html#top-level-python-code
* https://airflow.apache.org/docs/apache-airflow/2.4.1/best-practices.html#reducing-dag-complexity, PID: 239
[2024-05-21T15:49:56.394+0000] {processor.py:770} WARNING - No viable dags retrieved from /opt/airflow/dags/dags1.py
[2024-05-21T15:49:56.534+0000] {processor.py:156} INFO - Started process (PID=243) to work on /opt/airflow/dags/dags1.py
[2024-05-21T15:49:56.534+0000] {processor.py:758} INFO - Processing file /opt/airflow/dags/dags1.py for tasks to queue
[2024-05-21T15:49:56.535+0000] {logging_mixin.py:117} INFO - [2024-05-21T15:49:56.535+0000] {dagbag.py:525} INFO - Filling up the DagBag from /opt/airflow/dags/dags1.py
[2024-05-21T15:53:19.386+0000] {processor.py:156} INFO - Started process (PID=257) to work on /opt/airflow/dags/dags1.py
[2024-05-21T15:53:19.405+0000] {processor.py:758} INFO - Processing file /opt/airflow/dags/dags1.py for tasks to queue
[2024-05-21T15:53:19.407+0000] {logging_mixin.py:117} INFO - [2024-05-21T15:53:19.406+0000] {dagbag.py:525} INFO - Filling up the DagBag from /opt/airflow/dags/dags1.py
[2024-05-21T15:53:20.891+0000] {logging_mixin.py:117} INFO - [2024-05-21T15:53:20.871+0000] {dagbag.py:330} ERROR - Failed to import: /opt/airflow/dags/dags1.py
Traceback (most recent call last):
  File "/home/airflow/.local/lib/python3.7/site-packages/airflow/models/dagbag.py", line 326, in parse
    loader.exec_module(new_module)
  File "<frozen importlib._bootstrap_external>", line 728, in exec_module
  File "<frozen importlib._bootstrap>", line 219, in _call_with_frames_removed
  File "/opt/airflow/dags/dags1.py", line 10, in <module>
    from transform_script import transfrom
  File "/opt/airflow/dags/transform_script.py", line 2, in <module>
    from tqdm import tqdm
ModuleNotFoundError: No module named 'tqdm'
[2024-05-21T15:53:20.893+0000] {processor.py:770} WARNING - No viable dags retrieved from /opt/airflow/dags/dags1.py
[2024-05-21T15:53:21.044+0000] {processor.py:178} INFO - Processing /opt/airflow/dags/dags1.py took 1.676 seconds
[2024-05-21T15:54:28.959+0000] {processor.py:156} INFO - Started process (PID=262) to work on /opt/airflow/dags/dags1.py
[2024-05-21T15:54:28.975+0000] {processor.py:758} INFO - Processing file /opt/airflow/dags/dags1.py for tasks to queue
[2024-05-21T15:54:28.976+0000] {logging_mixin.py:117} INFO - [2024-05-21T15:54:28.975+0000] {dagbag.py:525} INFO - Filling up the DagBag from /opt/airflow/dags/dags1.py
[2024-05-21T15:55:18.993+0000] {processor.py:156} INFO - Started process (PID=267) to work on /opt/airflow/dags/dags1.py
[2024-05-21T15:55:18.995+0000] {processor.py:758} INFO - Processing file /opt/airflow/dags/dags1.py for tasks to queue
[2024-05-21T15:55:18.996+0000] {logging_mixin.py:117} INFO - [2024-05-21T15:55:18.996+0000] {dagbag.py:525} INFO - Filling up the DagBag from /opt/airflow/dags/dags1.py
[2024-05-21T15:55:55.640+0000] {processor.py:156} INFO - Started process (PID=280) to work on /opt/airflow/dags/dags1.py
[2024-05-21T15:55:55.647+0000] {processor.py:758} INFO - Processing file /opt/airflow/dags/dags1.py for tasks to queue
[2024-05-21T15:55:55.649+0000] {logging_mixin.py:117} INFO - [2024-05-21T15:55:55.649+0000] {dagbag.py:525} INFO - Filling up the DagBag from /opt/airflow/dags/dags1.py
[2024-05-21T15:56:27.689+0000] {logging_mixin.py:117} INFO - [2024-05-21T15:56:26.731+0000] {timeout.py:68} ERROR - Process timed out, PID: 280
[2024-05-21T15:56:27.723+0000] {logging_mixin.py:117} INFO - [2024-05-21T15:56:27.692+0000] {dagbag.py:330} ERROR - Failed to import: /opt/airflow/dags/dags1.py
Traceback (most recent call last):
  File "/home/airflow/.local/lib/python3.7/site-packages/airflow/models/dagbag.py", line 326, in parse
    loader.exec_module(new_module)
  File "<frozen importlib._bootstrap_external>", line 728, in exec_module
  File "<frozen importlib._bootstrap>", line 219, in _call_with_frames_removed
  File "/opt/airflow/dags/dags1.py", line 9, in <module>
    import pandas as pd
  File "/home/airflow/.local/lib/python3.7/site-packages/pandas/__init__.py", line 50, in <module>
    from pandas.core.api import (
  File "/home/airflow/.local/lib/python3.7/site-packages/pandas/core/api.py", line 29, in <module>
    from pandas.core.arrays import Categorical
  File "/home/airflow/.local/lib/python3.7/site-packages/pandas/core/arrays/__init__.py", line 13, in <module>
    from pandas.core.arrays.numpy_ import PandasArray
  File "<frozen importlib._bootstrap>", line 983, in _find_and_load
  File "<frozen importlib._bootstrap>", line 967, in _find_and_load_unlocked
  File "<frozen importlib._bootstrap>", line 677, in _load_unlocked
  File "<frozen importlib._bootstrap_external>", line 724, in exec_module
  File "<frozen importlib._bootstrap_external>", line 827, in get_code
  File "<frozen importlib._bootstrap_external>", line 463, in _classify_pyc
  File "<frozen importlib._bootstrap_external>", line 53, in _r_long
  File "/home/airflow/.local/lib/python3.7/site-packages/airflow/utils/timeout.py", line 69, in handle_timeout
    raise AirflowTaskTimeout(self.error_message)
airflow.exceptions.AirflowTaskTimeout: DagBag import timeout for /opt/airflow/dags/dags1.py after 30.0s.
Please take a look at these docs to improve your DAG import time:
* https://airflow.apache.org/docs/apache-airflow/2.4.1/best-practices.html#top-level-python-code
* https://airflow.apache.org/docs/apache-airflow/2.4.1/best-practices.html#reducing-dag-complexity, PID: 280
[2024-05-21T15:56:27.726+0000] {processor.py:770} WARNING - No viable dags retrieved from /opt/airflow/dags/dags1.py
[2024-05-21T15:56:50.164+0000] {processor.py:178} INFO - Processing /opt/airflow/dags/dags1.py took 54.540 seconds
[2024-05-21T15:56:50.257+0000] {processor.py:156} INFO - Started process (PID=285) to work on /opt/airflow/dags/dags1.py
[2024-05-21T15:56:50.258+0000] {processor.py:758} INFO - Processing file /opt/airflow/dags/dags1.py for tasks to queue
[2024-05-21T15:56:50.259+0000] {logging_mixin.py:117} INFO - [2024-05-21T15:56:50.259+0000] {dagbag.py:525} INFO - Filling up the DagBag from /opt/airflow/dags/dags1.py
[2024-05-21T15:57:13.605+0000] {logging_mixin.py:117} INFO - [2024-05-21T15:57:13.566+0000] {dagbag.py:330} ERROR - Failed to import: /opt/airflow/dags/dags1.py
Traceback (most recent call last):
  File "/home/airflow/.local/lib/python3.7/site-packages/airflow/models/dagbag.py", line 326, in parse
    loader.exec_module(new_module)
  File "<frozen importlib._bootstrap_external>", line 728, in exec_module
  File "<frozen importlib._bootstrap>", line 219, in _call_with_frames_removed
  File "/opt/airflow/dags/dags1.py", line 10, in <module>
    from transform_script import transfrom
  File "/opt/airflow/dags/transform_script.py", line 2, in <module>
    from tqdm import tqdm
ModuleNotFoundError: No module named 'tqdm'
[2024-05-21T15:57:13.632+0000] {processor.py:770} WARNING - No viable dags retrieved from /opt/airflow/dags/dags1.py
[2024-05-21T15:57:15.087+0000] {processor.py:178} INFO - Processing /opt/airflow/dags/dags1.py took 24.834 seconds
[2024-05-21T15:57:49.542+0000] {processor.py:156} INFO - Started process (PID=292) to work on /opt/airflow/dags/dags1.py
[2024-05-21T15:57:49.544+0000] {processor.py:758} INFO - Processing file /opt/airflow/dags/dags1.py for tasks to queue
[2024-05-21T15:57:49.545+0000] {logging_mixin.py:117} INFO - [2024-05-21T15:57:49.545+0000] {dagbag.py:525} INFO - Filling up the DagBag from /opt/airflow/dags/dags1.py
[2024-05-21T15:57:51.842+0000] {logging_mixin.py:117} INFO - [2024-05-21T15:57:51.497+0000] {dagbag.py:330} ERROR - Failed to import: /opt/airflow/dags/dags1.py
Traceback (most recent call last):
  File "/home/airflow/.local/lib/python3.7/site-packages/airflow/models/dagbag.py", line 326, in parse
    loader.exec_module(new_module)
  File "<frozen importlib._bootstrap_external>", line 728, in exec_module
  File "<frozen importlib._bootstrap>", line 219, in _call_with_frames_removed
  File "/opt/airflow/dags/dags1.py", line 10, in <module>
    from transform_script import transfrom
  File "/opt/airflow/dags/transform_script.py", line 2, in <module>
    from tqdm import tqdm
ModuleNotFoundError: No module named 'tqdm'
[2024-05-21T15:57:52.129+0000] {processor.py:770} WARNING - No viable dags retrieved from /opt/airflow/dags/dags1.py
[2024-05-21T15:58:53.920+0000] {processor.py:156} INFO - Started process (PID=317) to work on /opt/airflow/dags/dags1.py
[2024-05-21T15:58:53.922+0000] {processor.py:758} INFO - Processing file /opt/airflow/dags/dags1.py for tasks to queue
[2024-05-21T15:58:53.924+0000] {logging_mixin.py:117} INFO - [2024-05-21T15:58:53.924+0000] {dagbag.py:525} INFO - Filling up the DagBag from /opt/airflow/dags/dags1.py
[2024-05-21T15:59:35.055+0000] {processor.py:156} INFO - Started process (PID=330) to work on /opt/airflow/dags/dags1.py
[2024-05-21T15:59:35.058+0000] {processor.py:758} INFO - Processing file /opt/airflow/dags/dags1.py for tasks to queue
[2024-05-21T15:59:35.059+0000] {logging_mixin.py:117} INFO - [2024-05-21T15:59:35.059+0000] {dagbag.py:525} INFO - Filling up the DagBag from /opt/airflow/dags/dags1.py
[2024-05-21T15:59:36.003+0000] {logging_mixin.py:117} INFO - [2024-05-21T15:59:36.001+0000] {dagbag.py:330} ERROR - Failed to import: /opt/airflow/dags/dags1.py
Traceback (most recent call last):
  File "/home/airflow/.local/lib/python3.7/site-packages/airflow/models/dagbag.py", line 326, in parse
    loader.exec_module(new_module)
  File "<frozen importlib._bootstrap_external>", line 728, in exec_module
  File "<frozen importlib._bootstrap>", line 219, in _call_with_frames_removed
  File "/opt/airflow/dags/dags1.py", line 10, in <module>
    from transform_script import transfrom
  File "/opt/airflow/dags/transform_script.py", line 2, in <module>
    from tqdm import tqdm
ModuleNotFoundError: No module named 'tqdm'
[2024-05-21T15:59:36.004+0000] {processor.py:770} WARNING - No viable dags retrieved from /opt/airflow/dags/dags1.py
[2024-05-21T15:59:36.026+0000] {processor.py:178} INFO - Processing /opt/airflow/dags/dags1.py took 0.973 seconds
[2024-05-21T16:00:11.388+0000] {processor.py:156} INFO - Started process (PID=341) to work on /opt/airflow/dags/dags1.py
[2024-05-21T16:00:11.404+0000] {processor.py:758} INFO - Processing file /opt/airflow/dags/dags1.py for tasks to queue
[2024-05-21T16:00:11.480+0000] {logging_mixin.py:117} INFO - [2024-05-21T16:00:11.423+0000] {dagbag.py:525} INFO - Filling up the DagBag from /opt/airflow/dags/dags1.py
[2024-05-21T16:00:22.259+0000] {logging_mixin.py:117} INFO - [2024-05-21T16:00:22.228+0000] {dagbag.py:330} ERROR - Failed to import: /opt/airflow/dags/dags1.py
Traceback (most recent call last):
  File "/home/airflow/.local/lib/python3.7/site-packages/airflow/models/dagbag.py", line 326, in parse
    loader.exec_module(new_module)
  File "<frozen importlib._bootstrap_external>", line 728, in exec_module
  File "<frozen importlib._bootstrap>", line 219, in _call_with_frames_removed
  File "/opt/airflow/dags/dags1.py", line 10, in <module>
    from transform_script import transfrom
  File "/opt/airflow/dags/transform_script.py", line 2, in <module>
    from tqdm import tqdm
ModuleNotFoundError: No module named 'tqdm'
[2024-05-21T16:00:22.261+0000] {processor.py:770} WARNING - No viable dags retrieved from /opt/airflow/dags/dags1.py
[2024-05-21T16:00:22.448+0000] {processor.py:178} INFO - Processing /opt/airflow/dags/dags1.py took 11.392 seconds
[2024-05-21T16:00:52.996+0000] {processor.py:156} INFO - Started process (PID=355) to work on /opt/airflow/dags/dags1.py
[2024-05-21T16:00:53.005+0000] {processor.py:758} INFO - Processing file /opt/airflow/dags/dags1.py for tasks to queue
[2024-05-21T16:00:53.005+0000] {logging_mixin.py:117} INFO - [2024-05-21T16:00:53.005+0000] {dagbag.py:525} INFO - Filling up the DagBag from /opt/airflow/dags/dags1.py
[2024-05-21T16:01:34.217+0000] {processor.py:156} INFO - Started process (PID=370) to work on /opt/airflow/dags/dags1.py
[2024-05-21T16:01:34.225+0000] {processor.py:758} INFO - Processing file /opt/airflow/dags/dags1.py for tasks to queue
[2024-05-21T16:01:34.254+0000] {logging_mixin.py:117} INFO - [2024-05-21T16:01:34.254+0000] {dagbag.py:525} INFO - Filling up the DagBag from /opt/airflow/dags/dags1.py
[2024-05-21T16:01:43.533+0000] {logging_mixin.py:117} INFO - [2024-05-21T16:01:43.481+0000] {dagbag.py:330} ERROR - Failed to import: /opt/airflow/dags/dags1.py
Traceback (most recent call last):
  File "/home/airflow/.local/lib/python3.7/site-packages/airflow/models/dagbag.py", line 326, in parse
    loader.exec_module(new_module)
  File "<frozen importlib._bootstrap_external>", line 728, in exec_module
  File "<frozen importlib._bootstrap>", line 219, in _call_with_frames_removed
  File "/opt/airflow/dags/dags1.py", line 10, in <module>
    from transform_script import transfrom
  File "/opt/airflow/dags/transform_script.py", line 2, in <module>
    from tqdm import tqdm
ModuleNotFoundError: No module named 'tqdm'
[2024-05-21T16:01:43.552+0000] {processor.py:770} WARNING - No viable dags retrieved from /opt/airflow/dags/dags1.py
[2024-05-21T16:01:43.811+0000] {processor.py:178} INFO - Processing /opt/airflow/dags/dags1.py took 9.635 seconds
[2024-05-21T16:02:14.726+0000] {processor.py:156} INFO - Started process (PID=383) to work on /opt/airflow/dags/dags1.py
[2024-05-21T16:02:14.730+0000] {processor.py:758} INFO - Processing file /opt/airflow/dags/dags1.py for tasks to queue
[2024-05-21T16:02:14.731+0000] {logging_mixin.py:117} INFO - [2024-05-21T16:02:14.731+0000] {dagbag.py:525} INFO - Filling up the DagBag from /opt/airflow/dags/dags1.py
[2024-05-21T16:02:26.523+0000] {logging_mixin.py:117} INFO - [2024-05-21T16:02:26.494+0000] {dagbag.py:330} ERROR - Failed to import: /opt/airflow/dags/dags1.py
Traceback (most recent call last):
  File "/home/airflow/.local/lib/python3.7/site-packages/airflow/models/dagbag.py", line 326, in parse
    loader.exec_module(new_module)
  File "<frozen importlib._bootstrap_external>", line 728, in exec_module
  File "<frozen importlib._bootstrap>", line 219, in _call_with_frames_removed
  File "/opt/airflow/dags/dags1.py", line 10, in <module>
    from datetime import datetime, timedelta
  File "/opt/airflow/dags/transform_script.py", line 2, in <module>
    from tqdm import tqdm
ModuleNotFoundError: No module named 'tqdm'
[2024-05-21T16:02:26.528+0000] {processor.py:770} WARNING - No viable dags retrieved from /opt/airflow/dags/dags1.py
[2024-05-21T16:02:59.311+0000] {processor.py:156} INFO - Started process (PID=405) to work on /opt/airflow/dags/dags1.py
[2024-05-21T16:02:59.319+0000] {processor.py:758} INFO - Processing file /opt/airflow/dags/dags1.py for tasks to queue
[2024-05-21T16:02:59.320+0000] {logging_mixin.py:117} INFO - [2024-05-21T16:02:59.320+0000] {dagbag.py:525} INFO - Filling up the DagBag from /opt/airflow/dags/dags1.py
[2024-05-21T16:03:38.798+0000] {processor.py:156} INFO - Started process (PID=410) to work on /opt/airflow/dags/dags1.py
[2024-05-21T16:03:38.799+0000] {processor.py:758} INFO - Processing file /opt/airflow/dags/dags1.py for tasks to queue
[2024-05-21T16:03:38.800+0000] {logging_mixin.py:117} INFO - [2024-05-21T16:03:38.800+0000] {dagbag.py:525} INFO - Filling up the DagBag from /opt/airflow/dags/dags1.py
[2024-05-21T16:03:39.448+0000] {logging_mixin.py:117} INFO - [2024-05-21T16:03:39.443+0000] {dagbag.py:330} ERROR - Failed to import: /opt/airflow/dags/dags1.py
Traceback (most recent call last):
  File "/home/airflow/.local/lib/python3.7/site-packages/airflow/models/dagbag.py", line 326, in parse
    loader.exec_module(new_module)
  File "<frozen importlib._bootstrap_external>", line 728, in exec_module
  File "<frozen importlib._bootstrap>", line 219, in _call_with_frames_removed
  File "/opt/airflow/dags/dags1.py", line 9, in <module>
    from transform_script import transfrom
  File "/opt/airflow/dags/transform_script.py", line 2, in <module>
    from tqdm import tqdm
ModuleNotFoundError: No module named 'tqdm'
[2024-05-21T16:03:39.449+0000] {processor.py:770} WARNING - No viable dags retrieved from /opt/airflow/dags/dags1.py
[2024-05-21T16:03:39.494+0000] {processor.py:178} INFO - Processing /opt/airflow/dags/dags1.py took 0.699 seconds
[2024-05-21T16:04:13.216+0000] {processor.py:156} INFO - Started process (PID=425) to work on /opt/airflow/dags/dags1.py
[2024-05-21T16:04:13.250+0000] {processor.py:758} INFO - Processing file /opt/airflow/dags/dags1.py for tasks to queue
[2024-05-21T16:04:13.260+0000] {logging_mixin.py:117} INFO - [2024-05-21T16:04:13.260+0000] {dagbag.py:525} INFO - Filling up the DagBag from /opt/airflow/dags/dags1.py
[2024-05-21T16:04:20.151+0000] {logging_mixin.py:117} INFO - [2024-05-21T16:04:20.146+0000] {dagbag.py:330} ERROR - Failed to import: /opt/airflow/dags/dags1.py
Traceback (most recent call last):
  File "/home/airflow/.local/lib/python3.7/site-packages/airflow/models/dagbag.py", line 326, in parse
    loader.exec_module(new_module)
  File "<frozen importlib._bootstrap_external>", line 728, in exec_module
  File "<frozen importlib._bootstrap>", line 219, in _call_with_frames_removed
  File "/opt/airflow/dags/dags1.py", line 9, in <module>
    from transform_script import transfrom
  File "/opt/airflow/dags/transform_script.py", line 2, in <module>
    from tqdm import tqdm
ModuleNotFoundError: No module named 'tqdm'
[2024-05-21T16:04:20.152+0000] {processor.py:770} WARNING - No viable dags retrieved from /opt/airflow/dags/dags1.py
[2024-05-21T16:04:20.305+0000] {processor.py:178} INFO - Processing /opt/airflow/dags/dags1.py took 7.144 seconds
[2024-05-21T16:04:50.554+0000] {processor.py:156} INFO - Started process (PID=438) to work on /opt/airflow/dags/dags1.py
[2024-05-21T16:04:50.557+0000] {processor.py:758} INFO - Processing file /opt/airflow/dags/dags1.py for tasks to queue
[2024-05-21T16:04:50.557+0000] {logging_mixin.py:117} INFO - [2024-05-21T16:04:50.557+0000] {dagbag.py:525} INFO - Filling up the DagBag from /opt/airflow/dags/dags1.py
[2024-05-21T16:05:13.862+0000] {logging_mixin.py:117} INFO - [2024-05-21T16:05:13.852+0000] {dagbag.py:330} ERROR - Failed to import: /opt/airflow/dags/dags1.py
Traceback (most recent call last):
  File "/home/airflow/.local/lib/python3.7/site-packages/airflow/models/dagbag.py", line 326, in parse
    loader.exec_module(new_module)
  File "<frozen importlib._bootstrap_external>", line 728, in exec_module
  File "<frozen importlib._bootstrap>", line 219, in _call_with_frames_removed
  File "/opt/airflow/dags/dags1.py", line 9, in <module>
    from transform_script import transfrom
  File "/opt/airflow/dags/transform_script.py", line 2, in <module>
    from tqdm import tqdm
ModuleNotFoundError: No module named 'tqdm'
[2024-05-21T16:05:13.868+0000] {processor.py:770} WARNING - No viable dags retrieved from /opt/airflow/dags/dags1.py
[2024-05-21T16:05:14.276+0000] {processor.py:178} INFO - Processing /opt/airflow/dags/dags1.py took 23.715 seconds
[2024-05-21T16:06:06.347+0000] {processor.py:156} INFO - Started process (PID=453) to work on /opt/airflow/dags/dags1.py
[2024-05-21T16:06:06.349+0000] {processor.py:758} INFO - Processing file /opt/airflow/dags/dags1.py for tasks to queue
[2024-05-21T16:06:06.350+0000] {logging_mixin.py:117} INFO - [2024-05-21T16:06:06.350+0000] {dagbag.py:525} INFO - Filling up the DagBag from /opt/airflow/dags/dags1.py
[2024-05-21T16:06:54.831+0000] {processor.py:156} INFO - Started process (PID=458) to work on /opt/airflow/dags/dags1.py
[2024-05-21T16:06:54.837+0000] {processor.py:758} INFO - Processing file /opt/airflow/dags/dags1.py for tasks to queue
[2024-05-21T16:06:54.838+0000] {logging_mixin.py:117} INFO - [2024-05-21T16:06:54.838+0000] {dagbag.py:525} INFO - Filling up the DagBag from /opt/airflow/dags/dags1.py
[2024-05-21T16:07:30.699+0000] {processor.py:156} INFO - Started process (PID=472) to work on /opt/airflow/dags/dags1.py
[2024-05-21T16:07:30.720+0000] {processor.py:758} INFO - Processing file /opt/airflow/dags/dags1.py for tasks to queue
[2024-05-21T16:07:30.733+0000] {logging_mixin.py:117} INFO - [2024-05-21T16:07:30.733+0000] {dagbag.py:525} INFO - Filling up the DagBag from /opt/airflow/dags/dags1.py
[2024-05-21T16:07:42.165+0000] {logging_mixin.py:117} INFO - [2024-05-21T16:07:41.997+0000] {dagbag.py:330} ERROR - Failed to import: /opt/airflow/dags/dags1.py
Traceback (most recent call last):
  File "/home/airflow/.local/lib/python3.7/site-packages/airflow/models/dagbag.py", line 326, in parse
    loader.exec_module(new_module)
  File "<frozen importlib._bootstrap_external>", line 728, in exec_module
  File "<frozen importlib._bootstrap>", line 219, in _call_with_frames_removed
  File "/opt/airflow/dags/dags1.py", line 9, in <module>
    from transform_script import transfrom
  File "/opt/airflow/dags/transform_script.py", line 2, in <module>
    from tqdm import tqdm
ModuleNotFoundError: No module named 'tqdm'
[2024-05-21T16:07:42.270+0000] {processor.py:770} WARNING - No viable dags retrieved from /opt/airflow/dags/dags1.py
[2024-05-21T16:08:16.445+0000] {processor.py:156} INFO - Started process (PID=487) to work on /opt/airflow/dags/dags1.py
[2024-05-21T16:08:16.449+0000] {processor.py:758} INFO - Processing file /opt/airflow/dags/dags1.py for tasks to queue
[2024-05-21T16:08:16.450+0000] {logging_mixin.py:117} INFO - [2024-05-21T16:08:16.450+0000] {dagbag.py:525} INFO - Filling up the DagBag from /opt/airflow/dags/dags1.py
[2024-05-21T16:08:30.653+0000] {logging_mixin.py:117} INFO - [2024-05-21T16:08:30.648+0000] {dagbag.py:330} ERROR - Failed to import: /opt/airflow/dags/dags1.py
Traceback (most recent call last):
  File "/home/airflow/.local/lib/python3.7/site-packages/airflow/models/dagbag.py", line 326, in parse
    loader.exec_module(new_module)
  File "<frozen importlib._bootstrap_external>", line 728, in exec_module
  File "<frozen importlib._bootstrap>", line 219, in _call_with_frames_removed
  File "/opt/airflow/dags/dags1.py", line 9, in <module>
    from transform_script import transfrom
  File "/opt/airflow/dags/transform_script.py", line 2, in <module>
    from tqdm import tqdm
ModuleNotFoundError: No module named 'tqdm'
[2024-05-21T16:08:30.655+0000] {processor.py:770} WARNING - No viable dags retrieved from /opt/airflow/dags/dags1.py
[2024-05-21T16:08:30.948+0000] {processor.py:178} INFO - Processing /opt/airflow/dags/dags1.py took 14.507 seconds
[2024-05-21T16:09:01.575+0000] {processor.py:156} INFO - Started process (PID=502) to work on /opt/airflow/dags/dags1.py
[2024-05-21T16:09:01.577+0000] {processor.py:758} INFO - Processing file /opt/airflow/dags/dags1.py for tasks to queue
[2024-05-21T16:09:01.580+0000] {logging_mixin.py:117} INFO - [2024-05-21T16:09:01.579+0000] {dagbag.py:525} INFO - Filling up the DagBag from /opt/airflow/dags/dags1.py
[2024-05-21T16:09:10.450+0000] {logging_mixin.py:117} INFO - [2024-05-21T16:09:10.444+0000] {dagbag.py:330} ERROR - Failed to import: /opt/airflow/dags/dags1.py
Traceback (most recent call last):
  File "/home/airflow/.local/lib/python3.7/site-packages/airflow/models/dagbag.py", line 326, in parse
    loader.exec_module(new_module)
  File "<frozen importlib._bootstrap_external>", line 728, in exec_module
  File "<frozen importlib._bootstrap>", line 219, in _call_with_frames_removed
  File "/opt/airflow/dags/dags1.py", line 9, in <module>
    from transform_script import transfrom
  File "/opt/airflow/dags/transform_script.py", line 2, in <module>
    from tqdm import tqdm
ModuleNotFoundError: No module named 'tqdm'
[2024-05-21T16:09:10.451+0000] {processor.py:770} WARNING - No viable dags retrieved from /opt/airflow/dags/dags1.py
[2024-05-21T16:09:10.563+0000] {processor.py:178} INFO - Processing /opt/airflow/dags/dags1.py took 8.998 seconds
[2024-05-21T16:09:41.444+0000] {processor.py:156} INFO - Started process (PID=525) to work on /opt/airflow/dags/dags1.py
[2024-05-21T16:09:41.456+0000] {processor.py:758} INFO - Processing file /opt/airflow/dags/dags1.py for tasks to queue
[2024-05-21T16:09:41.460+0000] {logging_mixin.py:117} INFO - [2024-05-21T16:09:41.458+0000] {dagbag.py:525} INFO - Filling up the DagBag from /opt/airflow/dags/dags1.py
[2024-05-21T16:11:11.144+0000] {processor.py:156} INFO - Started process (PID=530) to work on /opt/airflow/dags/dags1.py
[2024-05-21T16:11:11.176+0000] {processor.py:758} INFO - Processing file /opt/airflow/dags/dags1.py for tasks to queue
[2024-05-21T16:11:11.177+0000] {logging_mixin.py:117} INFO - [2024-05-21T16:11:11.177+0000] {dagbag.py:525} INFO - Filling up the DagBag from /opt/airflow/dags/dags1.py
[2024-05-21T16:14:36.551+0000] {logging_mixin.py:117} INFO - [2024-05-21T16:14:36.542+0000] {timeout.py:68} ERROR - Process timed out, PID: 530
[2024-05-21T16:14:36.675+0000] {logging_mixin.py:117} INFO - [2024-05-21T16:14:36.568+0000] {dagbag.py:330} ERROR - Failed to import: /opt/airflow/dags/dags1.py
Traceback (most recent call last):
  File "/home/airflow/.local/lib/python3.7/site-packages/airflow/models/dagbag.py", line 326, in parse
    loader.exec_module(new_module)
  File "<frozen importlib._bootstrap_external>", line 728, in exec_module
  File "<frozen importlib._bootstrap>", line 219, in _call_with_frames_removed
  File "/opt/airflow/dags/dags1.py", line 8, in <module>
    import pandas as pd
  File "/home/airflow/.local/lib/python3.7/site-packages/pandas/__init__.py", line 22, in <module>
    from pandas.compat import (
  File "/home/airflow/.local/lib/python3.7/site-packages/pandas/compat/__init__.py", line 15, in <module>
    from pandas.compat.numpy import (
  File "/home/airflow/.local/lib/python3.7/site-packages/pandas/compat/numpy/__init__.py", line 7, in <module>
    from pandas.util.version import Version
  File "/home/airflow/.local/lib/python3.7/site-packages/pandas/util/__init__.py", line 1, in <module>
    from pandas.util._decorators import (  # noqa
  File "/home/airflow/.local/lib/python3.7/site-packages/pandas/util/_decorators.py", line 14, in <module>
    from pandas._libs.properties import cache_readonly  # noqa
  File "/home/airflow/.local/lib/python3.7/site-packages/pandas/_libs/__init__.py", line 13, in <module>
    from pandas._libs.interval import Interval
  File "pandas/_libs/interval.pyx", line 1, in init pandas._libs.interval
  File "pandas/_libs/hashtable.pyx", line 1, in init pandas._libs.hashtable
  File "pandas/_libs/missing.pyx", line 30, in init pandas._libs.missing
  File "<frozen importlib._bootstrap>", line 983, in _find_and_load
  File "<frozen importlib._bootstrap>", line 963, in _find_and_load_unlocked
  File "<frozen importlib._bootstrap>", line 906, in _find_spec
  File "<frozen importlib._bootstrap_external>", line 1280, in find_spec
  File "<frozen importlib._bootstrap_external>", line 1252, in _get_spec
  File "<frozen importlib._bootstrap_external>", line 1391, in find_spec
  File "<frozen importlib._bootstrap_external>", line 59, in _path_join
  File "<frozen importlib._bootstrap_external>", line 59, in <listcomp>
  File "/home/airflow/.local/lib/python3.7/site-packages/airflow/utils/timeout.py", line 69, in handle_timeout
    raise AirflowTaskTimeout(self.error_message)
airflow.exceptions.AirflowTaskTimeout: DagBag import timeout for /opt/airflow/dags/dags1.py after 30.0s.
Please take a look at these docs to improve your DAG import time:
* https://airflow.apache.org/docs/apache-airflow/2.4.1/best-practices.html#top-level-python-code
* https://airflow.apache.org/docs/apache-airflow/2.4.1/best-practices.html#reducing-dag-complexity, PID: 530
[2024-05-21T16:14:36.678+0000] {processor.py:770} WARNING - No viable dags retrieved from /opt/airflow/dags/dags1.py
[2024-05-21T16:20:42.292+0000] {processor.py:156} INFO - Started process (PID=33) to work on /opt/airflow/dags/dags1.py
[2024-05-21T16:20:42.294+0000] {processor.py:758} INFO - Processing file /opt/airflow/dags/dags1.py for tasks to queue
[2024-05-21T16:20:42.295+0000] {logging_mixin.py:117} INFO - [2024-05-21T16:20:42.295+0000] {dagbag.py:525} INFO - Filling up the DagBag from /opt/airflow/dags/dags1.py
[2024-05-21T16:20:43.156+0000] {logging_mixin.py:117} INFO - [2024-05-21T16:20:43.155+0000] {dagbag.py:330} ERROR - Failed to import: /opt/airflow/dags/dags1.py
Traceback (most recent call last):
  File "/home/airflow/.local/lib/python3.7/site-packages/airflow/models/dagbag.py", line 326, in parse
    loader.exec_module(new_module)
  File "<frozen importlib._bootstrap_external>", line 728, in exec_module
  File "<frozen importlib._bootstrap>", line 219, in _call_with_frames_removed
  File "/opt/airflow/dags/dags1.py", line 6, in <module>
    from transform_script import transfrom
  File "/opt/airflow/dags/transform_script.py", line 2, in <module>
    from tqdm import tqdm
ModuleNotFoundError: No module named 'tqdm'
[2024-05-21T16:20:43.156+0000] {processor.py:770} WARNING - No viable dags retrieved from /opt/airflow/dags/dags1.py
[2024-05-21T16:20:43.205+0000] {processor.py:178} INFO - Processing /opt/airflow/dags/dags1.py took 0.915 seconds
[2024-05-21T16:21:22.749+0000] {processor.py:156} INFO - Started process (PID=55) to work on /opt/airflow/dags/dags1.py
[2024-05-21T16:21:22.755+0000] {processor.py:758} INFO - Processing file /opt/airflow/dags/dags1.py for tasks to queue
[2024-05-21T16:21:22.758+0000] {logging_mixin.py:117} INFO - [2024-05-21T16:21:22.758+0000] {dagbag.py:525} INFO - Filling up the DagBag from /opt/airflow/dags/dags1.py
[2024-05-21T16:21:33.433+0000] {logging_mixin.py:117} INFO - [2024-05-21T16:21:33.422+0000] {dagbag.py:330} ERROR - Failed to import: /opt/airflow/dags/dags1.py
Traceback (most recent call last):
  File "/home/airflow/.local/lib/python3.7/site-packages/airflow/models/dagbag.py", line 326, in parse
    loader.exec_module(new_module)
  File "<frozen importlib._bootstrap_external>", line 728, in exec_module
  File "<frozen importlib._bootstrap>", line 219, in _call_with_frames_removed
  File "/opt/airflow/dags/dags1.py", line 6, in <module>
    from transform_script import transfrom
  File "/opt/airflow/dags/transform_script.py", line 2, in <module>
    from tqdm import tqdm
ModuleNotFoundError: No module named 'tqdm'
[2024-05-21T16:21:33.434+0000] {processor.py:770} WARNING - No viable dags retrieved from /opt/airflow/dags/dags1.py
[2024-05-21T16:21:34.152+0000] {processor.py:178} INFO - Processing /opt/airflow/dags/dags1.py took 11.536 seconds
[2024-05-21T16:22:07.904+0000] {processor.py:156} INFO - Started process (PID=78) to work on /opt/airflow/dags/dags1.py
[2024-05-21T16:22:07.939+0000] {processor.py:758} INFO - Processing file /opt/airflow/dags/dags1.py for tasks to queue
[2024-05-21T16:22:07.964+0000] {logging_mixin.py:117} INFO - [2024-05-21T16:22:07.962+0000] {dagbag.py:525} INFO - Filling up the DagBag from /opt/airflow/dags/dags1.py
[2024-05-21T16:22:35.145+0000] {logging_mixin.py:117} INFO - [2024-05-21T16:22:35.129+0000] {dagbag.py:330} ERROR - Failed to import: /opt/airflow/dags/dags1.py
Traceback (most recent call last):
  File "/home/airflow/.local/lib/python3.7/site-packages/airflow/models/dagbag.py", line 326, in parse
    loader.exec_module(new_module)
  File "<frozen importlib._bootstrap_external>", line 728, in exec_module
  File "<frozen importlib._bootstrap>", line 219, in _call_with_frames_removed
  File "/opt/airflow/dags/dags1.py", line 6, in <module>
    from transform_script import transfrom
  File "/opt/airflow/dags/transform_script.py", line 2, in <module>
    from tqdm import tqdm
ModuleNotFoundError: No module named 'tqdm'
[2024-05-21T16:22:35.146+0000] {processor.py:770} WARNING - No viable dags retrieved from /opt/airflow/dags/dags1.py
[2024-05-21T16:23:17.020+0000] {processor.py:156} INFO - Started process (PID=85) to work on /opt/airflow/dags/dags1.py
[2024-05-21T16:23:17.021+0000] {processor.py:758} INFO - Processing file /opt/airflow/dags/dags1.py for tasks to queue
[2024-05-21T16:23:17.022+0000] {logging_mixin.py:117} INFO - [2024-05-21T16:23:17.022+0000] {dagbag.py:525} INFO - Filling up the DagBag from /opt/airflow/dags/dags1.py
[2024-05-21T16:23:57.540+0000] {processor.py:156} INFO - Started process (PID=89) to work on /opt/airflow/dags/dags1.py
[2024-05-21T16:23:57.544+0000] {processor.py:758} INFO - Processing file /opt/airflow/dags/dags1.py for tasks to queue
[2024-05-21T16:23:57.545+0000] {logging_mixin.py:117} INFO - [2024-05-21T16:23:57.544+0000] {dagbag.py:525} INFO - Filling up the DagBag from /opt/airflow/dags/dags1.py
[2024-05-21T16:24:45.419+0000] {processor.py:156} INFO - Started process (PID=94) to work on /opt/airflow/dags/dags1.py
[2024-05-21T16:24:45.532+0000] {processor.py:758} INFO - Processing file /opt/airflow/dags/dags1.py for tasks to queue
[2024-05-21T16:24:45.668+0000] {logging_mixin.py:117} INFO - [2024-05-21T16:24:45.634+0000] {dagbag.py:525} INFO - Filling up the DagBag from /opt/airflow/dags/dags1.py
[2024-05-21T16:25:15.886+0000] {logging_mixin.py:117} INFO - [2024-05-21T16:25:15.804+0000] {timeout.py:68} ERROR - Process timed out, PID: 94
[2024-05-21T16:25:16.068+0000] {logging_mixin.py:117} INFO - [2024-05-21T16:25:15.929+0000] {dagbag.py:330} ERROR - Failed to import: /opt/airflow/dags/dags1.py
Traceback (most recent call last):
  File "/home/airflow/.local/lib/python3.7/site-packages/airflow/models/dagbag.py", line 326, in parse
    loader.exec_module(new_module)
  File "<frozen importlib._bootstrap_external>", line 728, in exec_module
  File "<frozen importlib._bootstrap>", line 219, in _call_with_frames_removed
  File "/opt/airflow/dags/dags1.py", line 5, in <module>
    import pandas as pd
  File "/home/airflow/.local/lib/python3.7/site-packages/pandas/__init__.py", line 143, in <module>
    from pandas.io.api import (
  File "/home/airflow/.local/lib/python3.7/site-packages/pandas/io/api.py", line 8, in <module>
    from pandas.io.excel import (
  File "/home/airflow/.local/lib/python3.7/site-packages/pandas/io/excel/__init__.py", line 1, in <module>
    from pandas.io.excel._base import (
  File "/home/airflow/.local/lib/python3.7/site-packages/pandas/io/excel/_base.py", line 1105, in <module>
    class ExcelFile:
  File "/home/airflow/.local/lib/python3.7/site-packages/pandas/io/excel/_base.py", line 1155, in ExcelFile
    from pandas.io.excel._openpyxl import OpenpyxlReader
  File "<frozen importlib._bootstrap>", line 983, in _find_and_load
  File "<frozen importlib._bootstrap>", line 967, in _find_and_load_unlocked
  File "<frozen importlib._bootstrap>", line 677, in _load_unlocked
  File "<frozen importlib._bootstrap_external>", line 724, in exec_module
  File "<frozen importlib._bootstrap_external>", line 818, in get_code
  File "<frozen importlib._bootstrap_external>", line 917, in get_data
  File "/home/airflow/.local/lib/python3.7/site-packages/airflow/utils/timeout.py", line 69, in handle_timeout
    raise AirflowTaskTimeout(self.error_message)
airflow.exceptions.AirflowTaskTimeout: DagBag import timeout for /opt/airflow/dags/dags1.py after 30.0s.
Please take a look at these docs to improve your DAG import time:
* https://airflow.apache.org/docs/apache-airflow/2.4.1/best-practices.html#top-level-python-code
* https://airflow.apache.org/docs/apache-airflow/2.4.1/best-practices.html#reducing-dag-complexity, PID: 94
[2024-05-21T16:25:16.208+0000] {processor.py:770} WARNING - No viable dags retrieved from /opt/airflow/dags/dags1.py
[2024-05-21T16:25:26.473+0000] {processor.py:181} ERROR - Got an exception! Propagating...
Traceback (most recent call last):
  File "/home/airflow/.local/lib/python3.7/site-packages/sqlalchemy/engine/base.py", line 3243, in _wrap_pool_connect
    return fn()
  File "/home/airflow/.local/lib/python3.7/site-packages/sqlalchemy/pool/base.py", line 310, in connect
    return _ConnectionFairy._checkout(self)
  File "/home/airflow/.local/lib/python3.7/site-packages/sqlalchemy/pool/base.py", line 868, in _checkout
    fairy = _ConnectionRecord.checkout(pool)
  File "/home/airflow/.local/lib/python3.7/site-packages/sqlalchemy/pool/base.py", line 476, in checkout
    rec = pool._do_get()
  File "/home/airflow/.local/lib/python3.7/site-packages/sqlalchemy/pool/impl.py", line 146, in _do_get
    self._dec_overflow()
  File "/home/airflow/.local/lib/python3.7/site-packages/sqlalchemy/util/langhelpers.py", line 72, in __exit__
    with_traceback=exc_tb,
  File "/home/airflow/.local/lib/python3.7/site-packages/sqlalchemy/util/compat.py", line 207, in raise_
    raise exception
  File "/home/airflow/.local/lib/python3.7/site-packages/sqlalchemy/pool/impl.py", line 143, in _do_get
    return self._create_connection()
  File "/home/airflow/.local/lib/python3.7/site-packages/sqlalchemy/pool/base.py", line 256, in _create_connection
    return _ConnectionRecord(self)
  File "/home/airflow/.local/lib/python3.7/site-packages/sqlalchemy/pool/base.py", line 371, in __init__
    self.__connect()
  File "/home/airflow/.local/lib/python3.7/site-packages/sqlalchemy/pool/base.py", line 666, in __connect
    pool.logger.debug("Error on connect(): %s", e)
  File "/home/airflow/.local/lib/python3.7/site-packages/sqlalchemy/util/langhelpers.py", line 72, in __exit__
    with_traceback=exc_tb,
  File "/home/airflow/.local/lib/python3.7/site-packages/sqlalchemy/util/compat.py", line 207, in raise_
    raise exception
  File "/home/airflow/.local/lib/python3.7/site-packages/sqlalchemy/pool/base.py", line 661, in __connect
    self.dbapi_connection = connection = pool._invoke_creator(self)
  File "/home/airflow/.local/lib/python3.7/site-packages/sqlalchemy/engine/create.py", line 590, in connect
    return dialect.connect(*cargs, **cparams)
  File "/home/airflow/.local/lib/python3.7/site-packages/sqlalchemy/engine/default.py", line 584, in connect
    return self.dbapi.connect(*cargs, **cparams)
  File "/home/airflow/.local/lib/python3.7/site-packages/psycopg2/__init__.py", line 122, in connect
    conn = _connect(dsn, connection_factory=connection_factory, **kwasync)
psycopg2.OperationalError: could not translate host name "postgres" to address: Temporary failure in name resolution


The above exception was the direct cause of the following exception:

Traceback (most recent call last):
  File "/home/airflow/.local/lib/python3.7/site-packages/airflow/dag_processing/processor.py", line 177, in _run_file_processor
    _handle_dag_file_processing()
  File "/home/airflow/.local/lib/python3.7/site-packages/airflow/dag_processing/processor.py", line 161, in _handle_dag_file_processing
    callback_requests=callback_requests,
  File "/home/airflow/.local/lib/python3.7/site-packages/airflow/utils/session.py", line 75, in wrapper
    return func(*args, session=session, **kwargs)
  File "/home/airflow/.local/lib/python3.7/site-packages/airflow/dag_processing/processor.py", line 771, in process_file
    self.update_import_errors(session, dagbag)
  File "/home/airflow/.local/lib/python3.7/site-packages/airflow/dag_processing/processor.py", line 558, in update_import_errors
    existing_import_error_files = [x.filename for x in session.query(errors.ImportError.filename).all()]
  File "/home/airflow/.local/lib/python3.7/site-packages/sqlalchemy/orm/query.py", line 2759, in all
    return self._iter().all()
  File "/home/airflow/.local/lib/python3.7/site-packages/sqlalchemy/orm/query.py", line 2897, in _iter
    execution_options={"_sa_orm_load_options": self.load_options},
  File "/home/airflow/.local/lib/python3.7/site-packages/sqlalchemy/orm/session.py", line 1688, in execute
    conn = self._connection_for_bind(bind)
  File "/home/airflow/.local/lib/python3.7/site-packages/sqlalchemy/orm/session.py", line 1530, in _connection_for_bind
    engine, execution_options
  File "/home/airflow/.local/lib/python3.7/site-packages/sqlalchemy/orm/session.py", line 747, in _connection_for_bind
    conn = bind.connect()
  File "/home/airflow/.local/lib/python3.7/site-packages/sqlalchemy/engine/base.py", line 3197, in connect
    return self._connection_cls(self, close_with_result=close_with_result)
  File "/home/airflow/.local/lib/python3.7/site-packages/sqlalchemy/engine/base.py", line 96, in __init__
    else engine.raw_connection()
  File "/home/airflow/.local/lib/python3.7/site-packages/sqlalchemy/engine/base.py", line 3276, in raw_connection
    return self._wrap_pool_connect(self.pool.connect, _connection)
  File "/home/airflow/.local/lib/python3.7/site-packages/sqlalchemy/engine/base.py", line 3247, in _wrap_pool_connect
    e, dialect, self
  File "/home/airflow/.local/lib/python3.7/site-packages/sqlalchemy/engine/base.py", line 2101, in _handle_dbapi_exception_noconnection
    sqlalchemy_exception, with_traceback=exc_info[2], from_=e
  File "/home/airflow/.local/lib/python3.7/site-packages/sqlalchemy/util/compat.py", line 207, in raise_
    raise exception
  File "/home/airflow/.local/lib/python3.7/site-packages/sqlalchemy/engine/base.py", line 3243, in _wrap_pool_connect
    return fn()
  File "/home/airflow/.local/lib/python3.7/site-packages/sqlalchemy/pool/base.py", line 310, in connect
    return _ConnectionFairy._checkout(self)
  File "/home/airflow/.local/lib/python3.7/site-packages/sqlalchemy/pool/base.py", line 868, in _checkout
    fairy = _ConnectionRecord.checkout(pool)
  File "/home/airflow/.local/lib/python3.7/site-packages/sqlalchemy/pool/base.py", line 476, in checkout
    rec = pool._do_get()
  File "/home/airflow/.local/lib/python3.7/site-packages/sqlalchemy/pool/impl.py", line 146, in _do_get
    self._dec_overflow()
  File "/home/airflow/.local/lib/python3.7/site-packages/sqlalchemy/util/langhelpers.py", line 72, in __exit__
    with_traceback=exc_tb,
  File "/home/airflow/.local/lib/python3.7/site-packages/sqlalchemy/util/compat.py", line 207, in raise_
    raise exception
  File "/home/airflow/.local/lib/python3.7/site-packages/sqlalchemy/pool/impl.py", line 143, in _do_get
    return self._create_connection()
  File "/home/airflow/.local/lib/python3.7/site-packages/sqlalchemy/pool/base.py", line 256, in _create_connection
    return _ConnectionRecord(self)
  File "/home/airflow/.local/lib/python3.7/site-packages/sqlalchemy/pool/base.py", line 371, in __init__
    self.__connect()
  File "/home/airflow/.local/lib/python3.7/site-packages/sqlalchemy/pool/base.py", line 666, in __connect
    pool.logger.debug("Error on connect(): %s", e)
  File "/home/airflow/.local/lib/python3.7/site-packages/sqlalchemy/util/langhelpers.py", line 72, in __exit__
    with_traceback=exc_tb,
  File "/home/airflow/.local/lib/python3.7/site-packages/sqlalchemy/util/compat.py", line 207, in raise_
    raise exception
  File "/home/airflow/.local/lib/python3.7/site-packages/sqlalchemy/pool/base.py", line 661, in __connect
    self.dbapi_connection = connection = pool._invoke_creator(self)
  File "/home/airflow/.local/lib/python3.7/site-packages/sqlalchemy/engine/create.py", line 590, in connect
    return dialect.connect(*cargs, **cparams)
  File "/home/airflow/.local/lib/python3.7/site-packages/sqlalchemy/engine/default.py", line 584, in connect
    return self.dbapi.connect(*cargs, **cparams)
  File "/home/airflow/.local/lib/python3.7/site-packages/psycopg2/__init__.py", line 122, in connect
    conn = _connect(dsn, connection_factory=connection_factory, **kwasync)
sqlalchemy.exc.OperationalError: (psycopg2.OperationalError) could not translate host name "postgres" to address: Temporary failure in name resolution

(Background on this error at: https://sqlalche.me/e/14/e3q8)
[2024-05-21T16:25:58.755+0000] {processor.py:156} INFO - Started process (PID=99) to work on /opt/airflow/dags/dags1.py
[2024-05-21T16:25:58.759+0000] {processor.py:758} INFO - Processing file /opt/airflow/dags/dags1.py for tasks to queue
[2024-05-21T16:25:58.761+0000] {logging_mixin.py:117} INFO - [2024-05-21T16:25:58.760+0000] {dagbag.py:525} INFO - Filling up the DagBag from /opt/airflow/dags/dags1.py
[2024-05-21T16:26:02.975+0000] {logging_mixin.py:117} INFO - [2024-05-21T16:26:02.598+0000] {dagbag.py:330} ERROR - Failed to import: /opt/airflow/dags/dags1.py
Traceback (most recent call last):
  File "/home/airflow/.local/lib/python3.7/site-packages/airflow/models/dagbag.py", line 326, in parse
    loader.exec_module(new_module)
  File "<frozen importlib._bootstrap_external>", line 728, in exec_module
  File "<frozen importlib._bootstrap>", line 219, in _call_with_frames_removed
  File "/opt/airflow/dags/dags1.py", line 6, in <module>
    from transform_script import transfrom
  File "/opt/airflow/dags/transform_script.py", line 2, in <module>
    from tqdm import tqdm
ModuleNotFoundError: No module named 'tqdm'
[2024-05-21T16:26:03.123+0000] {processor.py:770} WARNING - No viable dags retrieved from /opt/airflow/dags/dags1.py
[2024-05-21T16:26:13.322+0000] {processor.py:181} ERROR - Got an exception! Propagating...
Traceback (most recent call last):
  File "/home/airflow/.local/lib/python3.7/site-packages/sqlalchemy/engine/base.py", line 3243, in _wrap_pool_connect
    return fn()
  File "/home/airflow/.local/lib/python3.7/site-packages/sqlalchemy/pool/base.py", line 310, in connect
    return _ConnectionFairy._checkout(self)
  File "/home/airflow/.local/lib/python3.7/site-packages/sqlalchemy/pool/base.py", line 868, in _checkout
    fairy = _ConnectionRecord.checkout(pool)
  File "/home/airflow/.local/lib/python3.7/site-packages/sqlalchemy/pool/base.py", line 476, in checkout
    rec = pool._do_get()
  File "/home/airflow/.local/lib/python3.7/site-packages/sqlalchemy/pool/impl.py", line 146, in _do_get
    self._dec_overflow()
  File "/home/airflow/.local/lib/python3.7/site-packages/sqlalchemy/util/langhelpers.py", line 72, in __exit__
    with_traceback=exc_tb,
  File "/home/airflow/.local/lib/python3.7/site-packages/sqlalchemy/util/compat.py", line 207, in raise_
    raise exception
  File "/home/airflow/.local/lib/python3.7/site-packages/sqlalchemy/pool/impl.py", line 143, in _do_get
    return self._create_connection()
  File "/home/airflow/.local/lib/python3.7/site-packages/sqlalchemy/pool/base.py", line 256, in _create_connection
    return _ConnectionRecord(self)
  File "/home/airflow/.local/lib/python3.7/site-packages/sqlalchemy/pool/base.py", line 371, in __init__
    self.__connect()
  File "/home/airflow/.local/lib/python3.7/site-packages/sqlalchemy/pool/base.py", line 666, in __connect
    pool.logger.debug("Error on connect(): %s", e)
  File "/home/airflow/.local/lib/python3.7/site-packages/sqlalchemy/util/langhelpers.py", line 72, in __exit__
    with_traceback=exc_tb,
  File "/home/airflow/.local/lib/python3.7/site-packages/sqlalchemy/util/compat.py", line 207, in raise_
    raise exception
  File "/home/airflow/.local/lib/python3.7/site-packages/sqlalchemy/pool/base.py", line 661, in __connect
    self.dbapi_connection = connection = pool._invoke_creator(self)
  File "/home/airflow/.local/lib/python3.7/site-packages/sqlalchemy/engine/create.py", line 590, in connect
    return dialect.connect(*cargs, **cparams)
  File "/home/airflow/.local/lib/python3.7/site-packages/sqlalchemy/engine/default.py", line 584, in connect
    return self.dbapi.connect(*cargs, **cparams)
  File "/home/airflow/.local/lib/python3.7/site-packages/psycopg2/__init__.py", line 122, in connect
    conn = _connect(dsn, connection_factory=connection_factory, **kwasync)
psycopg2.OperationalError: could not translate host name "postgres" to address: Temporary failure in name resolution


The above exception was the direct cause of the following exception:

Traceback (most recent call last):
  File "/home/airflow/.local/lib/python3.7/site-packages/airflow/dag_processing/processor.py", line 177, in _run_file_processor
    _handle_dag_file_processing()
  File "/home/airflow/.local/lib/python3.7/site-packages/airflow/dag_processing/processor.py", line 161, in _handle_dag_file_processing
    callback_requests=callback_requests,
  File "/home/airflow/.local/lib/python3.7/site-packages/airflow/utils/session.py", line 75, in wrapper
    return func(*args, session=session, **kwargs)
  File "/home/airflow/.local/lib/python3.7/site-packages/airflow/dag_processing/processor.py", line 771, in process_file
    self.update_import_errors(session, dagbag)
  File "/home/airflow/.local/lib/python3.7/site-packages/airflow/dag_processing/processor.py", line 558, in update_import_errors
    existing_import_error_files = [x.filename for x in session.query(errors.ImportError.filename).all()]
  File "/home/airflow/.local/lib/python3.7/site-packages/sqlalchemy/orm/query.py", line 2759, in all
    return self._iter().all()
  File "/home/airflow/.local/lib/python3.7/site-packages/sqlalchemy/orm/query.py", line 2897, in _iter
    execution_options={"_sa_orm_load_options": self.load_options},
  File "/home/airflow/.local/lib/python3.7/site-packages/sqlalchemy/orm/session.py", line 1688, in execute
    conn = self._connection_for_bind(bind)
  File "/home/airflow/.local/lib/python3.7/site-packages/sqlalchemy/orm/session.py", line 1530, in _connection_for_bind
    engine, execution_options
  File "/home/airflow/.local/lib/python3.7/site-packages/sqlalchemy/orm/session.py", line 747, in _connection_for_bind
    conn = bind.connect()
  File "/home/airflow/.local/lib/python3.7/site-packages/sqlalchemy/engine/base.py", line 3197, in connect
    return self._connection_cls(self, close_with_result=close_with_result)
  File "/home/airflow/.local/lib/python3.7/site-packages/sqlalchemy/engine/base.py", line 96, in __init__
    else engine.raw_connection()
  File "/home/airflow/.local/lib/python3.7/site-packages/sqlalchemy/engine/base.py", line 3276, in raw_connection
    return self._wrap_pool_connect(self.pool.connect, _connection)
  File "/home/airflow/.local/lib/python3.7/site-packages/sqlalchemy/engine/base.py", line 3247, in _wrap_pool_connect
    e, dialect, self
  File "/home/airflow/.local/lib/python3.7/site-packages/sqlalchemy/engine/base.py", line 2101, in _handle_dbapi_exception_noconnection
    sqlalchemy_exception, with_traceback=exc_info[2], from_=e
  File "/home/airflow/.local/lib/python3.7/site-packages/sqlalchemy/util/compat.py", line 207, in raise_
    raise exception
  File "/home/airflow/.local/lib/python3.7/site-packages/sqlalchemy/engine/base.py", line 3243, in _wrap_pool_connect
    return fn()
  File "/home/airflow/.local/lib/python3.7/site-packages/sqlalchemy/pool/base.py", line 310, in connect
    return _ConnectionFairy._checkout(self)
  File "/home/airflow/.local/lib/python3.7/site-packages/sqlalchemy/pool/base.py", line 868, in _checkout
    fairy = _ConnectionRecord.checkout(pool)
  File "/home/airflow/.local/lib/python3.7/site-packages/sqlalchemy/pool/base.py", line 476, in checkout
    rec = pool._do_get()
  File "/home/airflow/.local/lib/python3.7/site-packages/sqlalchemy/pool/impl.py", line 146, in _do_get
    self._dec_overflow()
  File "/home/airflow/.local/lib/python3.7/site-packages/sqlalchemy/util/langhelpers.py", line 72, in __exit__
    with_traceback=exc_tb,
  File "/home/airflow/.local/lib/python3.7/site-packages/sqlalchemy/util/compat.py", line 207, in raise_
    raise exception
  File "/home/airflow/.local/lib/python3.7/site-packages/sqlalchemy/pool/impl.py", line 143, in _do_get
    return self._create_connection()
  File "/home/airflow/.local/lib/python3.7/site-packages/sqlalchemy/pool/base.py", line 256, in _create_connection
    return _ConnectionRecord(self)
  File "/home/airflow/.local/lib/python3.7/site-packages/sqlalchemy/pool/base.py", line 371, in __init__
    self.__connect()
  File "/home/airflow/.local/lib/python3.7/site-packages/sqlalchemy/pool/base.py", line 666, in __connect
    pool.logger.debug("Error on connect(): %s", e)
  File "/home/airflow/.local/lib/python3.7/site-packages/sqlalchemy/util/langhelpers.py", line 72, in __exit__
    with_traceback=exc_tb,
  File "/home/airflow/.local/lib/python3.7/site-packages/sqlalchemy/util/compat.py", line 207, in raise_
    raise exception
  File "/home/airflow/.local/lib/python3.7/site-packages/sqlalchemy/pool/base.py", line 661, in __connect
    self.dbapi_connection = connection = pool._invoke_creator(self)
  File "/home/airflow/.local/lib/python3.7/site-packages/sqlalchemy/engine/create.py", line 590, in connect
    return dialect.connect(*cargs, **cparams)
  File "/home/airflow/.local/lib/python3.7/site-packages/sqlalchemy/engine/default.py", line 584, in connect
    return self.dbapi.connect(*cargs, **cparams)
  File "/home/airflow/.local/lib/python3.7/site-packages/psycopg2/__init__.py", line 122, in connect
    conn = _connect(dsn, connection_factory=connection_factory, **kwasync)
sqlalchemy.exc.OperationalError: (psycopg2.OperationalError) could not translate host name "postgres" to address: Temporary failure in name resolution

(Background on this error at: https://sqlalche.me/e/14/e3q8)
[2024-05-21T16:26:43.961+0000] {processor.py:156} INFO - Started process (PID=104) to work on /opt/airflow/dags/dags1.py
[2024-05-21T16:26:43.963+0000] {processor.py:758} INFO - Processing file /opt/airflow/dags/dags1.py for tasks to queue
[2024-05-21T16:26:43.964+0000] {logging_mixin.py:117} INFO - [2024-05-21T16:26:43.963+0000] {dagbag.py:525} INFO - Filling up the DagBag from /opt/airflow/dags/dags1.py
[2024-05-21T16:27:20.791+0000] {logging_mixin.py:117} INFO - [2024-05-21T16:27:20.785+0000] {timeout.py:68} ERROR - Process timed out, PID: 104
[2024-05-21T16:27:20.816+0000] {logging_mixin.py:117} INFO - [2024-05-21T16:27:20.793+0000] {dagbag.py:330} ERROR - Failed to import: /opt/airflow/dags/dags1.py
Traceback (most recent call last):
  File "/home/airflow/.local/lib/python3.7/site-packages/airflow/models/dagbag.py", line 326, in parse
    loader.exec_module(new_module)
  File "<frozen importlib._bootstrap_external>", line 728, in exec_module
  File "<frozen importlib._bootstrap>", line 219, in _call_with_frames_removed
  File "/opt/airflow/dags/dags1.py", line 5, in <module>
    import pandas as pd
  File "/home/airflow/.local/lib/python3.7/site-packages/pandas/__init__.py", line 22, in <module>
    from pandas.compat import (
  File "/home/airflow/.local/lib/python3.7/site-packages/pandas/compat/__init__.py", line 23, in <module>
    from pandas.compat.pyarrow import (
  File "/home/airflow/.local/lib/python3.7/site-packages/pandas/compat/pyarrow.py", line 6, in <module>
    import pyarrow as pa
  File "/home/airflow/.local/lib/python3.7/site-packages/pyarrow/__init__.py", line 63, in <module>
    import pyarrow.lib as _lib
  File "<frozen importlib._bootstrap>", line 416, in parent
  File "/home/airflow/.local/lib/python3.7/site-packages/airflow/utils/timeout.py", line 69, in handle_timeout
    raise AirflowTaskTimeout(self.error_message)
airflow.exceptions.AirflowTaskTimeout: DagBag import timeout for /opt/airflow/dags/dags1.py after 30.0s.
Please take a look at these docs to improve your DAG import time:
* https://airflow.apache.org/docs/apache-airflow/2.4.1/best-practices.html#top-level-python-code
* https://airflow.apache.org/docs/apache-airflow/2.4.1/best-practices.html#reducing-dag-complexity, PID: 104
[2024-05-21T16:27:20.820+0000] {processor.py:770} WARNING - No viable dags retrieved from /opt/airflow/dags/dags1.py
[2024-05-21T16:27:31.050+0000] {processor.py:181} ERROR - Got an exception! Propagating...
Traceback (most recent call last):
  File "/home/airflow/.local/lib/python3.7/site-packages/sqlalchemy/engine/base.py", line 3243, in _wrap_pool_connect
    return fn()
  File "/home/airflow/.local/lib/python3.7/site-packages/sqlalchemy/pool/base.py", line 310, in connect
    return _ConnectionFairy._checkout(self)
  File "/home/airflow/.local/lib/python3.7/site-packages/sqlalchemy/pool/base.py", line 868, in _checkout
    fairy = _ConnectionRecord.checkout(pool)
  File "/home/airflow/.local/lib/python3.7/site-packages/sqlalchemy/pool/base.py", line 476, in checkout
    rec = pool._do_get()
  File "/home/airflow/.local/lib/python3.7/site-packages/sqlalchemy/pool/impl.py", line 146, in _do_get
    self._dec_overflow()
  File "/home/airflow/.local/lib/python3.7/site-packages/sqlalchemy/util/langhelpers.py", line 72, in __exit__
    with_traceback=exc_tb,
  File "/home/airflow/.local/lib/python3.7/site-packages/sqlalchemy/util/compat.py", line 207, in raise_
    raise exception
  File "/home/airflow/.local/lib/python3.7/site-packages/sqlalchemy/pool/impl.py", line 143, in _do_get
    return self._create_connection()
  File "/home/airflow/.local/lib/python3.7/site-packages/sqlalchemy/pool/base.py", line 256, in _create_connection
    return _ConnectionRecord(self)
  File "/home/airflow/.local/lib/python3.7/site-packages/sqlalchemy/pool/base.py", line 371, in __init__
    self.__connect()
  File "/home/airflow/.local/lib/python3.7/site-packages/sqlalchemy/pool/base.py", line 666, in __connect
    pool.logger.debug("Error on connect(): %s", e)
  File "/home/airflow/.local/lib/python3.7/site-packages/sqlalchemy/util/langhelpers.py", line 72, in __exit__
    with_traceback=exc_tb,
  File "/home/airflow/.local/lib/python3.7/site-packages/sqlalchemy/util/compat.py", line 207, in raise_
    raise exception
  File "/home/airflow/.local/lib/python3.7/site-packages/sqlalchemy/pool/base.py", line 661, in __connect
    self.dbapi_connection = connection = pool._invoke_creator(self)
  File "/home/airflow/.local/lib/python3.7/site-packages/sqlalchemy/engine/create.py", line 590, in connect
    return dialect.connect(*cargs, **cparams)
  File "/home/airflow/.local/lib/python3.7/site-packages/sqlalchemy/engine/default.py", line 584, in connect
    return self.dbapi.connect(*cargs, **cparams)
  File "/home/airflow/.local/lib/python3.7/site-packages/psycopg2/__init__.py", line 122, in connect
    conn = _connect(dsn, connection_factory=connection_factory, **kwasync)
psycopg2.OperationalError: could not translate host name "postgres" to address: Temporary failure in name resolution


The above exception was the direct cause of the following exception:

Traceback (most recent call last):
  File "/home/airflow/.local/lib/python3.7/site-packages/airflow/dag_processing/processor.py", line 177, in _run_file_processor
    _handle_dag_file_processing()
  File "/home/airflow/.local/lib/python3.7/site-packages/airflow/dag_processing/processor.py", line 161, in _handle_dag_file_processing
    callback_requests=callback_requests,
  File "/home/airflow/.local/lib/python3.7/site-packages/airflow/utils/session.py", line 75, in wrapper
    return func(*args, session=session, **kwargs)
  File "/home/airflow/.local/lib/python3.7/site-packages/airflow/dag_processing/processor.py", line 771, in process_file
    self.update_import_errors(session, dagbag)
  File "/home/airflow/.local/lib/python3.7/site-packages/airflow/dag_processing/processor.py", line 558, in update_import_errors
    existing_import_error_files = [x.filename for x in session.query(errors.ImportError.filename).all()]
  File "/home/airflow/.local/lib/python3.7/site-packages/sqlalchemy/orm/query.py", line 2759, in all
    return self._iter().all()
  File "/home/airflow/.local/lib/python3.7/site-packages/sqlalchemy/orm/query.py", line 2897, in _iter
    execution_options={"_sa_orm_load_options": self.load_options},
  File "/home/airflow/.local/lib/python3.7/site-packages/sqlalchemy/orm/session.py", line 1688, in execute
    conn = self._connection_for_bind(bind)
  File "/home/airflow/.local/lib/python3.7/site-packages/sqlalchemy/orm/session.py", line 1530, in _connection_for_bind
    engine, execution_options
  File "/home/airflow/.local/lib/python3.7/site-packages/sqlalchemy/orm/session.py", line 747, in _connection_for_bind
    conn = bind.connect()
  File "/home/airflow/.local/lib/python3.7/site-packages/sqlalchemy/engine/base.py", line 3197, in connect
    return self._connection_cls(self, close_with_result=close_with_result)
  File "/home/airflow/.local/lib/python3.7/site-packages/sqlalchemy/engine/base.py", line 96, in __init__
    else engine.raw_connection()
  File "/home/airflow/.local/lib/python3.7/site-packages/sqlalchemy/engine/base.py", line 3276, in raw_connection
    return self._wrap_pool_connect(self.pool.connect, _connection)
  File "/home/airflow/.local/lib/python3.7/site-packages/sqlalchemy/engine/base.py", line 3247, in _wrap_pool_connect
    e, dialect, self
  File "/home/airflow/.local/lib/python3.7/site-packages/sqlalchemy/engine/base.py", line 2101, in _handle_dbapi_exception_noconnection
    sqlalchemy_exception, with_traceback=exc_info[2], from_=e
  File "/home/airflow/.local/lib/python3.7/site-packages/sqlalchemy/util/compat.py", line 207, in raise_
    raise exception
  File "/home/airflow/.local/lib/python3.7/site-packages/sqlalchemy/engine/base.py", line 3243, in _wrap_pool_connect
    return fn()
  File "/home/airflow/.local/lib/python3.7/site-packages/sqlalchemy/pool/base.py", line 310, in connect
    return _ConnectionFairy._checkout(self)
  File "/home/airflow/.local/lib/python3.7/site-packages/sqlalchemy/pool/base.py", line 868, in _checkout
    fairy = _ConnectionRecord.checkout(pool)
  File "/home/airflow/.local/lib/python3.7/site-packages/sqlalchemy/pool/base.py", line 476, in checkout
    rec = pool._do_get()
  File "/home/airflow/.local/lib/python3.7/site-packages/sqlalchemy/pool/impl.py", line 146, in _do_get
    self._dec_overflow()
  File "/home/airflow/.local/lib/python3.7/site-packages/sqlalchemy/util/langhelpers.py", line 72, in __exit__
    with_traceback=exc_tb,
  File "/home/airflow/.local/lib/python3.7/site-packages/sqlalchemy/util/compat.py", line 207, in raise_
    raise exception
  File "/home/airflow/.local/lib/python3.7/site-packages/sqlalchemy/pool/impl.py", line 143, in _do_get
    return self._create_connection()
  File "/home/airflow/.local/lib/python3.7/site-packages/sqlalchemy/pool/base.py", line 256, in _create_connection
    return _ConnectionRecord(self)
  File "/home/airflow/.local/lib/python3.7/site-packages/sqlalchemy/pool/base.py", line 371, in __init__
    self.__connect()
  File "/home/airflow/.local/lib/python3.7/site-packages/sqlalchemy/pool/base.py", line 666, in __connect
    pool.logger.debug("Error on connect(): %s", e)
  File "/home/airflow/.local/lib/python3.7/site-packages/sqlalchemy/util/langhelpers.py", line 72, in __exit__
    with_traceback=exc_tb,
  File "/home/airflow/.local/lib/python3.7/site-packages/sqlalchemy/util/compat.py", line 207, in raise_
    raise exception
  File "/home/airflow/.local/lib/python3.7/site-packages/sqlalchemy/pool/base.py", line 661, in __connect
    self.dbapi_connection = connection = pool._invoke_creator(self)
  File "/home/airflow/.local/lib/python3.7/site-packages/sqlalchemy/engine/create.py", line 590, in connect
    return dialect.connect(*cargs, **cparams)
  File "/home/airflow/.local/lib/python3.7/site-packages/sqlalchemy/engine/default.py", line 584, in connect
    return self.dbapi.connect(*cargs, **cparams)
  File "/home/airflow/.local/lib/python3.7/site-packages/psycopg2/__init__.py", line 122, in connect
    conn = _connect(dsn, connection_factory=connection_factory, **kwasync)
sqlalchemy.exc.OperationalError: (psycopg2.OperationalError) could not translate host name "postgres" to address: Temporary failure in name resolution

(Background on this error at: https://sqlalche.me/e/14/e3q8)
[2024-05-21T16:28:02.106+0000] {processor.py:156} INFO - Started process (PID=109) to work on /opt/airflow/dags/dags1.py
[2024-05-21T16:28:02.108+0000] {processor.py:758} INFO - Processing file /opt/airflow/dags/dags1.py for tasks to queue
[2024-05-21T16:28:02.109+0000] {logging_mixin.py:117} INFO - [2024-05-21T16:28:02.109+0000] {dagbag.py:525} INFO - Filling up the DagBag from /opt/airflow/dags/dags1.py
[2024-05-21T16:28:32.193+0000] {logging_mixin.py:117} INFO - [2024-05-21T16:28:32.186+0000] {timeout.py:68} ERROR - Process timed out, PID: 109
[2024-05-21T16:28:32.204+0000] {logging_mixin.py:117} WARNING - Exception ignored in: <module 'collections.abc' from '/usr/local/lib/python3.7/collections/abc.py'>
[2024-05-21T16:28:32.238+0000] {logging_mixin.py:117} WARNING - Traceback (most recent call last):
[2024-05-21T16:28:32.343+0000] {logging_mixin.py:117} WARNING -   File "<string>", line 1, in <module>
[2024-05-21T16:28:32.473+0000] {logging_mixin.py:117} WARNING -   File "/home/airflow/.local/lib/python3.7/site-packages/airflow/utils/timeout.py", line 69, in handle_timeout
[2024-05-21T16:28:32.541+0000] {logging_mixin.py:117} WARNING -     raise AirflowTaskTimeout(self.error_message)
[2024-05-21T16:28:32.656+0000] {logging_mixin.py:117} WARNING - airflow.exceptions.AirflowTaskTimeout: DagBag import timeout for /opt/airflow/dags/dags1.py after 30.0s.
Please take a look at these docs to improve your DAG import time:
* https://airflow.apache.org/docs/apache-airflow/2.4.1/best-practices.html#top-level-python-code
* https://airflow.apache.org/docs/apache-airflow/2.4.1/best-practices.html#reducing-dag-complexity, PID: 109
[2024-05-21T16:28:33.001+0000] {logging_mixin.py:117} WARNING - /usr/local/lib/python3.7/importlib/_bootstrap.py:219 RuntimeWarning: Cython module failed to patch module with custom type
[2024-05-21T16:29:19.060+0000] {processor.py:156} INFO - Started process (PID=112) to work on /opt/airflow/dags/dags1.py
[2024-05-21T16:29:19.069+0000] {processor.py:758} INFO - Processing file /opt/airflow/dags/dags1.py for tasks to queue
[2024-05-21T16:29:19.070+0000] {logging_mixin.py:117} INFO - [2024-05-21T16:29:19.069+0000] {dagbag.py:525} INFO - Filling up the DagBag from /opt/airflow/dags/dags1.py
[2024-05-21T16:29:57.073+0000] {processor.py:156} INFO - Started process (PID=117) to work on /opt/airflow/dags/dags1.py
[2024-05-21T16:29:57.075+0000] {processor.py:758} INFO - Processing file /opt/airflow/dags/dags1.py for tasks to queue
[2024-05-21T16:29:57.076+0000] {logging_mixin.py:117} INFO - [2024-05-21T16:29:57.075+0000] {dagbag.py:525} INFO - Filling up the DagBag from /opt/airflow/dags/dags1.py
[2024-05-21T16:31:49.227+0000] {processor.py:156} INFO - Started process (PID=122) to work on /opt/airflow/dags/dags1.py
[2024-05-21T16:31:49.241+0000] {processor.py:758} INFO - Processing file /opt/airflow/dags/dags1.py for tasks to queue
[2024-05-21T16:31:49.242+0000] {logging_mixin.py:117} INFO - [2024-05-21T16:31:49.242+0000] {dagbag.py:525} INFO - Filling up the DagBag from /opt/airflow/dags/dags1.py
[2024-05-21T16:33:47.649+0000] {logging_mixin.py:117} INFO - [2024-05-21T16:33:47.602+0000] {timeout.py:68} ERROR - Process timed out, PID: 122
[2024-05-21T16:33:47.779+0000] {logging_mixin.py:117} INFO - [2024-05-21T16:33:47.655+0000] {dagbag.py:330} ERROR - Failed to import: /opt/airflow/dags/dags1.py
Traceback (most recent call last):
  File "/home/airflow/.local/lib/python3.7/site-packages/airflow/models/dagbag.py", line 326, in parse
    loader.exec_module(new_module)
  File "<frozen importlib._bootstrap_external>", line 728, in exec_module
  File "<frozen importlib._bootstrap>", line 219, in _call_with_frames_removed
  File "/opt/airflow/dags/dags1.py", line 5, in <module>
    import pandas as pd
  File "/home/airflow/.local/lib/python3.7/site-packages/pandas/__init__.py", line 50, in <module>
    from pandas.core.api import (
  File "/home/airflow/.local/lib/python3.7/site-packages/pandas/core/api.py", line 24, in <module>
    from pandas.core.algorithms import (
  File "/home/airflow/.local/lib/python3.7/site-packages/pandas/core/algorithms.py", line 75, in <module>
    from pandas.core.array_algos.take import take_nd
  File "/home/airflow/.local/lib/python3.7/site-packages/pandas/core/array_algos/take.py", line 25, in <module>
    from pandas.core.construction import ensure_wrapped_if_datetimelike
  File "/home/airflow/.local/lib/python3.7/site-packages/pandas/core/construction.py", line 62, in <module>
    import pandas.core.common as com
  File "<frozen importlib._bootstrap>", line 194, in _lock_unlock_module
  File "/home/airflow/.local/lib/python3.7/site-packages/airflow/utils/timeout.py", line 69, in handle_timeout
    raise AirflowTaskTimeout(self.error_message)
airflow.exceptions.AirflowTaskTimeout: DagBag import timeout for /opt/airflow/dags/dags1.py after 30.0s.
Please take a look at these docs to improve your DAG import time:
* https://airflow.apache.org/docs/apache-airflow/2.4.1/best-practices.html#top-level-python-code
* https://airflow.apache.org/docs/apache-airflow/2.4.1/best-practices.html#reducing-dag-complexity, PID: 122
[2024-05-21T16:33:47.787+0000] {processor.py:770} WARNING - No viable dags retrieved from /opt/airflow/dags/dags1.py
