[2024-05-24T11:21:58.723+0000] {processor.py:156} INFO - Started process (PID=35) to work on /opt/airflow/dags/airflow_first_dag.py
[2024-05-24T11:21:58.724+0000] {processor.py:758} INFO - Processing file /opt/airflow/dags/airflow_first_dag.py for tasks to queue
[2024-05-24T11:21:58.725+0000] {logging_mixin.py:117} INFO - [2024-05-24T11:21:58.725+0000] {dagbag.py:525} INFO - Filling up the DagBag from /opt/airflow/dags/airflow_first_dag.py
[2024-05-24T11:21:58.813+0000] {processor.py:768} INFO - DAG(s) dict_keys(['airflow_first_dag']) retrieved from /opt/airflow/dags/airflow_first_dag.py
[2024-05-24T11:21:59.139+0000] {logging_mixin.py:117} INFO - [2024-05-24T11:21:59.139+0000] {dag.py:2573} INFO - Sync 1 DAGs
[2024-05-24T11:21:59.179+0000] {logging_mixin.py:117} INFO - [2024-05-24T11:21:59.178+0000] {dag.py:3328} INFO - Setting next_dagrun for airflow_first_dag to 2024-05-22T21:00:00+00:00, run_after=2024-05-23T21:00:00+00:00
[2024-05-24T11:21:59.225+0000] {processor.py:178} INFO - Processing /opt/airflow/dags/airflow_first_dag.py took 0.505 seconds
[2024-05-24T11:22:45.953+0000] {processor.py:156} INFO - Started process (PID=57) to work on /opt/airflow/dags/airflow_first_dag.py
[2024-05-24T11:22:45.961+0000] {processor.py:758} INFO - Processing file /opt/airflow/dags/airflow_first_dag.py for tasks to queue
[2024-05-24T11:22:45.968+0000] {logging_mixin.py:117} INFO - [2024-05-24T11:22:45.968+0000] {dagbag.py:525} INFO - Filling up the DagBag from /opt/airflow/dags/airflow_first_dag.py
[2024-05-24T11:22:47.422+0000] {processor.py:768} INFO - DAG(s) dict_keys(['airflow_first_dag']) retrieved from /opt/airflow/dags/airflow_first_dag.py
[2024-05-24T11:23:10.123+0000] {logging_mixin.py:117} INFO - [2024-05-24T11:23:10.119+0000] {dag.py:2573} INFO - Sync 1 DAGs
[2024-05-24T11:23:10.406+0000] {logging_mixin.py:117} INFO - [2024-05-24T11:23:10.405+0000] {dag.py:3328} INFO - Setting next_dagrun for airflow_first_dag to 2024-05-22T21:00:00+00:00, run_after=2024-05-23T21:00:00+00:00
[2024-05-24T11:23:10.774+0000] {processor.py:178} INFO - Processing /opt/airflow/dags/airflow_first_dag.py took 24.884 seconds
[2024-05-24T11:23:41.436+0000] {processor.py:156} INFO - Started process (PID=60) to work on /opt/airflow/dags/airflow_first_dag.py
[2024-05-24T11:23:41.449+0000] {processor.py:758} INFO - Processing file /opt/airflow/dags/airflow_first_dag.py for tasks to queue
[2024-05-24T11:23:41.474+0000] {logging_mixin.py:117} INFO - [2024-05-24T11:23:41.462+0000] {dagbag.py:525} INFO - Filling up the DagBag from /opt/airflow/dags/airflow_first_dag.py
[2024-05-24T11:23:42.818+0000] {processor.py:768} INFO - DAG(s) dict_keys(['airflow_first_dag']) retrieved from /opt/airflow/dags/airflow_first_dag.py
[2024-05-24T11:27:11.601+0000] {processor.py:156} INFO - Started process (PID=63) to work on /opt/airflow/dags/airflow_first_dag.py
[2024-05-24T11:27:11.613+0000] {processor.py:758} INFO - Processing file /opt/airflow/dags/airflow_first_dag.py for tasks to queue
[2024-05-24T11:27:11.614+0000] {logging_mixin.py:117} INFO - [2024-05-24T11:27:11.613+0000] {dagbag.py:525} INFO - Filling up the DagBag from /opt/airflow/dags/airflow_first_dag.py
[2024-05-24T11:27:12.382+0000] {processor.py:768} INFO - DAG(s) dict_keys(['airflow_first_dag']) retrieved from /opt/airflow/dags/airflow_first_dag.py
[2024-05-24T11:28:01.755+0000] {processor.py:156} INFO - Started process (PID=74) to work on /opt/airflow/dags/airflow_first_dag.py
[2024-05-24T11:28:01.759+0000] {processor.py:758} INFO - Processing file /opt/airflow/dags/airflow_first_dag.py for tasks to queue
[2024-05-24T11:28:01.767+0000] {logging_mixin.py:117} INFO - [2024-05-24T11:28:01.766+0000] {dagbag.py:525} INFO - Filling up the DagBag from /opt/airflow/dags/airflow_first_dag.py
[2024-05-24T11:28:07.611+0000] {processor.py:768} INFO - DAG(s) dict_keys(['airflow_first_dag']) retrieved from /opt/airflow/dags/airflow_first_dag.py
[2024-05-24T11:28:40.217+0000] {processor.py:181} ERROR - Got an exception! Propagating...
Traceback (most recent call last):
  File "/home/airflow/.local/lib/python3.7/site-packages/sqlalchemy/engine/base.py", line 3243, in _wrap_pool_connect
    return fn()
  File "/home/airflow/.local/lib/python3.7/site-packages/sqlalchemy/pool/base.py", line 310, in connect
    return _ConnectionFairy._checkout(self)
  File "/home/airflow/.local/lib/python3.7/site-packages/sqlalchemy/pool/base.py", line 868, in _checkout
    fairy = _ConnectionRecord.checkout(pool)
  File "/home/airflow/.local/lib/python3.7/site-packages/sqlalchemy/pool/base.py", line 476, in checkout
    rec = pool._do_get()
  File "/home/airflow/.local/lib/python3.7/site-packages/sqlalchemy/pool/impl.py", line 146, in _do_get
    self._dec_overflow()
  File "/home/airflow/.local/lib/python3.7/site-packages/sqlalchemy/util/langhelpers.py", line 72, in __exit__
    with_traceback=exc_tb,
  File "/home/airflow/.local/lib/python3.7/site-packages/sqlalchemy/util/compat.py", line 207, in raise_
    raise exception
  File "/home/airflow/.local/lib/python3.7/site-packages/sqlalchemy/pool/impl.py", line 143, in _do_get
    return self._create_connection()
  File "/home/airflow/.local/lib/python3.7/site-packages/sqlalchemy/pool/base.py", line 256, in _create_connection
    return _ConnectionRecord(self)
  File "/home/airflow/.local/lib/python3.7/site-packages/sqlalchemy/pool/base.py", line 371, in __init__
    self.__connect()
  File "/home/airflow/.local/lib/python3.7/site-packages/sqlalchemy/pool/base.py", line 666, in __connect
    pool.logger.debug("Error on connect(): %s", e)
  File "/home/airflow/.local/lib/python3.7/site-packages/sqlalchemy/util/langhelpers.py", line 72, in __exit__
    with_traceback=exc_tb,
  File "/home/airflow/.local/lib/python3.7/site-packages/sqlalchemy/util/compat.py", line 207, in raise_
    raise exception
  File "/home/airflow/.local/lib/python3.7/site-packages/sqlalchemy/pool/base.py", line 661, in __connect
    self.dbapi_connection = connection = pool._invoke_creator(self)
  File "/home/airflow/.local/lib/python3.7/site-packages/sqlalchemy/engine/create.py", line 590, in connect
    return dialect.connect(*cargs, **cparams)
  File "/home/airflow/.local/lib/python3.7/site-packages/sqlalchemy/engine/default.py", line 584, in connect
    return self.dbapi.connect(*cargs, **cparams)
  File "/home/airflow/.local/lib/python3.7/site-packages/psycopg2/__init__.py", line 122, in connect
    conn = _connect(dsn, connection_factory=connection_factory, **kwasync)
psycopg2.OperationalError: could not translate host name "postgres" to address: Temporary failure in name resolution


The above exception was the direct cause of the following exception:

Traceback (most recent call last):
  File "/home/airflow/.local/lib/python3.7/site-packages/airflow/dag_processing/processor.py", line 177, in _run_file_processor
    _handle_dag_file_processing()
  File "/home/airflow/.local/lib/python3.7/site-packages/airflow/dag_processing/processor.py", line 161, in _handle_dag_file_processing
    callback_requests=callback_requests,
  File "/home/airflow/.local/lib/python3.7/site-packages/airflow/utils/session.py", line 75, in wrapper
    return func(*args, session=session, **kwargs)
  File "/home/airflow/.local/lib/python3.7/site-packages/airflow/dag_processing/processor.py", line 783, in process_file
    dagbag.sync_to_db(processor_subdir=self._dag_directory, session=session)
  File "/home/airflow/.local/lib/python3.7/site-packages/airflow/utils/session.py", line 72, in wrapper
    return func(*args, **kwargs)
  File "/home/airflow/.local/lib/python3.7/site-packages/airflow/models/dagbag.py", line 632, in sync_to_db
    for attempt in run_with_db_retries(logger=self.log):
  File "/home/airflow/.local/lib/python3.7/site-packages/tenacity/__init__.py", line 384, in __iter__
    do = self.iter(retry_state=retry_state)
  File "/home/airflow/.local/lib/python3.7/site-packages/tenacity/__init__.py", line 362, in iter
    raise retry_exc.reraise()
  File "/home/airflow/.local/lib/python3.7/site-packages/tenacity/__init__.py", line 195, in reraise
    raise self.last_attempt.result()
  File "/usr/local/lib/python3.7/concurrent/futures/_base.py", line 428, in result
    return self.__get_result()
  File "/usr/local/lib/python3.7/concurrent/futures/_base.py", line 384, in __get_result
    raise self._exception
  File "/home/airflow/.local/lib/python3.7/site-packages/airflow/models/dagbag.py", line 644, in sync_to_db
    serialize_errors.extend(_serialize_dag_capturing_errors(dag, session))
  File "/home/airflow/.local/lib/python3.7/site-packages/airflow/models/dagbag.py", line 618, in _serialize_dag_capturing_errors
    session=session,
  File "/home/airflow/.local/lib/python3.7/site-packages/airflow/utils/session.py", line 72, in wrapper
    return func(*args, **kwargs)
  File "/home/airflow/.local/lib/python3.7/site-packages/airflow/models/serialized_dag.py", line 150, in write_dag
    (timezone.utcnow() - timedelta(seconds=min_update_interval)) < cls.last_updated,
  File "/home/airflow/.local/lib/python3.7/site-packages/sqlalchemy/orm/query.py", line 2810, in first
    return self.limit(1)._iter().first()
  File "/home/airflow/.local/lib/python3.7/site-packages/sqlalchemy/orm/query.py", line 2897, in _iter
    execution_options={"_sa_orm_load_options": self.load_options},
  File "/home/airflow/.local/lib/python3.7/site-packages/sqlalchemy/orm/session.py", line 1688, in execute
    conn = self._connection_for_bind(bind)
  File "/home/airflow/.local/lib/python3.7/site-packages/sqlalchemy/orm/session.py", line 1530, in _connection_for_bind
    engine, execution_options
  File "/home/airflow/.local/lib/python3.7/site-packages/sqlalchemy/orm/session.py", line 747, in _connection_for_bind
    conn = bind.connect()
  File "/home/airflow/.local/lib/python3.7/site-packages/sqlalchemy/engine/base.py", line 3197, in connect
    return self._connection_cls(self, close_with_result=close_with_result)
  File "/home/airflow/.local/lib/python3.7/site-packages/sqlalchemy/engine/base.py", line 96, in __init__
    else engine.raw_connection()
  File "/home/airflow/.local/lib/python3.7/site-packages/sqlalchemy/engine/base.py", line 3276, in raw_connection
    return self._wrap_pool_connect(self.pool.connect, _connection)
  File "/home/airflow/.local/lib/python3.7/site-packages/sqlalchemy/engine/base.py", line 3247, in _wrap_pool_connect
    e, dialect, self
  File "/home/airflow/.local/lib/python3.7/site-packages/sqlalchemy/engine/base.py", line 2101, in _handle_dbapi_exception_noconnection
    sqlalchemy_exception, with_traceback=exc_info[2], from_=e
  File "/home/airflow/.local/lib/python3.7/site-packages/sqlalchemy/util/compat.py", line 207, in raise_
    raise exception
  File "/home/airflow/.local/lib/python3.7/site-packages/sqlalchemy/engine/base.py", line 3243, in _wrap_pool_connect
    return fn()
  File "/home/airflow/.local/lib/python3.7/site-packages/sqlalchemy/pool/base.py", line 310, in connect
    return _ConnectionFairy._checkout(self)
  File "/home/airflow/.local/lib/python3.7/site-packages/sqlalchemy/pool/base.py", line 868, in _checkout
    fairy = _ConnectionRecord.checkout(pool)
  File "/home/airflow/.local/lib/python3.7/site-packages/sqlalchemy/pool/base.py", line 476, in checkout
    rec = pool._do_get()
  File "/home/airflow/.local/lib/python3.7/site-packages/sqlalchemy/pool/impl.py", line 146, in _do_get
    self._dec_overflow()
  File "/home/airflow/.local/lib/python3.7/site-packages/sqlalchemy/util/langhelpers.py", line 72, in __exit__
    with_traceback=exc_tb,
  File "/home/airflow/.local/lib/python3.7/site-packages/sqlalchemy/util/compat.py", line 207, in raise_
    raise exception
  File "/home/airflow/.local/lib/python3.7/site-packages/sqlalchemy/pool/impl.py", line 143, in _do_get
    return self._create_connection()
  File "/home/airflow/.local/lib/python3.7/site-packages/sqlalchemy/pool/base.py", line 256, in _create_connection
    return _ConnectionRecord(self)
  File "/home/airflow/.local/lib/python3.7/site-packages/sqlalchemy/pool/base.py", line 371, in __init__
    self.__connect()
  File "/home/airflow/.local/lib/python3.7/site-packages/sqlalchemy/pool/base.py", line 666, in __connect
    pool.logger.debug("Error on connect(): %s", e)
  File "/home/airflow/.local/lib/python3.7/site-packages/sqlalchemy/util/langhelpers.py", line 72, in __exit__
    with_traceback=exc_tb,
  File "/home/airflow/.local/lib/python3.7/site-packages/sqlalchemy/util/compat.py", line 207, in raise_
    raise exception
  File "/home/airflow/.local/lib/python3.7/site-packages/sqlalchemy/pool/base.py", line 661, in __connect
    self.dbapi_connection = connection = pool._invoke_creator(self)
  File "/home/airflow/.local/lib/python3.7/site-packages/sqlalchemy/engine/create.py", line 590, in connect
    return dialect.connect(*cargs, **cparams)
  File "/home/airflow/.local/lib/python3.7/site-packages/sqlalchemy/engine/default.py", line 584, in connect
    return self.dbapi.connect(*cargs, **cparams)
  File "/home/airflow/.local/lib/python3.7/site-packages/psycopg2/__init__.py", line 122, in connect
    conn = _connect(dsn, connection_factory=connection_factory, **kwasync)
sqlalchemy.exc.OperationalError: (psycopg2.OperationalError) could not translate host name "postgres" to address: Temporary failure in name resolution

(Background on this error at: https://sqlalche.me/e/14/e3q8)
[2024-05-24T11:29:10.839+0000] {processor.py:156} INFO - Started process (PID=86) to work on /opt/airflow/dags/airflow_first_dag.py
[2024-05-24T11:29:10.855+0000] {processor.py:758} INFO - Processing file /opt/airflow/dags/airflow_first_dag.py for tasks to queue
[2024-05-24T11:29:10.859+0000] {logging_mixin.py:117} INFO - [2024-05-24T11:29:10.859+0000] {dagbag.py:525} INFO - Filling up the DagBag from /opt/airflow/dags/airflow_first_dag.py
[2024-05-24T11:29:12.672+0000] {processor.py:768} INFO - DAG(s) dict_keys(['airflow_first_dag']) retrieved from /opt/airflow/dags/airflow_first_dag.py
[2024-05-24T11:32:25.039+0000] {processor.py:156} INFO - Started process (PID=35) to work on /opt/airflow/dags/airflow_first_dag.py
[2024-05-24T11:32:25.040+0000] {processor.py:758} INFO - Processing file /opt/airflow/dags/airflow_first_dag.py for tasks to queue
[2024-05-24T11:32:25.041+0000] {logging_mixin.py:117} INFO - [2024-05-24T11:32:25.040+0000] {dagbag.py:525} INFO - Filling up the DagBag from /opt/airflow/dags/airflow_first_dag.py
[2024-05-24T11:32:25.071+0000] {processor.py:768} INFO - DAG(s) dict_keys(['airflow_first_dag']) retrieved from /opt/airflow/dags/airflow_first_dag.py
[2024-05-24T11:32:25.257+0000] {logging_mixin.py:117} INFO - [2024-05-24T11:32:25.257+0000] {dag.py:2573} INFO - Sync 1 DAGs
[2024-05-24T11:32:25.288+0000] {logging_mixin.py:117} INFO - [2024-05-24T11:32:25.287+0000] {dag.py:3328} INFO - Setting next_dagrun for airflow_first_dag to 2024-05-22T21:00:00+00:00, run_after=2024-05-23T21:00:00+00:00
[2024-05-24T11:32:25.314+0000] {processor.py:178} INFO - Processing /opt/airflow/dags/airflow_first_dag.py took 0.277 seconds
[2024-05-24T11:32:55.499+0000] {processor.py:156} INFO - Started process (PID=63) to work on /opt/airflow/dags/airflow_first_dag.py
[2024-05-24T11:32:55.500+0000] {processor.py:758} INFO - Processing file /opt/airflow/dags/airflow_first_dag.py for tasks to queue
[2024-05-24T11:32:55.503+0000] {logging_mixin.py:117} INFO - [2024-05-24T11:32:55.503+0000] {dagbag.py:525} INFO - Filling up the DagBag from /opt/airflow/dags/airflow_first_dag.py
[2024-05-24T11:32:55.600+0000] {processor.py:768} INFO - DAG(s) dict_keys(['airflow_first_dag']) retrieved from /opt/airflow/dags/airflow_first_dag.py
[2024-05-24T11:32:56.905+0000] {logging_mixin.py:117} INFO - [2024-05-24T11:32:56.904+0000] {dag.py:2573} INFO - Sync 1 DAGs
[2024-05-24T11:32:56.930+0000] {logging_mixin.py:117} INFO - [2024-05-24T11:32:56.930+0000] {dag.py:3328} INFO - Setting next_dagrun for airflow_first_dag to 2024-05-22T21:00:00+00:00, run_after=2024-05-23T21:00:00+00:00
[2024-05-24T11:32:56.950+0000] {processor.py:178} INFO - Processing /opt/airflow/dags/airflow_first_dag.py took 1.453 seconds
[2024-05-24T11:33:47.810+0000] {processor.py:156} INFO - Started process (PID=34) to work on /opt/airflow/dags/airflow_first_dag.py
[2024-05-24T11:33:47.810+0000] {processor.py:758} INFO - Processing file /opt/airflow/dags/airflow_first_dag.py for tasks to queue
[2024-05-24T11:33:47.811+0000] {logging_mixin.py:117} INFO - [2024-05-24T11:33:47.811+0000] {dagbag.py:525} INFO - Filling up the DagBag from /opt/airflow/dags/airflow_first_dag.py
[2024-05-24T11:33:47.857+0000] {processor.py:768} INFO - DAG(s) dict_keys(['airflow_first_dag']) retrieved from /opt/airflow/dags/airflow_first_dag.py
[2024-05-24T11:33:47.920+0000] {logging_mixin.py:117} INFO - [2024-05-24T11:33:47.920+0000] {dag.py:2573} INFO - Sync 1 DAGs
[2024-05-24T11:33:48.137+0000] {logging_mixin.py:117} INFO - [2024-05-24T11:33:48.137+0000] {dag.py:3328} INFO - Setting next_dagrun for airflow_first_dag to 2024-05-22T21:00:00+00:00, run_after=2024-05-23T21:00:00+00:00
[2024-05-24T11:33:48.176+0000] {processor.py:178} INFO - Processing /opt/airflow/dags/airflow_first_dag.py took 0.369 seconds
[2024-05-24T11:34:18.424+0000] {processor.py:156} INFO - Started process (PID=53) to work on /opt/airflow/dags/airflow_first_dag.py
[2024-05-24T11:34:18.427+0000] {processor.py:758} INFO - Processing file /opt/airflow/dags/airflow_first_dag.py for tasks to queue
[2024-05-24T11:34:18.433+0000] {logging_mixin.py:117} INFO - [2024-05-24T11:34:18.433+0000] {dagbag.py:525} INFO - Filling up the DagBag from /opt/airflow/dags/airflow_first_dag.py
[2024-05-24T11:34:18.881+0000] {processor.py:768} INFO - DAG(s) dict_keys(['airflow_first_dag']) retrieved from /opt/airflow/dags/airflow_first_dag.py
[2024-05-24T11:34:54.173+0000] {processor.py:181} ERROR - Got an exception! Propagating...
Traceback (most recent call last):
  File "/home/airflow/.local/lib/python3.7/site-packages/sqlalchemy/engine/base.py", line 3243, in _wrap_pool_connect
    return fn()
  File "/home/airflow/.local/lib/python3.7/site-packages/sqlalchemy/pool/base.py", line 310, in connect
    return _ConnectionFairy._checkout(self)
  File "/home/airflow/.local/lib/python3.7/site-packages/sqlalchemy/pool/base.py", line 868, in _checkout
    fairy = _ConnectionRecord.checkout(pool)
  File "/home/airflow/.local/lib/python3.7/site-packages/sqlalchemy/pool/base.py", line 476, in checkout
    rec = pool._do_get()
  File "/home/airflow/.local/lib/python3.7/site-packages/sqlalchemy/pool/impl.py", line 146, in _do_get
    self._dec_overflow()
  File "/home/airflow/.local/lib/python3.7/site-packages/sqlalchemy/util/langhelpers.py", line 72, in __exit__
    with_traceback=exc_tb,
  File "/home/airflow/.local/lib/python3.7/site-packages/sqlalchemy/util/compat.py", line 207, in raise_
    raise exception
  File "/home/airflow/.local/lib/python3.7/site-packages/sqlalchemy/pool/impl.py", line 143, in _do_get
    return self._create_connection()
  File "/home/airflow/.local/lib/python3.7/site-packages/sqlalchemy/pool/base.py", line 256, in _create_connection
    return _ConnectionRecord(self)
  File "/home/airflow/.local/lib/python3.7/site-packages/sqlalchemy/pool/base.py", line 371, in __init__
    self.__connect()
  File "/home/airflow/.local/lib/python3.7/site-packages/sqlalchemy/pool/base.py", line 666, in __connect
    pool.logger.debug("Error on connect(): %s", e)
  File "/home/airflow/.local/lib/python3.7/site-packages/sqlalchemy/util/langhelpers.py", line 72, in __exit__
    with_traceback=exc_tb,
  File "/home/airflow/.local/lib/python3.7/site-packages/sqlalchemy/util/compat.py", line 207, in raise_
    raise exception
  File "/home/airflow/.local/lib/python3.7/site-packages/sqlalchemy/pool/base.py", line 661, in __connect
    self.dbapi_connection = connection = pool._invoke_creator(self)
  File "/home/airflow/.local/lib/python3.7/site-packages/sqlalchemy/engine/create.py", line 590, in connect
    return dialect.connect(*cargs, **cparams)
  File "/home/airflow/.local/lib/python3.7/site-packages/sqlalchemy/engine/default.py", line 584, in connect
    return self.dbapi.connect(*cargs, **cparams)
  File "/home/airflow/.local/lib/python3.7/site-packages/psycopg2/__init__.py", line 122, in connect
    conn = _connect(dsn, connection_factory=connection_factory, **kwasync)
psycopg2.OperationalError: could not translate host name "postgres" to address: Temporary failure in name resolution


The above exception was the direct cause of the following exception:

Traceback (most recent call last):
  File "/home/airflow/.local/lib/python3.7/site-packages/airflow/dag_processing/processor.py", line 177, in _run_file_processor
    _handle_dag_file_processing()
  File "/home/airflow/.local/lib/python3.7/site-packages/airflow/dag_processing/processor.py", line 161, in _handle_dag_file_processing
    callback_requests=callback_requests,
  File "/home/airflow/.local/lib/python3.7/site-packages/airflow/utils/session.py", line 75, in wrapper
    return func(*args, session=session, **kwargs)
  File "/home/airflow/.local/lib/python3.7/site-packages/airflow/dag_processing/processor.py", line 783, in process_file
    dagbag.sync_to_db(processor_subdir=self._dag_directory, session=session)
  File "/home/airflow/.local/lib/python3.7/site-packages/airflow/utils/session.py", line 72, in wrapper
    return func(*args, **kwargs)
  File "/home/airflow/.local/lib/python3.7/site-packages/airflow/models/dagbag.py", line 632, in sync_to_db
    for attempt in run_with_db_retries(logger=self.log):
  File "/home/airflow/.local/lib/python3.7/site-packages/tenacity/__init__.py", line 384, in __iter__
    do = self.iter(retry_state=retry_state)
  File "/home/airflow/.local/lib/python3.7/site-packages/tenacity/__init__.py", line 362, in iter
    raise retry_exc.reraise()
  File "/home/airflow/.local/lib/python3.7/site-packages/tenacity/__init__.py", line 195, in reraise
    raise self.last_attempt.result()
  File "/usr/local/lib/python3.7/concurrent/futures/_base.py", line 428, in result
    return self.__get_result()
  File "/usr/local/lib/python3.7/concurrent/futures/_base.py", line 384, in __get_result
    raise self._exception
  File "/home/airflow/.local/lib/python3.7/site-packages/airflow/models/dagbag.py", line 644, in sync_to_db
    serialize_errors.extend(_serialize_dag_capturing_errors(dag, session))
  File "/home/airflow/.local/lib/python3.7/site-packages/airflow/models/dagbag.py", line 618, in _serialize_dag_capturing_errors
    session=session,
  File "/home/airflow/.local/lib/python3.7/site-packages/airflow/utils/session.py", line 72, in wrapper
    return func(*args, **kwargs)
  File "/home/airflow/.local/lib/python3.7/site-packages/airflow/models/serialized_dag.py", line 150, in write_dag
    (timezone.utcnow() - timedelta(seconds=min_update_interval)) < cls.last_updated,
  File "/home/airflow/.local/lib/python3.7/site-packages/sqlalchemy/orm/query.py", line 2810, in first
    return self.limit(1)._iter().first()
  File "/home/airflow/.local/lib/python3.7/site-packages/sqlalchemy/orm/query.py", line 2897, in _iter
    execution_options={"_sa_orm_load_options": self.load_options},
  File "/home/airflow/.local/lib/python3.7/site-packages/sqlalchemy/orm/session.py", line 1688, in execute
    conn = self._connection_for_bind(bind)
  File "/home/airflow/.local/lib/python3.7/site-packages/sqlalchemy/orm/session.py", line 1530, in _connection_for_bind
    engine, execution_options
  File "/home/airflow/.local/lib/python3.7/site-packages/sqlalchemy/orm/session.py", line 747, in _connection_for_bind
    conn = bind.connect()
  File "/home/airflow/.local/lib/python3.7/site-packages/sqlalchemy/engine/base.py", line 3197, in connect
    return self._connection_cls(self, close_with_result=close_with_result)
  File "/home/airflow/.local/lib/python3.7/site-packages/sqlalchemy/engine/base.py", line 96, in __init__
    else engine.raw_connection()
  File "/home/airflow/.local/lib/python3.7/site-packages/sqlalchemy/engine/base.py", line 3276, in raw_connection
    return self._wrap_pool_connect(self.pool.connect, _connection)
  File "/home/airflow/.local/lib/python3.7/site-packages/sqlalchemy/engine/base.py", line 3247, in _wrap_pool_connect
    e, dialect, self
  File "/home/airflow/.local/lib/python3.7/site-packages/sqlalchemy/engine/base.py", line 2101, in _handle_dbapi_exception_noconnection
    sqlalchemy_exception, with_traceback=exc_info[2], from_=e
  File "/home/airflow/.local/lib/python3.7/site-packages/sqlalchemy/util/compat.py", line 207, in raise_
    raise exception
  File "/home/airflow/.local/lib/python3.7/site-packages/sqlalchemy/engine/base.py", line 3243, in _wrap_pool_connect
    return fn()
  File "/home/airflow/.local/lib/python3.7/site-packages/sqlalchemy/pool/base.py", line 310, in connect
    return _ConnectionFairy._checkout(self)
  File "/home/airflow/.local/lib/python3.7/site-packages/sqlalchemy/pool/base.py", line 868, in _checkout
    fairy = _ConnectionRecord.checkout(pool)
  File "/home/airflow/.local/lib/python3.7/site-packages/sqlalchemy/pool/base.py", line 476, in checkout
    rec = pool._do_get()
  File "/home/airflow/.local/lib/python3.7/site-packages/sqlalchemy/pool/impl.py", line 146, in _do_get
    self._dec_overflow()
  File "/home/airflow/.local/lib/python3.7/site-packages/sqlalchemy/util/langhelpers.py", line 72, in __exit__
    with_traceback=exc_tb,
  File "/home/airflow/.local/lib/python3.7/site-packages/sqlalchemy/util/compat.py", line 207, in raise_
    raise exception
  File "/home/airflow/.local/lib/python3.7/site-packages/sqlalchemy/pool/impl.py", line 143, in _do_get
    return self._create_connection()
  File "/home/airflow/.local/lib/python3.7/site-packages/sqlalchemy/pool/base.py", line 256, in _create_connection
    return _ConnectionRecord(self)
  File "/home/airflow/.local/lib/python3.7/site-packages/sqlalchemy/pool/base.py", line 371, in __init__
    self.__connect()
  File "/home/airflow/.local/lib/python3.7/site-packages/sqlalchemy/pool/base.py", line 666, in __connect
    pool.logger.debug("Error on connect(): %s", e)
  File "/home/airflow/.local/lib/python3.7/site-packages/sqlalchemy/util/langhelpers.py", line 72, in __exit__
    with_traceback=exc_tb,
  File "/home/airflow/.local/lib/python3.7/site-packages/sqlalchemy/util/compat.py", line 207, in raise_
    raise exception
  File "/home/airflow/.local/lib/python3.7/site-packages/sqlalchemy/pool/base.py", line 661, in __connect
    self.dbapi_connection = connection = pool._invoke_creator(self)
  File "/home/airflow/.local/lib/python3.7/site-packages/sqlalchemy/engine/create.py", line 590, in connect
    return dialect.connect(*cargs, **cparams)
  File "/home/airflow/.local/lib/python3.7/site-packages/sqlalchemy/engine/default.py", line 584, in connect
    return self.dbapi.connect(*cargs, **cparams)
  File "/home/airflow/.local/lib/python3.7/site-packages/psycopg2/__init__.py", line 122, in connect
    conn = _connect(dsn, connection_factory=connection_factory, **kwasync)
sqlalchemy.exc.OperationalError: (psycopg2.OperationalError) could not translate host name "postgres" to address: Temporary failure in name resolution

(Background on this error at: https://sqlalche.me/e/14/e3q8)
[2024-05-24T11:35:28.795+0000] {processor.py:156} INFO - Started process (PID=65) to work on /opt/airflow/dags/airflow_first_dag.py
[2024-05-24T11:35:28.797+0000] {processor.py:758} INFO - Processing file /opt/airflow/dags/airflow_first_dag.py for tasks to queue
[2024-05-24T11:35:28.798+0000] {logging_mixin.py:117} INFO - [2024-05-24T11:35:28.798+0000] {dagbag.py:525} INFO - Filling up the DagBag from /opt/airflow/dags/airflow_first_dag.py
[2024-05-24T11:35:29.874+0000] {processor.py:768} INFO - DAG(s) dict_keys(['airflow_first_dag']) retrieved from /opt/airflow/dags/airflow_first_dag.py
[2024-05-24T11:36:44.876+0000] {logging_mixin.py:117} INFO - [2024-05-24T11:36:44.873+0000] {process_utils.py:256} INFO - Waiting up to 5 seconds for processes to exit...
[2024-05-24T11:36:45.723+0000] {processor.py:156} INFO - Started process (PID=69) to work on /opt/airflow/dags/airflow_first_dag.py
[2024-05-24T11:36:45.724+0000] {processor.py:758} INFO - Processing file /opt/airflow/dags/airflow_first_dag.py for tasks to queue
[2024-05-24T11:36:45.728+0000] {logging_mixin.py:117} INFO - [2024-05-24T11:36:45.728+0000] {dagbag.py:525} INFO - Filling up the DagBag from /opt/airflow/dags/airflow_first_dag.py
[2024-05-24T11:36:45.905+0000] {processor.py:768} INFO - DAG(s) dict_keys(['airflow_first_dag']) retrieved from /opt/airflow/dags/airflow_first_dag.py
[2024-05-24T11:36:46.067+0000] {logging_mixin.py:117} INFO - [2024-05-24T11:36:46.067+0000] {dag.py:2573} INFO - Sync 1 DAGs
[2024-05-24T11:36:46.138+0000] {logging_mixin.py:117} INFO - [2024-05-24T11:36:46.137+0000] {dag.py:3328} INFO - Setting next_dagrun for airflow_first_dag to 2024-05-22T21:00:00+00:00, run_after=2024-05-23T21:00:00+00:00
[2024-05-24T11:36:46.180+0000] {processor.py:178} INFO - Processing /opt/airflow/dags/airflow_first_dag.py took 0.461 seconds
[2024-05-24T11:37:16.772+0000] {processor.py:156} INFO - Started process (PID=89) to work on /opt/airflow/dags/airflow_first_dag.py
[2024-05-24T11:37:16.779+0000] {processor.py:758} INFO - Processing file /opt/airflow/dags/airflow_first_dag.py for tasks to queue
[2024-05-24T11:37:16.781+0000] {logging_mixin.py:117} INFO - [2024-05-24T11:37:16.780+0000] {dagbag.py:525} INFO - Filling up the DagBag from /opt/airflow/dags/airflow_first_dag.py
[2024-05-24T11:37:18.134+0000] {processor.py:768} INFO - DAG(s) dict_keys(['airflow_first_dag']) retrieved from /opt/airflow/dags/airflow_first_dag.py
[2024-05-24T11:37:33.572+0000] {logging_mixin.py:117} INFO - [2024-05-24T11:37:33.572+0000] {dag.py:2573} INFO - Sync 1 DAGs
[2024-05-24T11:37:33.661+0000] {logging_mixin.py:117} INFO - [2024-05-24T11:37:33.660+0000] {dag.py:3328} INFO - Setting next_dagrun for airflow_first_dag to 2024-05-22T21:00:00+00:00, run_after=2024-05-23T21:00:00+00:00
[2024-05-24T11:37:33.709+0000] {processor.py:178} INFO - Processing /opt/airflow/dags/airflow_first_dag.py took 16.949 seconds
[2024-05-24T11:38:03.853+0000] {processor.py:156} INFO - Started process (PID=93) to work on /opt/airflow/dags/airflow_first_dag.py
[2024-05-24T11:38:03.859+0000] {processor.py:758} INFO - Processing file /opt/airflow/dags/airflow_first_dag.py for tasks to queue
[2024-05-24T11:38:03.867+0000] {logging_mixin.py:117} INFO - [2024-05-24T11:38:03.866+0000] {dagbag.py:525} INFO - Filling up the DagBag from /opt/airflow/dags/airflow_first_dag.py
[2024-05-24T11:38:10.417+0000] {processor.py:768} INFO - DAG(s) dict_keys(['airflow_first_dag']) retrieved from /opt/airflow/dags/airflow_first_dag.py
[2024-05-24T11:38:42.282+0000] {processor.py:181} ERROR - Got an exception! Propagating...
Traceback (most recent call last):
  File "/home/airflow/.local/lib/python3.7/site-packages/sqlalchemy/engine/base.py", line 3243, in _wrap_pool_connect
    return fn()
  File "/home/airflow/.local/lib/python3.7/site-packages/sqlalchemy/pool/base.py", line 310, in connect
    return _ConnectionFairy._checkout(self)
  File "/home/airflow/.local/lib/python3.7/site-packages/sqlalchemy/pool/base.py", line 868, in _checkout
    fairy = _ConnectionRecord.checkout(pool)
  File "/home/airflow/.local/lib/python3.7/site-packages/sqlalchemy/pool/base.py", line 476, in checkout
    rec = pool._do_get()
  File "/home/airflow/.local/lib/python3.7/site-packages/sqlalchemy/pool/impl.py", line 146, in _do_get
    self._dec_overflow()
  File "/home/airflow/.local/lib/python3.7/site-packages/sqlalchemy/util/langhelpers.py", line 72, in __exit__
    with_traceback=exc_tb,
  File "/home/airflow/.local/lib/python3.7/site-packages/sqlalchemy/util/compat.py", line 207, in raise_
    raise exception
  File "/home/airflow/.local/lib/python3.7/site-packages/sqlalchemy/pool/impl.py", line 143, in _do_get
    return self._create_connection()
  File "/home/airflow/.local/lib/python3.7/site-packages/sqlalchemy/pool/base.py", line 256, in _create_connection
    return _ConnectionRecord(self)
  File "/home/airflow/.local/lib/python3.7/site-packages/sqlalchemy/pool/base.py", line 371, in __init__
    self.__connect()
  File "/home/airflow/.local/lib/python3.7/site-packages/sqlalchemy/pool/base.py", line 666, in __connect
    pool.logger.debug("Error on connect(): %s", e)
  File "/home/airflow/.local/lib/python3.7/site-packages/sqlalchemy/util/langhelpers.py", line 72, in __exit__
    with_traceback=exc_tb,
  File "/home/airflow/.local/lib/python3.7/site-packages/sqlalchemy/util/compat.py", line 207, in raise_
    raise exception
  File "/home/airflow/.local/lib/python3.7/site-packages/sqlalchemy/pool/base.py", line 661, in __connect
    self.dbapi_connection = connection = pool._invoke_creator(self)
  File "/home/airflow/.local/lib/python3.7/site-packages/sqlalchemy/engine/create.py", line 590, in connect
    return dialect.connect(*cargs, **cparams)
  File "/home/airflow/.local/lib/python3.7/site-packages/sqlalchemy/engine/default.py", line 584, in connect
    return self.dbapi.connect(*cargs, **cparams)
  File "/home/airflow/.local/lib/python3.7/site-packages/psycopg2/__init__.py", line 122, in connect
    conn = _connect(dsn, connection_factory=connection_factory, **kwasync)
psycopg2.OperationalError: could not translate host name "postgres" to address: Temporary failure in name resolution


The above exception was the direct cause of the following exception:

Traceback (most recent call last):
  File "/home/airflow/.local/lib/python3.7/site-packages/airflow/dag_processing/processor.py", line 177, in _run_file_processor
    _handle_dag_file_processing()
  File "/home/airflow/.local/lib/python3.7/site-packages/airflow/dag_processing/processor.py", line 161, in _handle_dag_file_processing
    callback_requests=callback_requests,
  File "/home/airflow/.local/lib/python3.7/site-packages/airflow/utils/session.py", line 75, in wrapper
    return func(*args, session=session, **kwargs)
  File "/home/airflow/.local/lib/python3.7/site-packages/airflow/dag_processing/processor.py", line 783, in process_file
    dagbag.sync_to_db(processor_subdir=self._dag_directory, session=session)
  File "/home/airflow/.local/lib/python3.7/site-packages/airflow/utils/session.py", line 72, in wrapper
    return func(*args, **kwargs)
  File "/home/airflow/.local/lib/python3.7/site-packages/airflow/models/dagbag.py", line 632, in sync_to_db
    for attempt in run_with_db_retries(logger=self.log):
  File "/home/airflow/.local/lib/python3.7/site-packages/tenacity/__init__.py", line 384, in __iter__
    do = self.iter(retry_state=retry_state)
  File "/home/airflow/.local/lib/python3.7/site-packages/tenacity/__init__.py", line 362, in iter
    raise retry_exc.reraise()
  File "/home/airflow/.local/lib/python3.7/site-packages/tenacity/__init__.py", line 195, in reraise
    raise self.last_attempt.result()
  File "/usr/local/lib/python3.7/concurrent/futures/_base.py", line 428, in result
    return self.__get_result()
  File "/usr/local/lib/python3.7/concurrent/futures/_base.py", line 384, in __get_result
    raise self._exception
  File "/home/airflow/.local/lib/python3.7/site-packages/airflow/models/dagbag.py", line 644, in sync_to_db
    serialize_errors.extend(_serialize_dag_capturing_errors(dag, session))
  File "/home/airflow/.local/lib/python3.7/site-packages/airflow/models/dagbag.py", line 618, in _serialize_dag_capturing_errors
    session=session,
  File "/home/airflow/.local/lib/python3.7/site-packages/airflow/utils/session.py", line 72, in wrapper
    return func(*args, **kwargs)
  File "/home/airflow/.local/lib/python3.7/site-packages/airflow/models/serialized_dag.py", line 150, in write_dag
    (timezone.utcnow() - timedelta(seconds=min_update_interval)) < cls.last_updated,
  File "/home/airflow/.local/lib/python3.7/site-packages/sqlalchemy/orm/query.py", line 2810, in first
    return self.limit(1)._iter().first()
  File "/home/airflow/.local/lib/python3.7/site-packages/sqlalchemy/orm/query.py", line 2897, in _iter
    execution_options={"_sa_orm_load_options": self.load_options},
  File "/home/airflow/.local/lib/python3.7/site-packages/sqlalchemy/orm/session.py", line 1688, in execute
    conn = self._connection_for_bind(bind)
  File "/home/airflow/.local/lib/python3.7/site-packages/sqlalchemy/orm/session.py", line 1530, in _connection_for_bind
    engine, execution_options
  File "/home/airflow/.local/lib/python3.7/site-packages/sqlalchemy/orm/session.py", line 747, in _connection_for_bind
    conn = bind.connect()
  File "/home/airflow/.local/lib/python3.7/site-packages/sqlalchemy/engine/base.py", line 3197, in connect
    return self._connection_cls(self, close_with_result=close_with_result)
  File "/home/airflow/.local/lib/python3.7/site-packages/sqlalchemy/engine/base.py", line 96, in __init__
    else engine.raw_connection()
  File "/home/airflow/.local/lib/python3.7/site-packages/sqlalchemy/engine/base.py", line 3276, in raw_connection
    return self._wrap_pool_connect(self.pool.connect, _connection)
  File "/home/airflow/.local/lib/python3.7/site-packages/sqlalchemy/engine/base.py", line 3247, in _wrap_pool_connect
    e, dialect, self
  File "/home/airflow/.local/lib/python3.7/site-packages/sqlalchemy/engine/base.py", line 2101, in _handle_dbapi_exception_noconnection
    sqlalchemy_exception, with_traceback=exc_info[2], from_=e
  File "/home/airflow/.local/lib/python3.7/site-packages/sqlalchemy/util/compat.py", line 207, in raise_
    raise exception
  File "/home/airflow/.local/lib/python3.7/site-packages/sqlalchemy/engine/base.py", line 3243, in _wrap_pool_connect
    return fn()
  File "/home/airflow/.local/lib/python3.7/site-packages/sqlalchemy/pool/base.py", line 310, in connect
    return _ConnectionFairy._checkout(self)
  File "/home/airflow/.local/lib/python3.7/site-packages/sqlalchemy/pool/base.py", line 868, in _checkout
    fairy = _ConnectionRecord.checkout(pool)
  File "/home/airflow/.local/lib/python3.7/site-packages/sqlalchemy/pool/base.py", line 476, in checkout
    rec = pool._do_get()
  File "/home/airflow/.local/lib/python3.7/site-packages/sqlalchemy/pool/impl.py", line 146, in _do_get
    self._dec_overflow()
  File "/home/airflow/.local/lib/python3.7/site-packages/sqlalchemy/util/langhelpers.py", line 72, in __exit__
    with_traceback=exc_tb,
  File "/home/airflow/.local/lib/python3.7/site-packages/sqlalchemy/util/compat.py", line 207, in raise_
    raise exception
  File "/home/airflow/.local/lib/python3.7/site-packages/sqlalchemy/pool/impl.py", line 143, in _do_get
    return self._create_connection()
  File "/home/airflow/.local/lib/python3.7/site-packages/sqlalchemy/pool/base.py", line 256, in _create_connection
    return _ConnectionRecord(self)
  File "/home/airflow/.local/lib/python3.7/site-packages/sqlalchemy/pool/base.py", line 371, in __init__
    self.__connect()
  File "/home/airflow/.local/lib/python3.7/site-packages/sqlalchemy/pool/base.py", line 666, in __connect
    pool.logger.debug("Error on connect(): %s", e)
  File "/home/airflow/.local/lib/python3.7/site-packages/sqlalchemy/util/langhelpers.py", line 72, in __exit__
    with_traceback=exc_tb,
  File "/home/airflow/.local/lib/python3.7/site-packages/sqlalchemy/util/compat.py", line 207, in raise_
    raise exception
  File "/home/airflow/.local/lib/python3.7/site-packages/sqlalchemy/pool/base.py", line 661, in __connect
    self.dbapi_connection = connection = pool._invoke_creator(self)
  File "/home/airflow/.local/lib/python3.7/site-packages/sqlalchemy/engine/create.py", line 590, in connect
    return dialect.connect(*cargs, **cparams)
  File "/home/airflow/.local/lib/python3.7/site-packages/sqlalchemy/engine/default.py", line 584, in connect
    return self.dbapi.connect(*cargs, **cparams)
  File "/home/airflow/.local/lib/python3.7/site-packages/psycopg2/__init__.py", line 122, in connect
    conn = _connect(dsn, connection_factory=connection_factory, **kwasync)
sqlalchemy.exc.OperationalError: (psycopg2.OperationalError) could not translate host name "postgres" to address: Temporary failure in name resolution

(Background on this error at: https://sqlalche.me/e/14/e3q8)
[2024-05-24T11:39:33.844+0000] {processor.py:156} INFO - Started process (PID=96) to work on /opt/airflow/dags/airflow_first_dag.py
[2024-05-24T11:39:33.846+0000] {processor.py:758} INFO - Processing file /opt/airflow/dags/airflow_first_dag.py for tasks to queue
[2024-05-24T11:39:33.847+0000] {logging_mixin.py:117} INFO - [2024-05-24T11:39:33.847+0000] {dagbag.py:525} INFO - Filling up the DagBag from /opt/airflow/dags/airflow_first_dag.py
[2024-05-24T11:39:34.120+0000] {processor.py:768} INFO - DAG(s) dict_keys(['airflow_first_dag']) retrieved from /opt/airflow/dags/airflow_first_dag.py
[2024-05-24T11:39:46.234+0000] {logging_mixin.py:117} INFO - [2024-05-24T11:39:46.224+0000] {dag.py:2573} INFO - Sync 1 DAGs
[2024-05-24T11:39:46.350+0000] {logging_mixin.py:117} INFO - [2024-05-24T11:39:46.348+0000] {dag.py:3328} INFO - Setting next_dagrun for airflow_first_dag to 2024-05-22T21:00:00+00:00, run_after=2024-05-23T21:00:00+00:00
[2024-05-24T11:39:46.423+0000] {processor.py:178} INFO - Processing /opt/airflow/dags/airflow_first_dag.py took 12.583 seconds
[2024-05-24T11:40:17.056+0000] {processor.py:156} INFO - Started process (PID=107) to work on /opt/airflow/dags/airflow_first_dag.py
[2024-05-24T11:40:17.096+0000] {processor.py:758} INFO - Processing file /opt/airflow/dags/airflow_first_dag.py for tasks to queue
[2024-05-24T11:40:17.222+0000] {logging_mixin.py:117} INFO - [2024-05-24T11:40:17.203+0000] {dagbag.py:525} INFO - Filling up the DagBag from /opt/airflow/dags/airflow_first_dag.py
[2024-05-24T11:40:20.302+0000] {processor.py:768} INFO - DAG(s) dict_keys(['airflow_first_dag']) retrieved from /opt/airflow/dags/airflow_first_dag.py
[2024-05-24T11:40:28.003+0000] {logging_mixin.py:117} INFO - [2024-05-24T11:40:28.003+0000] {dag.py:2573} INFO - Sync 1 DAGs
[2024-05-24T11:40:28.138+0000] {logging_mixin.py:117} INFO - [2024-05-24T11:40:28.137+0000] {dag.py:3328} INFO - Setting next_dagrun for airflow_first_dag to 2024-05-22T21:00:00+00:00, run_after=2024-05-23T21:00:00+00:00
[2024-05-24T11:40:28.231+0000] {processor.py:178} INFO - Processing /opt/airflow/dags/airflow_first_dag.py took 11.268 seconds
[2024-05-24T11:40:59.323+0000] {processor.py:156} INFO - Started process (PID=111) to work on /opt/airflow/dags/airflow_first_dag.py
[2024-05-24T11:40:59.337+0000] {processor.py:758} INFO - Processing file /opt/airflow/dags/airflow_first_dag.py for tasks to queue
[2024-05-24T11:40:59.362+0000] {logging_mixin.py:117} INFO - [2024-05-24T11:40:59.355+0000] {dagbag.py:525} INFO - Filling up the DagBag from /opt/airflow/dags/airflow_first_dag.py
[2024-05-24T11:41:03.093+0000] {processor.py:768} INFO - DAG(s) dict_keys(['airflow_first_dag']) retrieved from /opt/airflow/dags/airflow_first_dag.py
[2024-05-24T11:42:09.281+0000] {processor.py:156} INFO - Started process (PID=113) to work on /opt/airflow/dags/airflow_first_dag.py
[2024-05-24T11:42:09.286+0000] {processor.py:758} INFO - Processing file /opt/airflow/dags/airflow_first_dag.py for tasks to queue
[2024-05-24T11:42:09.306+0000] {logging_mixin.py:117} INFO - [2024-05-24T11:42:09.305+0000] {dagbag.py:525} INFO - Filling up the DagBag from /opt/airflow/dags/airflow_first_dag.py
[2024-05-24T11:42:13.474+0000] {processor.py:768} INFO - DAG(s) dict_keys(['airflow_first_dag']) retrieved from /opt/airflow/dags/airflow_first_dag.py
[2024-05-24T11:42:58.689+0000] {processor.py:181} ERROR - Got an exception! Propagating...
Traceback (most recent call last):
  File "/home/airflow/.local/lib/python3.7/site-packages/sqlalchemy/engine/base.py", line 3243, in _wrap_pool_connect
    return fn()
  File "/home/airflow/.local/lib/python3.7/site-packages/sqlalchemy/pool/base.py", line 310, in connect
    return _ConnectionFairy._checkout(self)
  File "/home/airflow/.local/lib/python3.7/site-packages/sqlalchemy/pool/base.py", line 868, in _checkout
    fairy = _ConnectionRecord.checkout(pool)
  File "/home/airflow/.local/lib/python3.7/site-packages/sqlalchemy/pool/base.py", line 476, in checkout
    rec = pool._do_get()
  File "/home/airflow/.local/lib/python3.7/site-packages/sqlalchemy/pool/impl.py", line 146, in _do_get
    self._dec_overflow()
  File "/home/airflow/.local/lib/python3.7/site-packages/sqlalchemy/util/langhelpers.py", line 72, in __exit__
    with_traceback=exc_tb,
  File "/home/airflow/.local/lib/python3.7/site-packages/sqlalchemy/util/compat.py", line 207, in raise_
    raise exception
  File "/home/airflow/.local/lib/python3.7/site-packages/sqlalchemy/pool/impl.py", line 143, in _do_get
    return self._create_connection()
  File "/home/airflow/.local/lib/python3.7/site-packages/sqlalchemy/pool/base.py", line 256, in _create_connection
    return _ConnectionRecord(self)
  File "/home/airflow/.local/lib/python3.7/site-packages/sqlalchemy/pool/base.py", line 371, in __init__
    self.__connect()
  File "/home/airflow/.local/lib/python3.7/site-packages/sqlalchemy/pool/base.py", line 666, in __connect
    pool.logger.debug("Error on connect(): %s", e)
  File "/home/airflow/.local/lib/python3.7/site-packages/sqlalchemy/util/langhelpers.py", line 72, in __exit__
    with_traceback=exc_tb,
  File "/home/airflow/.local/lib/python3.7/site-packages/sqlalchemy/util/compat.py", line 207, in raise_
    raise exception
  File "/home/airflow/.local/lib/python3.7/site-packages/sqlalchemy/pool/base.py", line 661, in __connect
    self.dbapi_connection = connection = pool._invoke_creator(self)
  File "/home/airflow/.local/lib/python3.7/site-packages/sqlalchemy/engine/create.py", line 590, in connect
    return dialect.connect(*cargs, **cparams)
  File "/home/airflow/.local/lib/python3.7/site-packages/sqlalchemy/engine/default.py", line 584, in connect
    return self.dbapi.connect(*cargs, **cparams)
  File "/home/airflow/.local/lib/python3.7/site-packages/psycopg2/__init__.py", line 122, in connect
    conn = _connect(dsn, connection_factory=connection_factory, **kwasync)
psycopg2.OperationalError: could not translate host name "postgres" to address: Temporary failure in name resolution


The above exception was the direct cause of the following exception:

Traceback (most recent call last):
  File "/home/airflow/.local/lib/python3.7/site-packages/airflow/dag_processing/processor.py", line 177, in _run_file_processor
    _handle_dag_file_processing()
  File "/home/airflow/.local/lib/python3.7/site-packages/airflow/dag_processing/processor.py", line 161, in _handle_dag_file_processing
    callback_requests=callback_requests,
  File "/home/airflow/.local/lib/python3.7/site-packages/airflow/utils/session.py", line 75, in wrapper
    return func(*args, session=session, **kwargs)
  File "/home/airflow/.local/lib/python3.7/site-packages/airflow/dag_processing/processor.py", line 783, in process_file
    dagbag.sync_to_db(processor_subdir=self._dag_directory, session=session)
  File "/home/airflow/.local/lib/python3.7/site-packages/airflow/utils/session.py", line 72, in wrapper
    return func(*args, **kwargs)
  File "/home/airflow/.local/lib/python3.7/site-packages/airflow/models/dagbag.py", line 632, in sync_to_db
    for attempt in run_with_db_retries(logger=self.log):
  File "/home/airflow/.local/lib/python3.7/site-packages/tenacity/__init__.py", line 384, in __iter__
    do = self.iter(retry_state=retry_state)
  File "/home/airflow/.local/lib/python3.7/site-packages/tenacity/__init__.py", line 362, in iter
    raise retry_exc.reraise()
  File "/home/airflow/.local/lib/python3.7/site-packages/tenacity/__init__.py", line 195, in reraise
    raise self.last_attempt.result()
  File "/usr/local/lib/python3.7/concurrent/futures/_base.py", line 428, in result
    return self.__get_result()
  File "/usr/local/lib/python3.7/concurrent/futures/_base.py", line 384, in __get_result
    raise self._exception
  File "/home/airflow/.local/lib/python3.7/site-packages/airflow/models/dagbag.py", line 644, in sync_to_db
    serialize_errors.extend(_serialize_dag_capturing_errors(dag, session))
  File "/home/airflow/.local/lib/python3.7/site-packages/airflow/models/dagbag.py", line 618, in _serialize_dag_capturing_errors
    session=session,
  File "/home/airflow/.local/lib/python3.7/site-packages/airflow/utils/session.py", line 72, in wrapper
    return func(*args, **kwargs)
  File "/home/airflow/.local/lib/python3.7/site-packages/airflow/models/serialized_dag.py", line 150, in write_dag
    (timezone.utcnow() - timedelta(seconds=min_update_interval)) < cls.last_updated,
  File "/home/airflow/.local/lib/python3.7/site-packages/sqlalchemy/orm/query.py", line 2810, in first
    return self.limit(1)._iter().first()
  File "/home/airflow/.local/lib/python3.7/site-packages/sqlalchemy/orm/query.py", line 2897, in _iter
    execution_options={"_sa_orm_load_options": self.load_options},
  File "/home/airflow/.local/lib/python3.7/site-packages/sqlalchemy/orm/session.py", line 1688, in execute
    conn = self._connection_for_bind(bind)
  File "/home/airflow/.local/lib/python3.7/site-packages/sqlalchemy/orm/session.py", line 1530, in _connection_for_bind
    engine, execution_options
  File "/home/airflow/.local/lib/python3.7/site-packages/sqlalchemy/orm/session.py", line 747, in _connection_for_bind
    conn = bind.connect()
  File "/home/airflow/.local/lib/python3.7/site-packages/sqlalchemy/engine/base.py", line 3197, in connect
    return self._connection_cls(self, close_with_result=close_with_result)
  File "/home/airflow/.local/lib/python3.7/site-packages/sqlalchemy/engine/base.py", line 96, in __init__
    else engine.raw_connection()
  File "/home/airflow/.local/lib/python3.7/site-packages/sqlalchemy/engine/base.py", line 3276, in raw_connection
    return self._wrap_pool_connect(self.pool.connect, _connection)
  File "/home/airflow/.local/lib/python3.7/site-packages/sqlalchemy/engine/base.py", line 3247, in _wrap_pool_connect
    e, dialect, self
  File "/home/airflow/.local/lib/python3.7/site-packages/sqlalchemy/engine/base.py", line 2101, in _handle_dbapi_exception_noconnection
    sqlalchemy_exception, with_traceback=exc_info[2], from_=e
  File "/home/airflow/.local/lib/python3.7/site-packages/sqlalchemy/util/compat.py", line 207, in raise_
    raise exception
  File "/home/airflow/.local/lib/python3.7/site-packages/sqlalchemy/engine/base.py", line 3243, in _wrap_pool_connect
    return fn()
  File "/home/airflow/.local/lib/python3.7/site-packages/sqlalchemy/pool/base.py", line 310, in connect
    return _ConnectionFairy._checkout(self)
  File "/home/airflow/.local/lib/python3.7/site-packages/sqlalchemy/pool/base.py", line 868, in _checkout
    fairy = _ConnectionRecord.checkout(pool)
  File "/home/airflow/.local/lib/python3.7/site-packages/sqlalchemy/pool/base.py", line 476, in checkout
    rec = pool._do_get()
  File "/home/airflow/.local/lib/python3.7/site-packages/sqlalchemy/pool/impl.py", line 146, in _do_get
    self._dec_overflow()
  File "/home/airflow/.local/lib/python3.7/site-packages/sqlalchemy/util/langhelpers.py", line 72, in __exit__
    with_traceback=exc_tb,
  File "/home/airflow/.local/lib/python3.7/site-packages/sqlalchemy/util/compat.py", line 207, in raise_
    raise exception
  File "/home/airflow/.local/lib/python3.7/site-packages/sqlalchemy/pool/impl.py", line 143, in _do_get
    return self._create_connection()
  File "/home/airflow/.local/lib/python3.7/site-packages/sqlalchemy/pool/base.py", line 256, in _create_connection
    return _ConnectionRecord(self)
  File "/home/airflow/.local/lib/python3.7/site-packages/sqlalchemy/pool/base.py", line 371, in __init__
    self.__connect()
  File "/home/airflow/.local/lib/python3.7/site-packages/sqlalchemy/pool/base.py", line 666, in __connect
    pool.logger.debug("Error on connect(): %s", e)
  File "/home/airflow/.local/lib/python3.7/site-packages/sqlalchemy/util/langhelpers.py", line 72, in __exit__
    with_traceback=exc_tb,
  File "/home/airflow/.local/lib/python3.7/site-packages/sqlalchemy/util/compat.py", line 207, in raise_
    raise exception
  File "/home/airflow/.local/lib/python3.7/site-packages/sqlalchemy/pool/base.py", line 661, in __connect
    self.dbapi_connection = connection = pool._invoke_creator(self)
  File "/home/airflow/.local/lib/python3.7/site-packages/sqlalchemy/engine/create.py", line 590, in connect
    return dialect.connect(*cargs, **cparams)
  File "/home/airflow/.local/lib/python3.7/site-packages/sqlalchemy/engine/default.py", line 584, in connect
    return self.dbapi.connect(*cargs, **cparams)
  File "/home/airflow/.local/lib/python3.7/site-packages/psycopg2/__init__.py", line 122, in connect
    conn = _connect(dsn, connection_factory=connection_factory, **kwasync)
sqlalchemy.exc.OperationalError: (psycopg2.OperationalError) could not translate host name "postgres" to address: Temporary failure in name resolution

(Background on this error at: https://sqlalche.me/e/14/e3q8)
[2024-05-24T11:43:00.415+0000] {processor.py:156} INFO - Started process (PID=115) to work on /opt/airflow/dags/airflow_first_dag.py
[2024-05-24T11:43:00.516+0000] {processor.py:758} INFO - Processing file /opt/airflow/dags/airflow_first_dag.py for tasks to queue
[2024-05-24T11:43:00.582+0000] {logging_mixin.py:117} INFO - [2024-05-24T11:43:00.558+0000] {dagbag.py:525} INFO - Filling up the DagBag from /opt/airflow/dags/airflow_first_dag.py
[2024-05-24T11:43:02.301+0000] {processor.py:768} INFO - DAG(s) dict_keys(['airflow_first_dag']) retrieved from /opt/airflow/dags/airflow_first_dag.py
[2024-05-24T11:43:34.972+0000] {processor.py:181} ERROR - Got an exception! Propagating...
Traceback (most recent call last):
  File "/home/airflow/.local/lib/python3.7/site-packages/sqlalchemy/engine/base.py", line 3243, in _wrap_pool_connect
    return fn()
  File "/home/airflow/.local/lib/python3.7/site-packages/sqlalchemy/pool/base.py", line 310, in connect
    return _ConnectionFairy._checkout(self)
  File "/home/airflow/.local/lib/python3.7/site-packages/sqlalchemy/pool/base.py", line 868, in _checkout
    fairy = _ConnectionRecord.checkout(pool)
  File "/home/airflow/.local/lib/python3.7/site-packages/sqlalchemy/pool/base.py", line 476, in checkout
    rec = pool._do_get()
  File "/home/airflow/.local/lib/python3.7/site-packages/sqlalchemy/pool/impl.py", line 146, in _do_get
    self._dec_overflow()
  File "/home/airflow/.local/lib/python3.7/site-packages/sqlalchemy/util/langhelpers.py", line 72, in __exit__
    with_traceback=exc_tb,
  File "/home/airflow/.local/lib/python3.7/site-packages/sqlalchemy/util/compat.py", line 207, in raise_
    raise exception
  File "/home/airflow/.local/lib/python3.7/site-packages/sqlalchemy/pool/impl.py", line 143, in _do_get
    return self._create_connection()
  File "/home/airflow/.local/lib/python3.7/site-packages/sqlalchemy/pool/base.py", line 256, in _create_connection
    return _ConnectionRecord(self)
  File "/home/airflow/.local/lib/python3.7/site-packages/sqlalchemy/pool/base.py", line 371, in __init__
    self.__connect()
  File "/home/airflow/.local/lib/python3.7/site-packages/sqlalchemy/pool/base.py", line 666, in __connect
    pool.logger.debug("Error on connect(): %s", e)
  File "/home/airflow/.local/lib/python3.7/site-packages/sqlalchemy/util/langhelpers.py", line 72, in __exit__
    with_traceback=exc_tb,
  File "/home/airflow/.local/lib/python3.7/site-packages/sqlalchemy/util/compat.py", line 207, in raise_
    raise exception
  File "/home/airflow/.local/lib/python3.7/site-packages/sqlalchemy/pool/base.py", line 661, in __connect
    self.dbapi_connection = connection = pool._invoke_creator(self)
  File "/home/airflow/.local/lib/python3.7/site-packages/sqlalchemy/engine/create.py", line 590, in connect
    return dialect.connect(*cargs, **cparams)
  File "/home/airflow/.local/lib/python3.7/site-packages/sqlalchemy/engine/default.py", line 584, in connect
    return self.dbapi.connect(*cargs, **cparams)
  File "/home/airflow/.local/lib/python3.7/site-packages/psycopg2/__init__.py", line 122, in connect
    conn = _connect(dsn, connection_factory=connection_factory, **kwasync)
psycopg2.OperationalError: could not translate host name "postgres" to address: Temporary failure in name resolution


The above exception was the direct cause of the following exception:

Traceback (most recent call last):
  File "/home/airflow/.local/lib/python3.7/site-packages/airflow/dag_processing/processor.py", line 177, in _run_file_processor
    _handle_dag_file_processing()
  File "/home/airflow/.local/lib/python3.7/site-packages/airflow/dag_processing/processor.py", line 161, in _handle_dag_file_processing
    callback_requests=callback_requests,
  File "/home/airflow/.local/lib/python3.7/site-packages/airflow/utils/session.py", line 75, in wrapper
    return func(*args, session=session, **kwargs)
  File "/home/airflow/.local/lib/python3.7/site-packages/airflow/dag_processing/processor.py", line 783, in process_file
    dagbag.sync_to_db(processor_subdir=self._dag_directory, session=session)
  File "/home/airflow/.local/lib/python3.7/site-packages/airflow/utils/session.py", line 72, in wrapper
    return func(*args, **kwargs)
  File "/home/airflow/.local/lib/python3.7/site-packages/airflow/models/dagbag.py", line 632, in sync_to_db
    for attempt in run_with_db_retries(logger=self.log):
  File "/home/airflow/.local/lib/python3.7/site-packages/tenacity/__init__.py", line 384, in __iter__
    do = self.iter(retry_state=retry_state)
  File "/home/airflow/.local/lib/python3.7/site-packages/tenacity/__init__.py", line 362, in iter
    raise retry_exc.reraise()
  File "/home/airflow/.local/lib/python3.7/site-packages/tenacity/__init__.py", line 195, in reraise
    raise self.last_attempt.result()
  File "/usr/local/lib/python3.7/concurrent/futures/_base.py", line 428, in result
    return self.__get_result()
  File "/usr/local/lib/python3.7/concurrent/futures/_base.py", line 384, in __get_result
    raise self._exception
  File "/home/airflow/.local/lib/python3.7/site-packages/airflow/models/dagbag.py", line 644, in sync_to_db
    serialize_errors.extend(_serialize_dag_capturing_errors(dag, session))
  File "/home/airflow/.local/lib/python3.7/site-packages/airflow/models/dagbag.py", line 618, in _serialize_dag_capturing_errors
    session=session,
  File "/home/airflow/.local/lib/python3.7/site-packages/airflow/utils/session.py", line 72, in wrapper
    return func(*args, **kwargs)
  File "/home/airflow/.local/lib/python3.7/site-packages/airflow/models/serialized_dag.py", line 150, in write_dag
    (timezone.utcnow() - timedelta(seconds=min_update_interval)) < cls.last_updated,
  File "/home/airflow/.local/lib/python3.7/site-packages/sqlalchemy/orm/query.py", line 2810, in first
    return self.limit(1)._iter().first()
  File "/home/airflow/.local/lib/python3.7/site-packages/sqlalchemy/orm/query.py", line 2897, in _iter
    execution_options={"_sa_orm_load_options": self.load_options},
  File "/home/airflow/.local/lib/python3.7/site-packages/sqlalchemy/orm/session.py", line 1688, in execute
    conn = self._connection_for_bind(bind)
  File "/home/airflow/.local/lib/python3.7/site-packages/sqlalchemy/orm/session.py", line 1530, in _connection_for_bind
    engine, execution_options
  File "/home/airflow/.local/lib/python3.7/site-packages/sqlalchemy/orm/session.py", line 747, in _connection_for_bind
    conn = bind.connect()
  File "/home/airflow/.local/lib/python3.7/site-packages/sqlalchemy/engine/base.py", line 3197, in connect
    return self._connection_cls(self, close_with_result=close_with_result)
  File "/home/airflow/.local/lib/python3.7/site-packages/sqlalchemy/engine/base.py", line 96, in __init__
    else engine.raw_connection()
  File "/home/airflow/.local/lib/python3.7/site-packages/sqlalchemy/engine/base.py", line 3276, in raw_connection
    return self._wrap_pool_connect(self.pool.connect, _connection)
  File "/home/airflow/.local/lib/python3.7/site-packages/sqlalchemy/engine/base.py", line 3247, in _wrap_pool_connect
    e, dialect, self
  File "/home/airflow/.local/lib/python3.7/site-packages/sqlalchemy/engine/base.py", line 2101, in _handle_dbapi_exception_noconnection
    sqlalchemy_exception, with_traceback=exc_info[2], from_=e
  File "/home/airflow/.local/lib/python3.7/site-packages/sqlalchemy/util/compat.py", line 207, in raise_
    raise exception
  File "/home/airflow/.local/lib/python3.7/site-packages/sqlalchemy/engine/base.py", line 3243, in _wrap_pool_connect
    return fn()
  File "/home/airflow/.local/lib/python3.7/site-packages/sqlalchemy/pool/base.py", line 310, in connect
    return _ConnectionFairy._checkout(self)
  File "/home/airflow/.local/lib/python3.7/site-packages/sqlalchemy/pool/base.py", line 868, in _checkout
    fairy = _ConnectionRecord.checkout(pool)
  File "/home/airflow/.local/lib/python3.7/site-packages/sqlalchemy/pool/base.py", line 476, in checkout
    rec = pool._do_get()
  File "/home/airflow/.local/lib/python3.7/site-packages/sqlalchemy/pool/impl.py", line 146, in _do_get
    self._dec_overflow()
  File "/home/airflow/.local/lib/python3.7/site-packages/sqlalchemy/util/langhelpers.py", line 72, in __exit__
    with_traceback=exc_tb,
  File "/home/airflow/.local/lib/python3.7/site-packages/sqlalchemy/util/compat.py", line 207, in raise_
    raise exception
  File "/home/airflow/.local/lib/python3.7/site-packages/sqlalchemy/pool/impl.py", line 143, in _do_get
    return self._create_connection()
  File "/home/airflow/.local/lib/python3.7/site-packages/sqlalchemy/pool/base.py", line 256, in _create_connection
    return _ConnectionRecord(self)
  File "/home/airflow/.local/lib/python3.7/site-packages/sqlalchemy/pool/base.py", line 371, in __init__
    self.__connect()
  File "/home/airflow/.local/lib/python3.7/site-packages/sqlalchemy/pool/base.py", line 666, in __connect
    pool.logger.debug("Error on connect(): %s", e)
  File "/home/airflow/.local/lib/python3.7/site-packages/sqlalchemy/util/langhelpers.py", line 72, in __exit__
    with_traceback=exc_tb,
  File "/home/airflow/.local/lib/python3.7/site-packages/sqlalchemy/util/compat.py", line 207, in raise_
    raise exception
  File "/home/airflow/.local/lib/python3.7/site-packages/sqlalchemy/pool/base.py", line 661, in __connect
    self.dbapi_connection = connection = pool._invoke_creator(self)
  File "/home/airflow/.local/lib/python3.7/site-packages/sqlalchemy/engine/create.py", line 590, in connect
    return dialect.connect(*cargs, **cparams)
  File "/home/airflow/.local/lib/python3.7/site-packages/sqlalchemy/engine/default.py", line 584, in connect
    return self.dbapi.connect(*cargs, **cparams)
  File "/home/airflow/.local/lib/python3.7/site-packages/psycopg2/__init__.py", line 122, in connect
    conn = _connect(dsn, connection_factory=connection_factory, **kwasync)
sqlalchemy.exc.OperationalError: (psycopg2.OperationalError) could not translate host name "postgres" to address: Temporary failure in name resolution

(Background on this error at: https://sqlalche.me/e/14/e3q8)
[2024-05-24T11:44:10.634+0000] {processor.py:156} INFO - Started process (PID=117) to work on /opt/airflow/dags/airflow_first_dag.py
[2024-05-24T11:44:10.667+0000] {processor.py:758} INFO - Processing file /opt/airflow/dags/airflow_first_dag.py for tasks to queue
[2024-05-24T11:44:10.752+0000] {logging_mixin.py:117} INFO - [2024-05-24T11:44:10.701+0000] {dagbag.py:525} INFO - Filling up the DagBag from /opt/airflow/dags/airflow_first_dag.py
[2024-05-24T11:44:15.874+0000] {processor.py:768} INFO - DAG(s) dict_keys(['airflow_first_dag']) retrieved from /opt/airflow/dags/airflow_first_dag.py
[2024-05-24T11:48:36.475+0000] {processor.py:156} INFO - Started process (PID=121) to work on /opt/airflow/dags/airflow_first_dag.py
[2024-05-24T11:48:36.479+0000] {processor.py:758} INFO - Processing file /opt/airflow/dags/airflow_first_dag.py for tasks to queue
[2024-05-24T11:48:36.491+0000] {logging_mixin.py:117} INFO - [2024-05-24T11:48:36.491+0000] {dagbag.py:525} INFO - Filling up the DagBag from /opt/airflow/dags/airflow_first_dag.py
[2024-05-24T11:48:36.846+0000] {processor.py:768} INFO - DAG(s) dict_keys(['airflow_first_dag']) retrieved from /opt/airflow/dags/airflow_first_dag.py
[2024-05-24T11:48:38.389+0000] {logging_mixin.py:117} INFO - [2024-05-24T11:48:38.388+0000] {dag.py:2573} INFO - Sync 1 DAGs
[2024-05-24T11:48:39.302+0000] {logging_mixin.py:117} INFO - [2024-05-24T11:48:39.281+0000] {dag.py:3328} INFO - Setting next_dagrun for airflow_first_dag to 2024-05-22T21:00:00+00:00, run_after=2024-05-23T21:00:00+00:00
[2024-05-24T11:48:39.967+0000] {processor.py:178} INFO - Processing /opt/airflow/dags/airflow_first_dag.py took 3.545 seconds
[2024-05-24T11:49:40.333+0000] {processor.py:156} INFO - Started process (PID=133) to work on /opt/airflow/dags/airflow_first_dag.py
[2024-05-24T11:49:40.656+0000] {processor.py:758} INFO - Processing file /opt/airflow/dags/airflow_first_dag.py for tasks to queue
[2024-05-24T11:49:43.053+0000] {logging_mixin.py:117} INFO - [2024-05-24T11:49:41.106+0000] {dagbag.py:525} INFO - Filling up the DagBag from /opt/airflow/dags/airflow_first_dag.py
[2024-05-24T11:49:44.224+0000] {processor.py:768} INFO - DAG(s) dict_keys(['airflow_first_dag']) retrieved from /opt/airflow/dags/airflow_first_dag.py
[2024-05-24T11:50:17.040+0000] {processor.py:181} ERROR - Got an exception! Propagating...
Traceback (most recent call last):
  File "/home/airflow/.local/lib/python3.7/site-packages/sqlalchemy/engine/base.py", line 3243, in _wrap_pool_connect
    return fn()
  File "/home/airflow/.local/lib/python3.7/site-packages/sqlalchemy/pool/base.py", line 310, in connect
    return _ConnectionFairy._checkout(self)
  File "/home/airflow/.local/lib/python3.7/site-packages/sqlalchemy/pool/base.py", line 868, in _checkout
    fairy = _ConnectionRecord.checkout(pool)
  File "/home/airflow/.local/lib/python3.7/site-packages/sqlalchemy/pool/base.py", line 476, in checkout
    rec = pool._do_get()
  File "/home/airflow/.local/lib/python3.7/site-packages/sqlalchemy/pool/impl.py", line 146, in _do_get
    self._dec_overflow()
  File "/home/airflow/.local/lib/python3.7/site-packages/sqlalchemy/util/langhelpers.py", line 72, in __exit__
    with_traceback=exc_tb,
  File "/home/airflow/.local/lib/python3.7/site-packages/sqlalchemy/util/compat.py", line 207, in raise_
    raise exception
  File "/home/airflow/.local/lib/python3.7/site-packages/sqlalchemy/pool/impl.py", line 143, in _do_get
    return self._create_connection()
  File "/home/airflow/.local/lib/python3.7/site-packages/sqlalchemy/pool/base.py", line 256, in _create_connection
    return _ConnectionRecord(self)
  File "/home/airflow/.local/lib/python3.7/site-packages/sqlalchemy/pool/base.py", line 371, in __init__
    self.__connect()
  File "/home/airflow/.local/lib/python3.7/site-packages/sqlalchemy/pool/base.py", line 666, in __connect
    pool.logger.debug("Error on connect(): %s", e)
  File "/home/airflow/.local/lib/python3.7/site-packages/sqlalchemy/util/langhelpers.py", line 72, in __exit__
    with_traceback=exc_tb,
  File "/home/airflow/.local/lib/python3.7/site-packages/sqlalchemy/util/compat.py", line 207, in raise_
    raise exception
  File "/home/airflow/.local/lib/python3.7/site-packages/sqlalchemy/pool/base.py", line 661, in __connect
    self.dbapi_connection = connection = pool._invoke_creator(self)
  File "/home/airflow/.local/lib/python3.7/site-packages/sqlalchemy/engine/create.py", line 590, in connect
    return dialect.connect(*cargs, **cparams)
  File "/home/airflow/.local/lib/python3.7/site-packages/sqlalchemy/engine/default.py", line 584, in connect
    return self.dbapi.connect(*cargs, **cparams)
  File "/home/airflow/.local/lib/python3.7/site-packages/psycopg2/__init__.py", line 122, in connect
    conn = _connect(dsn, connection_factory=connection_factory, **kwasync)
psycopg2.OperationalError: could not translate host name "postgres" to address: Temporary failure in name resolution


The above exception was the direct cause of the following exception:

Traceback (most recent call last):
  File "/home/airflow/.local/lib/python3.7/site-packages/airflow/dag_processing/processor.py", line 177, in _run_file_processor
    _handle_dag_file_processing()
  File "/home/airflow/.local/lib/python3.7/site-packages/airflow/dag_processing/processor.py", line 161, in _handle_dag_file_processing
    callback_requests=callback_requests,
  File "/home/airflow/.local/lib/python3.7/site-packages/airflow/utils/session.py", line 75, in wrapper
    return func(*args, session=session, **kwargs)
  File "/home/airflow/.local/lib/python3.7/site-packages/airflow/dag_processing/processor.py", line 783, in process_file
    dagbag.sync_to_db(processor_subdir=self._dag_directory, session=session)
  File "/home/airflow/.local/lib/python3.7/site-packages/airflow/utils/session.py", line 72, in wrapper
    return func(*args, **kwargs)
  File "/home/airflow/.local/lib/python3.7/site-packages/airflow/models/dagbag.py", line 632, in sync_to_db
    for attempt in run_with_db_retries(logger=self.log):
  File "/home/airflow/.local/lib/python3.7/site-packages/tenacity/__init__.py", line 384, in __iter__
    do = self.iter(retry_state=retry_state)
  File "/home/airflow/.local/lib/python3.7/site-packages/tenacity/__init__.py", line 362, in iter
    raise retry_exc.reraise()
  File "/home/airflow/.local/lib/python3.7/site-packages/tenacity/__init__.py", line 195, in reraise
    raise self.last_attempt.result()
  File "/usr/local/lib/python3.7/concurrent/futures/_base.py", line 428, in result
    return self.__get_result()
  File "/usr/local/lib/python3.7/concurrent/futures/_base.py", line 384, in __get_result
    raise self._exception
  File "/home/airflow/.local/lib/python3.7/site-packages/airflow/models/dagbag.py", line 644, in sync_to_db
    serialize_errors.extend(_serialize_dag_capturing_errors(dag, session))
  File "/home/airflow/.local/lib/python3.7/site-packages/airflow/models/dagbag.py", line 618, in _serialize_dag_capturing_errors
    session=session,
  File "/home/airflow/.local/lib/python3.7/site-packages/airflow/utils/session.py", line 72, in wrapper
    return func(*args, **kwargs)
  File "/home/airflow/.local/lib/python3.7/site-packages/airflow/models/serialized_dag.py", line 150, in write_dag
    (timezone.utcnow() - timedelta(seconds=min_update_interval)) < cls.last_updated,
  File "/home/airflow/.local/lib/python3.7/site-packages/sqlalchemy/orm/query.py", line 2810, in first
    return self.limit(1)._iter().first()
  File "/home/airflow/.local/lib/python3.7/site-packages/sqlalchemy/orm/query.py", line 2897, in _iter
    execution_options={"_sa_orm_load_options": self.load_options},
  File "/home/airflow/.local/lib/python3.7/site-packages/sqlalchemy/orm/session.py", line 1688, in execute
    conn = self._connection_for_bind(bind)
  File "/home/airflow/.local/lib/python3.7/site-packages/sqlalchemy/orm/session.py", line 1530, in _connection_for_bind
    engine, execution_options
  File "/home/airflow/.local/lib/python3.7/site-packages/sqlalchemy/orm/session.py", line 747, in _connection_for_bind
    conn = bind.connect()
  File "/home/airflow/.local/lib/python3.7/site-packages/sqlalchemy/engine/base.py", line 3197, in connect
    return self._connection_cls(self, close_with_result=close_with_result)
  File "/home/airflow/.local/lib/python3.7/site-packages/sqlalchemy/engine/base.py", line 96, in __init__
    else engine.raw_connection()
  File "/home/airflow/.local/lib/python3.7/site-packages/sqlalchemy/engine/base.py", line 3276, in raw_connection
    return self._wrap_pool_connect(self.pool.connect, _connection)
  File "/home/airflow/.local/lib/python3.7/site-packages/sqlalchemy/engine/base.py", line 3247, in _wrap_pool_connect
    e, dialect, self
  File "/home/airflow/.local/lib/python3.7/site-packages/sqlalchemy/engine/base.py", line 2101, in _handle_dbapi_exception_noconnection
    sqlalchemy_exception, with_traceback=exc_info[2], from_=e
  File "/home/airflow/.local/lib/python3.7/site-packages/sqlalchemy/util/compat.py", line 207, in raise_
    raise exception
  File "/home/airflow/.local/lib/python3.7/site-packages/sqlalchemy/engine/base.py", line 3243, in _wrap_pool_connect
    return fn()
  File "/home/airflow/.local/lib/python3.7/site-packages/sqlalchemy/pool/base.py", line 310, in connect
    return _ConnectionFairy._checkout(self)
  File "/home/airflow/.local/lib/python3.7/site-packages/sqlalchemy/pool/base.py", line 868, in _checkout
    fairy = _ConnectionRecord.checkout(pool)
  File "/home/airflow/.local/lib/python3.7/site-packages/sqlalchemy/pool/base.py", line 476, in checkout
    rec = pool._do_get()
  File "/home/airflow/.local/lib/python3.7/site-packages/sqlalchemy/pool/impl.py", line 146, in _do_get
    self._dec_overflow()
  File "/home/airflow/.local/lib/python3.7/site-packages/sqlalchemy/util/langhelpers.py", line 72, in __exit__
    with_traceback=exc_tb,
  File "/home/airflow/.local/lib/python3.7/site-packages/sqlalchemy/util/compat.py", line 207, in raise_
    raise exception
  File "/home/airflow/.local/lib/python3.7/site-packages/sqlalchemy/pool/impl.py", line 143, in _do_get
    return self._create_connection()
  File "/home/airflow/.local/lib/python3.7/site-packages/sqlalchemy/pool/base.py", line 256, in _create_connection
    return _ConnectionRecord(self)
  File "/home/airflow/.local/lib/python3.7/site-packages/sqlalchemy/pool/base.py", line 371, in __init__
    self.__connect()
  File "/home/airflow/.local/lib/python3.7/site-packages/sqlalchemy/pool/base.py", line 666, in __connect
    pool.logger.debug("Error on connect(): %s", e)
  File "/home/airflow/.local/lib/python3.7/site-packages/sqlalchemy/util/langhelpers.py", line 72, in __exit__
    with_traceback=exc_tb,
  File "/home/airflow/.local/lib/python3.7/site-packages/sqlalchemy/util/compat.py", line 207, in raise_
    raise exception
  File "/home/airflow/.local/lib/python3.7/site-packages/sqlalchemy/pool/base.py", line 661, in __connect
    self.dbapi_connection = connection = pool._invoke_creator(self)
  File "/home/airflow/.local/lib/python3.7/site-packages/sqlalchemy/engine/create.py", line 590, in connect
    return dialect.connect(*cargs, **cparams)
  File "/home/airflow/.local/lib/python3.7/site-packages/sqlalchemy/engine/default.py", line 584, in connect
    return self.dbapi.connect(*cargs, **cparams)
  File "/home/airflow/.local/lib/python3.7/site-packages/psycopg2/__init__.py", line 122, in connect
    conn = _connect(dsn, connection_factory=connection_factory, **kwasync)
sqlalchemy.exc.OperationalError: (psycopg2.OperationalError) could not translate host name "postgres" to address: Temporary failure in name resolution

(Background on this error at: https://sqlalche.me/e/14/e3q8)
[2024-05-24T11:50:49.902+0000] {processor.py:156} INFO - Started process (PID=136) to work on /opt/airflow/dags/airflow_first_dag.py
[2024-05-24T11:50:49.907+0000] {processor.py:758} INFO - Processing file /opt/airflow/dags/airflow_first_dag.py for tasks to queue
[2024-05-24T11:50:49.912+0000] {logging_mixin.py:117} INFO - [2024-05-24T11:50:49.912+0000] {dagbag.py:525} INFO - Filling up the DagBag from /opt/airflow/dags/airflow_first_dag.py
[2024-05-24T11:50:51.140+0000] {processor.py:768} INFO - DAG(s) dict_keys(['airflow_first_dag']) retrieved from /opt/airflow/dags/airflow_first_dag.py
[2024-05-24T11:55:17.538+0000] {processor.py:156} INFO - Started process (PID=141) to work on /opt/airflow/dags/airflow_first_dag.py
[2024-05-24T11:55:17.563+0000] {processor.py:758} INFO - Processing file /opt/airflow/dags/airflow_first_dag.py for tasks to queue
[2024-05-24T11:55:17.576+0000] {logging_mixin.py:117} INFO - [2024-05-24T11:55:17.573+0000] {dagbag.py:525} INFO - Filling up the DagBag from /opt/airflow/dags/airflow_first_dag.py
[2024-05-24T11:55:21.014+0000] {logging_mixin.py:117} INFO - [2024-05-24T11:55:21.013+0000] {process_utils.py:256} INFO - Waiting up to 5 seconds for processes to exit...
[2024-05-24T11:55:47.898+0000] {processor.py:156} INFO - Started process (PID=153) to work on /opt/airflow/dags/airflow_first_dag.py
[2024-05-24T11:55:47.905+0000] {processor.py:758} INFO - Processing file /opt/airflow/dags/airflow_first_dag.py for tasks to queue
[2024-05-24T11:55:47.916+0000] {logging_mixin.py:117} INFO - [2024-05-24T11:55:47.914+0000] {dagbag.py:525} INFO - Filling up the DagBag from /opt/airflow/dags/airflow_first_dag.py
[2024-05-24T11:55:48.101+0000] {processor.py:768} INFO - DAG(s) dict_keys(['airflow_first_dag']) retrieved from /opt/airflow/dags/airflow_first_dag.py
[2024-05-24T11:56:19.354+0000] {processor.py:181} ERROR - Got an exception! Propagating...
Traceback (most recent call last):
  File "/home/airflow/.local/lib/python3.7/site-packages/sqlalchemy/engine/base.py", line 3243, in _wrap_pool_connect
    return fn()
  File "/home/airflow/.local/lib/python3.7/site-packages/sqlalchemy/pool/base.py", line 310, in connect
    return _ConnectionFairy._checkout(self)
  File "/home/airflow/.local/lib/python3.7/site-packages/sqlalchemy/pool/base.py", line 868, in _checkout
    fairy = _ConnectionRecord.checkout(pool)
  File "/home/airflow/.local/lib/python3.7/site-packages/sqlalchemy/pool/base.py", line 476, in checkout
    rec = pool._do_get()
  File "/home/airflow/.local/lib/python3.7/site-packages/sqlalchemy/pool/impl.py", line 146, in _do_get
    self._dec_overflow()
  File "/home/airflow/.local/lib/python3.7/site-packages/sqlalchemy/util/langhelpers.py", line 72, in __exit__
    with_traceback=exc_tb,
  File "/home/airflow/.local/lib/python3.7/site-packages/sqlalchemy/util/compat.py", line 207, in raise_
    raise exception
  File "/home/airflow/.local/lib/python3.7/site-packages/sqlalchemy/pool/impl.py", line 143, in _do_get
    return self._create_connection()
  File "/home/airflow/.local/lib/python3.7/site-packages/sqlalchemy/pool/base.py", line 256, in _create_connection
    return _ConnectionRecord(self)
  File "/home/airflow/.local/lib/python3.7/site-packages/sqlalchemy/pool/base.py", line 371, in __init__
    self.__connect()
  File "/home/airflow/.local/lib/python3.7/site-packages/sqlalchemy/pool/base.py", line 666, in __connect
    pool.logger.debug("Error on connect(): %s", e)
  File "/home/airflow/.local/lib/python3.7/site-packages/sqlalchemy/util/langhelpers.py", line 72, in __exit__
    with_traceback=exc_tb,
  File "/home/airflow/.local/lib/python3.7/site-packages/sqlalchemy/util/compat.py", line 207, in raise_
    raise exception
  File "/home/airflow/.local/lib/python3.7/site-packages/sqlalchemy/pool/base.py", line 661, in __connect
    self.dbapi_connection = connection = pool._invoke_creator(self)
  File "/home/airflow/.local/lib/python3.7/site-packages/sqlalchemy/engine/create.py", line 590, in connect
    return dialect.connect(*cargs, **cparams)
  File "/home/airflow/.local/lib/python3.7/site-packages/sqlalchemy/engine/default.py", line 584, in connect
    return self.dbapi.connect(*cargs, **cparams)
  File "/home/airflow/.local/lib/python3.7/site-packages/psycopg2/__init__.py", line 122, in connect
    conn = _connect(dsn, connection_factory=connection_factory, **kwasync)
psycopg2.OperationalError: could not translate host name "postgres" to address: Temporary failure in name resolution


The above exception was the direct cause of the following exception:

Traceback (most recent call last):
  File "/home/airflow/.local/lib/python3.7/site-packages/airflow/dag_processing/processor.py", line 177, in _run_file_processor
    _handle_dag_file_processing()
  File "/home/airflow/.local/lib/python3.7/site-packages/airflow/dag_processing/processor.py", line 161, in _handle_dag_file_processing
    callback_requests=callback_requests,
  File "/home/airflow/.local/lib/python3.7/site-packages/airflow/utils/session.py", line 75, in wrapper
    return func(*args, session=session, **kwargs)
  File "/home/airflow/.local/lib/python3.7/site-packages/airflow/dag_processing/processor.py", line 783, in process_file
    dagbag.sync_to_db(processor_subdir=self._dag_directory, session=session)
  File "/home/airflow/.local/lib/python3.7/site-packages/airflow/utils/session.py", line 72, in wrapper
    return func(*args, **kwargs)
  File "/home/airflow/.local/lib/python3.7/site-packages/airflow/models/dagbag.py", line 632, in sync_to_db
    for attempt in run_with_db_retries(logger=self.log):
  File "/home/airflow/.local/lib/python3.7/site-packages/tenacity/__init__.py", line 384, in __iter__
    do = self.iter(retry_state=retry_state)
  File "/home/airflow/.local/lib/python3.7/site-packages/tenacity/__init__.py", line 362, in iter
    raise retry_exc.reraise()
  File "/home/airflow/.local/lib/python3.7/site-packages/tenacity/__init__.py", line 195, in reraise
    raise self.last_attempt.result()
  File "/usr/local/lib/python3.7/concurrent/futures/_base.py", line 428, in result
    return self.__get_result()
  File "/usr/local/lib/python3.7/concurrent/futures/_base.py", line 384, in __get_result
    raise self._exception
  File "/home/airflow/.local/lib/python3.7/site-packages/airflow/models/dagbag.py", line 644, in sync_to_db
    serialize_errors.extend(_serialize_dag_capturing_errors(dag, session))
  File "/home/airflow/.local/lib/python3.7/site-packages/airflow/models/dagbag.py", line 618, in _serialize_dag_capturing_errors
    session=session,
  File "/home/airflow/.local/lib/python3.7/site-packages/airflow/utils/session.py", line 72, in wrapper
    return func(*args, **kwargs)
  File "/home/airflow/.local/lib/python3.7/site-packages/airflow/models/serialized_dag.py", line 150, in write_dag
    (timezone.utcnow() - timedelta(seconds=min_update_interval)) < cls.last_updated,
  File "/home/airflow/.local/lib/python3.7/site-packages/sqlalchemy/orm/query.py", line 2810, in first
    return self.limit(1)._iter().first()
  File "/home/airflow/.local/lib/python3.7/site-packages/sqlalchemy/orm/query.py", line 2897, in _iter
    execution_options={"_sa_orm_load_options": self.load_options},
  File "/home/airflow/.local/lib/python3.7/site-packages/sqlalchemy/orm/session.py", line 1688, in execute
    conn = self._connection_for_bind(bind)
  File "/home/airflow/.local/lib/python3.7/site-packages/sqlalchemy/orm/session.py", line 1530, in _connection_for_bind
    engine, execution_options
  File "/home/airflow/.local/lib/python3.7/site-packages/sqlalchemy/orm/session.py", line 747, in _connection_for_bind
    conn = bind.connect()
  File "/home/airflow/.local/lib/python3.7/site-packages/sqlalchemy/engine/base.py", line 3197, in connect
    return self._connection_cls(self, close_with_result=close_with_result)
  File "/home/airflow/.local/lib/python3.7/site-packages/sqlalchemy/engine/base.py", line 96, in __init__
    else engine.raw_connection()
  File "/home/airflow/.local/lib/python3.7/site-packages/sqlalchemy/engine/base.py", line 3276, in raw_connection
    return self._wrap_pool_connect(self.pool.connect, _connection)
  File "/home/airflow/.local/lib/python3.7/site-packages/sqlalchemy/engine/base.py", line 3247, in _wrap_pool_connect
    e, dialect, self
  File "/home/airflow/.local/lib/python3.7/site-packages/sqlalchemy/engine/base.py", line 2101, in _handle_dbapi_exception_noconnection
    sqlalchemy_exception, with_traceback=exc_info[2], from_=e
  File "/home/airflow/.local/lib/python3.7/site-packages/sqlalchemy/util/compat.py", line 207, in raise_
    raise exception
  File "/home/airflow/.local/lib/python3.7/site-packages/sqlalchemy/engine/base.py", line 3243, in _wrap_pool_connect
    return fn()
  File "/home/airflow/.local/lib/python3.7/site-packages/sqlalchemy/pool/base.py", line 310, in connect
    return _ConnectionFairy._checkout(self)
  File "/home/airflow/.local/lib/python3.7/site-packages/sqlalchemy/pool/base.py", line 868, in _checkout
    fairy = _ConnectionRecord.checkout(pool)
  File "/home/airflow/.local/lib/python3.7/site-packages/sqlalchemy/pool/base.py", line 476, in checkout
    rec = pool._do_get()
  File "/home/airflow/.local/lib/python3.7/site-packages/sqlalchemy/pool/impl.py", line 146, in _do_get
    self._dec_overflow()
  File "/home/airflow/.local/lib/python3.7/site-packages/sqlalchemy/util/langhelpers.py", line 72, in __exit__
    with_traceback=exc_tb,
  File "/home/airflow/.local/lib/python3.7/site-packages/sqlalchemy/util/compat.py", line 207, in raise_
    raise exception
  File "/home/airflow/.local/lib/python3.7/site-packages/sqlalchemy/pool/impl.py", line 143, in _do_get
    return self._create_connection()
  File "/home/airflow/.local/lib/python3.7/site-packages/sqlalchemy/pool/base.py", line 256, in _create_connection
    return _ConnectionRecord(self)
  File "/home/airflow/.local/lib/python3.7/site-packages/sqlalchemy/pool/base.py", line 371, in __init__
    self.__connect()
  File "/home/airflow/.local/lib/python3.7/site-packages/sqlalchemy/pool/base.py", line 666, in __connect
    pool.logger.debug("Error on connect(): %s", e)
  File "/home/airflow/.local/lib/python3.7/site-packages/sqlalchemy/util/langhelpers.py", line 72, in __exit__
    with_traceback=exc_tb,
  File "/home/airflow/.local/lib/python3.7/site-packages/sqlalchemy/util/compat.py", line 207, in raise_
    raise exception
  File "/home/airflow/.local/lib/python3.7/site-packages/sqlalchemy/pool/base.py", line 661, in __connect
    self.dbapi_connection = connection = pool._invoke_creator(self)
  File "/home/airflow/.local/lib/python3.7/site-packages/sqlalchemy/engine/create.py", line 590, in connect
    return dialect.connect(*cargs, **cparams)
  File "/home/airflow/.local/lib/python3.7/site-packages/sqlalchemy/engine/default.py", line 584, in connect
    return self.dbapi.connect(*cargs, **cparams)
  File "/home/airflow/.local/lib/python3.7/site-packages/psycopg2/__init__.py", line 122, in connect
    conn = _connect(dsn, connection_factory=connection_factory, **kwasync)
sqlalchemy.exc.OperationalError: (psycopg2.OperationalError) could not translate host name "postgres" to address: Temporary failure in name resolution

(Background on this error at: https://sqlalche.me/e/14/e3q8)
[2024-05-24T11:57:50.345+0000] {processor.py:156} INFO - Started process (PID=157) to work on /opt/airflow/dags/airflow_first_dag.py
[2024-05-24T11:57:50.355+0000] {processor.py:758} INFO - Processing file /opt/airflow/dags/airflow_first_dag.py for tasks to queue
[2024-05-24T11:57:50.364+0000] {logging_mixin.py:117} INFO - [2024-05-24T11:57:50.361+0000] {dagbag.py:525} INFO - Filling up the DagBag from /opt/airflow/dags/airflow_first_dag.py
[2024-05-24T11:57:52.309+0000] {processor.py:768} INFO - DAG(s) dict_keys(['airflow_first_dag']) retrieved from /opt/airflow/dags/airflow_first_dag.py
[2024-05-24T11:58:38.941+0000] {processor.py:181} ERROR - Got an exception! Propagating...
Traceback (most recent call last):
  File "/home/airflow/.local/lib/python3.7/site-packages/sqlalchemy/engine/base.py", line 3243, in _wrap_pool_connect
    return fn()
  File "/home/airflow/.local/lib/python3.7/site-packages/sqlalchemy/pool/base.py", line 310, in connect
    return _ConnectionFairy._checkout(self)
  File "/home/airflow/.local/lib/python3.7/site-packages/sqlalchemy/pool/base.py", line 868, in _checkout
    fairy = _ConnectionRecord.checkout(pool)
  File "/home/airflow/.local/lib/python3.7/site-packages/sqlalchemy/pool/base.py", line 476, in checkout
    rec = pool._do_get()
  File "/home/airflow/.local/lib/python3.7/site-packages/sqlalchemy/pool/impl.py", line 146, in _do_get
    self._dec_overflow()
  File "/home/airflow/.local/lib/python3.7/site-packages/sqlalchemy/util/langhelpers.py", line 72, in __exit__
    with_traceback=exc_tb,
  File "/home/airflow/.local/lib/python3.7/site-packages/sqlalchemy/util/compat.py", line 207, in raise_
    raise exception
  File "/home/airflow/.local/lib/python3.7/site-packages/sqlalchemy/pool/impl.py", line 143, in _do_get
    return self._create_connection()
  File "/home/airflow/.local/lib/python3.7/site-packages/sqlalchemy/pool/base.py", line 256, in _create_connection
    return _ConnectionRecord(self)
  File "/home/airflow/.local/lib/python3.7/site-packages/sqlalchemy/pool/base.py", line 371, in __init__
    self.__connect()
  File "/home/airflow/.local/lib/python3.7/site-packages/sqlalchemy/pool/base.py", line 666, in __connect
    pool.logger.debug("Error on connect(): %s", e)
  File "/home/airflow/.local/lib/python3.7/site-packages/sqlalchemy/util/langhelpers.py", line 72, in __exit__
    with_traceback=exc_tb,
  File "/home/airflow/.local/lib/python3.7/site-packages/sqlalchemy/util/compat.py", line 207, in raise_
    raise exception
  File "/home/airflow/.local/lib/python3.7/site-packages/sqlalchemy/pool/base.py", line 661, in __connect
    self.dbapi_connection = connection = pool._invoke_creator(self)
  File "/home/airflow/.local/lib/python3.7/site-packages/sqlalchemy/engine/create.py", line 590, in connect
    return dialect.connect(*cargs, **cparams)
  File "/home/airflow/.local/lib/python3.7/site-packages/sqlalchemy/engine/default.py", line 584, in connect
    return self.dbapi.connect(*cargs, **cparams)
  File "/home/airflow/.local/lib/python3.7/site-packages/psycopg2/__init__.py", line 122, in connect
    conn = _connect(dsn, connection_factory=connection_factory, **kwasync)
psycopg2.OperationalError: could not translate host name "postgres" to address: Temporary failure in name resolution


The above exception was the direct cause of the following exception:

Traceback (most recent call last):
  File "/home/airflow/.local/lib/python3.7/site-packages/airflow/dag_processing/processor.py", line 177, in _run_file_processor
    _handle_dag_file_processing()
  File "/home/airflow/.local/lib/python3.7/site-packages/airflow/dag_processing/processor.py", line 161, in _handle_dag_file_processing
    callback_requests=callback_requests,
  File "/home/airflow/.local/lib/python3.7/site-packages/airflow/utils/session.py", line 75, in wrapper
    return func(*args, session=session, **kwargs)
  File "/home/airflow/.local/lib/python3.7/site-packages/airflow/dag_processing/processor.py", line 783, in process_file
    dagbag.sync_to_db(processor_subdir=self._dag_directory, session=session)
  File "/home/airflow/.local/lib/python3.7/site-packages/airflow/utils/session.py", line 72, in wrapper
    return func(*args, **kwargs)
  File "/home/airflow/.local/lib/python3.7/site-packages/airflow/models/dagbag.py", line 632, in sync_to_db
    for attempt in run_with_db_retries(logger=self.log):
  File "/home/airflow/.local/lib/python3.7/site-packages/tenacity/__init__.py", line 384, in __iter__
    do = self.iter(retry_state=retry_state)
  File "/home/airflow/.local/lib/python3.7/site-packages/tenacity/__init__.py", line 362, in iter
    raise retry_exc.reraise()
  File "/home/airflow/.local/lib/python3.7/site-packages/tenacity/__init__.py", line 195, in reraise
    raise self.last_attempt.result()
  File "/usr/local/lib/python3.7/concurrent/futures/_base.py", line 428, in result
    return self.__get_result()
  File "/usr/local/lib/python3.7/concurrent/futures/_base.py", line 384, in __get_result
    raise self._exception
  File "/home/airflow/.local/lib/python3.7/site-packages/airflow/models/dagbag.py", line 644, in sync_to_db
    serialize_errors.extend(_serialize_dag_capturing_errors(dag, session))
  File "/home/airflow/.local/lib/python3.7/site-packages/airflow/models/dagbag.py", line 618, in _serialize_dag_capturing_errors
    session=session,
  File "/home/airflow/.local/lib/python3.7/site-packages/airflow/utils/session.py", line 72, in wrapper
    return func(*args, **kwargs)
  File "/home/airflow/.local/lib/python3.7/site-packages/airflow/models/serialized_dag.py", line 150, in write_dag
    (timezone.utcnow() - timedelta(seconds=min_update_interval)) < cls.last_updated,
  File "/home/airflow/.local/lib/python3.7/site-packages/sqlalchemy/orm/query.py", line 2810, in first
    return self.limit(1)._iter().first()
  File "/home/airflow/.local/lib/python3.7/site-packages/sqlalchemy/orm/query.py", line 2897, in _iter
    execution_options={"_sa_orm_load_options": self.load_options},
  File "/home/airflow/.local/lib/python3.7/site-packages/sqlalchemy/orm/session.py", line 1688, in execute
    conn = self._connection_for_bind(bind)
  File "/home/airflow/.local/lib/python3.7/site-packages/sqlalchemy/orm/session.py", line 1530, in _connection_for_bind
    engine, execution_options
  File "/home/airflow/.local/lib/python3.7/site-packages/sqlalchemy/orm/session.py", line 747, in _connection_for_bind
    conn = bind.connect()
  File "/home/airflow/.local/lib/python3.7/site-packages/sqlalchemy/engine/base.py", line 3197, in connect
    return self._connection_cls(self, close_with_result=close_with_result)
  File "/home/airflow/.local/lib/python3.7/site-packages/sqlalchemy/engine/base.py", line 96, in __init__
    else engine.raw_connection()
  File "/home/airflow/.local/lib/python3.7/site-packages/sqlalchemy/engine/base.py", line 3276, in raw_connection
    return self._wrap_pool_connect(self.pool.connect, _connection)
  File "/home/airflow/.local/lib/python3.7/site-packages/sqlalchemy/engine/base.py", line 3247, in _wrap_pool_connect
    e, dialect, self
  File "/home/airflow/.local/lib/python3.7/site-packages/sqlalchemy/engine/base.py", line 2101, in _handle_dbapi_exception_noconnection
    sqlalchemy_exception, with_traceback=exc_info[2], from_=e
  File "/home/airflow/.local/lib/python3.7/site-packages/sqlalchemy/util/compat.py", line 207, in raise_
    raise exception
  File "/home/airflow/.local/lib/python3.7/site-packages/sqlalchemy/engine/base.py", line 3243, in _wrap_pool_connect
    return fn()
  File "/home/airflow/.local/lib/python3.7/site-packages/sqlalchemy/pool/base.py", line 310, in connect
    return _ConnectionFairy._checkout(self)
  File "/home/airflow/.local/lib/python3.7/site-packages/sqlalchemy/pool/base.py", line 868, in _checkout
    fairy = _ConnectionRecord.checkout(pool)
  File "/home/airflow/.local/lib/python3.7/site-packages/sqlalchemy/pool/base.py", line 476, in checkout
    rec = pool._do_get()
  File "/home/airflow/.local/lib/python3.7/site-packages/sqlalchemy/pool/impl.py", line 146, in _do_get
    self._dec_overflow()
  File "/home/airflow/.local/lib/python3.7/site-packages/sqlalchemy/util/langhelpers.py", line 72, in __exit__
    with_traceback=exc_tb,
  File "/home/airflow/.local/lib/python3.7/site-packages/sqlalchemy/util/compat.py", line 207, in raise_
    raise exception
  File "/home/airflow/.local/lib/python3.7/site-packages/sqlalchemy/pool/impl.py", line 143, in _do_get
    return self._create_connection()
  File "/home/airflow/.local/lib/python3.7/site-packages/sqlalchemy/pool/base.py", line 256, in _create_connection
    return _ConnectionRecord(self)
  File "/home/airflow/.local/lib/python3.7/site-packages/sqlalchemy/pool/base.py", line 371, in __init__
    self.__connect()
  File "/home/airflow/.local/lib/python3.7/site-packages/sqlalchemy/pool/base.py", line 666, in __connect
    pool.logger.debug("Error on connect(): %s", e)
  File "/home/airflow/.local/lib/python3.7/site-packages/sqlalchemy/util/langhelpers.py", line 72, in __exit__
    with_traceback=exc_tb,
  File "/home/airflow/.local/lib/python3.7/site-packages/sqlalchemy/util/compat.py", line 207, in raise_
    raise exception
  File "/home/airflow/.local/lib/python3.7/site-packages/sqlalchemy/pool/base.py", line 661, in __connect
    self.dbapi_connection = connection = pool._invoke_creator(self)
  File "/home/airflow/.local/lib/python3.7/site-packages/sqlalchemy/engine/create.py", line 590, in connect
    return dialect.connect(*cargs, **cparams)
  File "/home/airflow/.local/lib/python3.7/site-packages/sqlalchemy/engine/default.py", line 584, in connect
    return self.dbapi.connect(*cargs, **cparams)
  File "/home/airflow/.local/lib/python3.7/site-packages/psycopg2/__init__.py", line 122, in connect
    conn = _connect(dsn, connection_factory=connection_factory, **kwasync)
sqlalchemy.exc.OperationalError: (psycopg2.OperationalError) could not translate host name "postgres" to address: Temporary failure in name resolution

(Background on this error at: https://sqlalche.me/e/14/e3q8)
[2024-05-24T11:59:12.152+0000] {processor.py:156} INFO - Started process (PID=159) to work on /opt/airflow/dags/airflow_first_dag.py
[2024-05-24T11:59:12.163+0000] {processor.py:758} INFO - Processing file /opt/airflow/dags/airflow_first_dag.py for tasks to queue
[2024-05-24T11:59:12.367+0000] {logging_mixin.py:117} INFO - [2024-05-24T11:59:12.258+0000] {dagbag.py:525} INFO - Filling up the DagBag from /opt/airflow/dags/airflow_first_dag.py
[2024-05-24T11:59:18.037+0000] {processor.py:768} INFO - DAG(s) dict_keys(['airflow_first_dag']) retrieved from /opt/airflow/dags/airflow_first_dag.py
[2024-05-24T11:59:55.560+0000] {processor.py:181} ERROR - Got an exception! Propagating...
Traceback (most recent call last):
  File "/home/airflow/.local/lib/python3.7/site-packages/sqlalchemy/engine/base.py", line 3243, in _wrap_pool_connect
    return fn()
  File "/home/airflow/.local/lib/python3.7/site-packages/sqlalchemy/pool/base.py", line 310, in connect
    return _ConnectionFairy._checkout(self)
  File "/home/airflow/.local/lib/python3.7/site-packages/sqlalchemy/pool/base.py", line 868, in _checkout
    fairy = _ConnectionRecord.checkout(pool)
  File "/home/airflow/.local/lib/python3.7/site-packages/sqlalchemy/pool/base.py", line 476, in checkout
    rec = pool._do_get()
  File "/home/airflow/.local/lib/python3.7/site-packages/sqlalchemy/pool/impl.py", line 146, in _do_get
    self._dec_overflow()
  File "/home/airflow/.local/lib/python3.7/site-packages/sqlalchemy/util/langhelpers.py", line 72, in __exit__
    with_traceback=exc_tb,
  File "/home/airflow/.local/lib/python3.7/site-packages/sqlalchemy/util/compat.py", line 207, in raise_
    raise exception
  File "/home/airflow/.local/lib/python3.7/site-packages/sqlalchemy/pool/impl.py", line 143, in _do_get
    return self._create_connection()
  File "/home/airflow/.local/lib/python3.7/site-packages/sqlalchemy/pool/base.py", line 256, in _create_connection
    return _ConnectionRecord(self)
  File "/home/airflow/.local/lib/python3.7/site-packages/sqlalchemy/pool/base.py", line 371, in __init__
    self.__connect()
  File "/home/airflow/.local/lib/python3.7/site-packages/sqlalchemy/pool/base.py", line 666, in __connect
    pool.logger.debug("Error on connect(): %s", e)
  File "/home/airflow/.local/lib/python3.7/site-packages/sqlalchemy/util/langhelpers.py", line 72, in __exit__
    with_traceback=exc_tb,
  File "/home/airflow/.local/lib/python3.7/site-packages/sqlalchemy/util/compat.py", line 207, in raise_
    raise exception
  File "/home/airflow/.local/lib/python3.7/site-packages/sqlalchemy/pool/base.py", line 661, in __connect
    self.dbapi_connection = connection = pool._invoke_creator(self)
  File "/home/airflow/.local/lib/python3.7/site-packages/sqlalchemy/engine/create.py", line 590, in connect
    return dialect.connect(*cargs, **cparams)
  File "/home/airflow/.local/lib/python3.7/site-packages/sqlalchemy/engine/default.py", line 584, in connect
    return self.dbapi.connect(*cargs, **cparams)
  File "/home/airflow/.local/lib/python3.7/site-packages/psycopg2/__init__.py", line 122, in connect
    conn = _connect(dsn, connection_factory=connection_factory, **kwasync)
psycopg2.OperationalError: could not translate host name "postgres" to address: Temporary failure in name resolution


The above exception was the direct cause of the following exception:

Traceback (most recent call last):
  File "/home/airflow/.local/lib/python3.7/site-packages/airflow/dag_processing/processor.py", line 177, in _run_file_processor
    _handle_dag_file_processing()
  File "/home/airflow/.local/lib/python3.7/site-packages/airflow/dag_processing/processor.py", line 161, in _handle_dag_file_processing
    callback_requests=callback_requests,
  File "/home/airflow/.local/lib/python3.7/site-packages/airflow/utils/session.py", line 75, in wrapper
    return func(*args, session=session, **kwargs)
  File "/home/airflow/.local/lib/python3.7/site-packages/airflow/dag_processing/processor.py", line 783, in process_file
    dagbag.sync_to_db(processor_subdir=self._dag_directory, session=session)
  File "/home/airflow/.local/lib/python3.7/site-packages/airflow/utils/session.py", line 72, in wrapper
    return func(*args, **kwargs)
  File "/home/airflow/.local/lib/python3.7/site-packages/airflow/models/dagbag.py", line 632, in sync_to_db
    for attempt in run_with_db_retries(logger=self.log):
  File "/home/airflow/.local/lib/python3.7/site-packages/tenacity/__init__.py", line 384, in __iter__
    do = self.iter(retry_state=retry_state)
  File "/home/airflow/.local/lib/python3.7/site-packages/tenacity/__init__.py", line 362, in iter
    raise retry_exc.reraise()
  File "/home/airflow/.local/lib/python3.7/site-packages/tenacity/__init__.py", line 195, in reraise
    raise self.last_attempt.result()
  File "/usr/local/lib/python3.7/concurrent/futures/_base.py", line 428, in result
    return self.__get_result()
  File "/usr/local/lib/python3.7/concurrent/futures/_base.py", line 384, in __get_result
    raise self._exception
  File "/home/airflow/.local/lib/python3.7/site-packages/airflow/models/dagbag.py", line 644, in sync_to_db
    serialize_errors.extend(_serialize_dag_capturing_errors(dag, session))
  File "/home/airflow/.local/lib/python3.7/site-packages/airflow/models/dagbag.py", line 618, in _serialize_dag_capturing_errors
    session=session,
  File "/home/airflow/.local/lib/python3.7/site-packages/airflow/utils/session.py", line 72, in wrapper
    return func(*args, **kwargs)
  File "/home/airflow/.local/lib/python3.7/site-packages/airflow/models/serialized_dag.py", line 150, in write_dag
    (timezone.utcnow() - timedelta(seconds=min_update_interval)) < cls.last_updated,
  File "/home/airflow/.local/lib/python3.7/site-packages/sqlalchemy/orm/query.py", line 2810, in first
    return self.limit(1)._iter().first()
  File "/home/airflow/.local/lib/python3.7/site-packages/sqlalchemy/orm/query.py", line 2897, in _iter
    execution_options={"_sa_orm_load_options": self.load_options},
  File "/home/airflow/.local/lib/python3.7/site-packages/sqlalchemy/orm/session.py", line 1688, in execute
    conn = self._connection_for_bind(bind)
  File "/home/airflow/.local/lib/python3.7/site-packages/sqlalchemy/orm/session.py", line 1530, in _connection_for_bind
    engine, execution_options
  File "/home/airflow/.local/lib/python3.7/site-packages/sqlalchemy/orm/session.py", line 747, in _connection_for_bind
    conn = bind.connect()
  File "/home/airflow/.local/lib/python3.7/site-packages/sqlalchemy/engine/base.py", line 3197, in connect
    return self._connection_cls(self, close_with_result=close_with_result)
  File "/home/airflow/.local/lib/python3.7/site-packages/sqlalchemy/engine/base.py", line 96, in __init__
    else engine.raw_connection()
  File "/home/airflow/.local/lib/python3.7/site-packages/sqlalchemy/engine/base.py", line 3276, in raw_connection
    return self._wrap_pool_connect(self.pool.connect, _connection)
  File "/home/airflow/.local/lib/python3.7/site-packages/sqlalchemy/engine/base.py", line 3247, in _wrap_pool_connect
    e, dialect, self
  File "/home/airflow/.local/lib/python3.7/site-packages/sqlalchemy/engine/base.py", line 2101, in _handle_dbapi_exception_noconnection
    sqlalchemy_exception, with_traceback=exc_info[2], from_=e
  File "/home/airflow/.local/lib/python3.7/site-packages/sqlalchemy/util/compat.py", line 207, in raise_
    raise exception
  File "/home/airflow/.local/lib/python3.7/site-packages/sqlalchemy/engine/base.py", line 3243, in _wrap_pool_connect
    return fn()
  File "/home/airflow/.local/lib/python3.7/site-packages/sqlalchemy/pool/base.py", line 310, in connect
    return _ConnectionFairy._checkout(self)
  File "/home/airflow/.local/lib/python3.7/site-packages/sqlalchemy/pool/base.py", line 868, in _checkout
    fairy = _ConnectionRecord.checkout(pool)
  File "/home/airflow/.local/lib/python3.7/site-packages/sqlalchemy/pool/base.py", line 476, in checkout
    rec = pool._do_get()
  File "/home/airflow/.local/lib/python3.7/site-packages/sqlalchemy/pool/impl.py", line 146, in _do_get
    self._dec_overflow()
  File "/home/airflow/.local/lib/python3.7/site-packages/sqlalchemy/util/langhelpers.py", line 72, in __exit__
    with_traceback=exc_tb,
  File "/home/airflow/.local/lib/python3.7/site-packages/sqlalchemy/util/compat.py", line 207, in raise_
    raise exception
  File "/home/airflow/.local/lib/python3.7/site-packages/sqlalchemy/pool/impl.py", line 143, in _do_get
    return self._create_connection()
  File "/home/airflow/.local/lib/python3.7/site-packages/sqlalchemy/pool/base.py", line 256, in _create_connection
    return _ConnectionRecord(self)
  File "/home/airflow/.local/lib/python3.7/site-packages/sqlalchemy/pool/base.py", line 371, in __init__
    self.__connect()
  File "/home/airflow/.local/lib/python3.7/site-packages/sqlalchemy/pool/base.py", line 666, in __connect
    pool.logger.debug("Error on connect(): %s", e)
  File "/home/airflow/.local/lib/python3.7/site-packages/sqlalchemy/util/langhelpers.py", line 72, in __exit__
    with_traceback=exc_tb,
  File "/home/airflow/.local/lib/python3.7/site-packages/sqlalchemy/util/compat.py", line 207, in raise_
    raise exception
  File "/home/airflow/.local/lib/python3.7/site-packages/sqlalchemy/pool/base.py", line 661, in __connect
    self.dbapi_connection = connection = pool._invoke_creator(self)
  File "/home/airflow/.local/lib/python3.7/site-packages/sqlalchemy/engine/create.py", line 590, in connect
    return dialect.connect(*cargs, **cparams)
  File "/home/airflow/.local/lib/python3.7/site-packages/sqlalchemy/engine/default.py", line 584, in connect
    return self.dbapi.connect(*cargs, **cparams)
  File "/home/airflow/.local/lib/python3.7/site-packages/psycopg2/__init__.py", line 122, in connect
    conn = _connect(dsn, connection_factory=connection_factory, **kwasync)
sqlalchemy.exc.OperationalError: (psycopg2.OperationalError) could not translate host name "postgres" to address: Temporary failure in name resolution

(Background on this error at: https://sqlalche.me/e/14/e3q8)
[2024-05-24T12:00:03.918+0000] {processor.py:156} INFO - Started process (PID=162) to work on /opt/airflow/dags/airflow_first_dag.py
[2024-05-24T12:00:03.943+0000] {processor.py:758} INFO - Processing file /opt/airflow/dags/airflow_first_dag.py for tasks to queue
[2024-05-24T12:00:03.948+0000] {logging_mixin.py:117} INFO - [2024-05-24T12:00:03.948+0000] {dagbag.py:525} INFO - Filling up the DagBag from /opt/airflow/dags/airflow_first_dag.py
[2024-05-24T12:00:11.953+0000] {processor.py:768} INFO - DAG(s) dict_keys(['airflow_first_dag']) retrieved from /opt/airflow/dags/airflow_first_dag.py
[2024-05-24T12:00:44.402+0000] {processor.py:181} ERROR - Got an exception! Propagating...
Traceback (most recent call last):
  File "/home/airflow/.local/lib/python3.7/site-packages/sqlalchemy/engine/base.py", line 3243, in _wrap_pool_connect
    return fn()
  File "/home/airflow/.local/lib/python3.7/site-packages/sqlalchemy/pool/base.py", line 310, in connect
    return _ConnectionFairy._checkout(self)
  File "/home/airflow/.local/lib/python3.7/site-packages/sqlalchemy/pool/base.py", line 868, in _checkout
    fairy = _ConnectionRecord.checkout(pool)
  File "/home/airflow/.local/lib/python3.7/site-packages/sqlalchemy/pool/base.py", line 476, in checkout
    rec = pool._do_get()
  File "/home/airflow/.local/lib/python3.7/site-packages/sqlalchemy/pool/impl.py", line 146, in _do_get
    self._dec_overflow()
  File "/home/airflow/.local/lib/python3.7/site-packages/sqlalchemy/util/langhelpers.py", line 72, in __exit__
    with_traceback=exc_tb,
  File "/home/airflow/.local/lib/python3.7/site-packages/sqlalchemy/util/compat.py", line 207, in raise_
    raise exception
  File "/home/airflow/.local/lib/python3.7/site-packages/sqlalchemy/pool/impl.py", line 143, in _do_get
    return self._create_connection()
  File "/home/airflow/.local/lib/python3.7/site-packages/sqlalchemy/pool/base.py", line 256, in _create_connection
    return _ConnectionRecord(self)
  File "/home/airflow/.local/lib/python3.7/site-packages/sqlalchemy/pool/base.py", line 371, in __init__
    self.__connect()
  File "/home/airflow/.local/lib/python3.7/site-packages/sqlalchemy/pool/base.py", line 666, in __connect
    pool.logger.debug("Error on connect(): %s", e)
  File "/home/airflow/.local/lib/python3.7/site-packages/sqlalchemy/util/langhelpers.py", line 72, in __exit__
    with_traceback=exc_tb,
  File "/home/airflow/.local/lib/python3.7/site-packages/sqlalchemy/util/compat.py", line 207, in raise_
    raise exception
  File "/home/airflow/.local/lib/python3.7/site-packages/sqlalchemy/pool/base.py", line 661, in __connect
    self.dbapi_connection = connection = pool._invoke_creator(self)
  File "/home/airflow/.local/lib/python3.7/site-packages/sqlalchemy/engine/create.py", line 590, in connect
    return dialect.connect(*cargs, **cparams)
  File "/home/airflow/.local/lib/python3.7/site-packages/sqlalchemy/engine/default.py", line 584, in connect
    return self.dbapi.connect(*cargs, **cparams)
  File "/home/airflow/.local/lib/python3.7/site-packages/psycopg2/__init__.py", line 122, in connect
    conn = _connect(dsn, connection_factory=connection_factory, **kwasync)
psycopg2.OperationalError: could not translate host name "postgres" to address: Temporary failure in name resolution


The above exception was the direct cause of the following exception:

Traceback (most recent call last):
  File "/home/airflow/.local/lib/python3.7/site-packages/airflow/dag_processing/processor.py", line 177, in _run_file_processor
    _handle_dag_file_processing()
  File "/home/airflow/.local/lib/python3.7/site-packages/airflow/dag_processing/processor.py", line 161, in _handle_dag_file_processing
    callback_requests=callback_requests,
  File "/home/airflow/.local/lib/python3.7/site-packages/airflow/utils/session.py", line 75, in wrapper
    return func(*args, session=session, **kwargs)
  File "/home/airflow/.local/lib/python3.7/site-packages/airflow/dag_processing/processor.py", line 783, in process_file
    dagbag.sync_to_db(processor_subdir=self._dag_directory, session=session)
  File "/home/airflow/.local/lib/python3.7/site-packages/airflow/utils/session.py", line 72, in wrapper
    return func(*args, **kwargs)
  File "/home/airflow/.local/lib/python3.7/site-packages/airflow/models/dagbag.py", line 632, in sync_to_db
    for attempt in run_with_db_retries(logger=self.log):
  File "/home/airflow/.local/lib/python3.7/site-packages/tenacity/__init__.py", line 384, in __iter__
    do = self.iter(retry_state=retry_state)
  File "/home/airflow/.local/lib/python3.7/site-packages/tenacity/__init__.py", line 362, in iter
    raise retry_exc.reraise()
  File "/home/airflow/.local/lib/python3.7/site-packages/tenacity/__init__.py", line 195, in reraise
    raise self.last_attempt.result()
  File "/usr/local/lib/python3.7/concurrent/futures/_base.py", line 428, in result
    return self.__get_result()
  File "/usr/local/lib/python3.7/concurrent/futures/_base.py", line 384, in __get_result
    raise self._exception
  File "/home/airflow/.local/lib/python3.7/site-packages/airflow/models/dagbag.py", line 644, in sync_to_db
    serialize_errors.extend(_serialize_dag_capturing_errors(dag, session))
  File "/home/airflow/.local/lib/python3.7/site-packages/airflow/models/dagbag.py", line 618, in _serialize_dag_capturing_errors
    session=session,
  File "/home/airflow/.local/lib/python3.7/site-packages/airflow/utils/session.py", line 72, in wrapper
    return func(*args, **kwargs)
  File "/home/airflow/.local/lib/python3.7/site-packages/airflow/models/serialized_dag.py", line 150, in write_dag
    (timezone.utcnow() - timedelta(seconds=min_update_interval)) < cls.last_updated,
  File "/home/airflow/.local/lib/python3.7/site-packages/sqlalchemy/orm/query.py", line 2810, in first
    return self.limit(1)._iter().first()
  File "/home/airflow/.local/lib/python3.7/site-packages/sqlalchemy/orm/query.py", line 2897, in _iter
    execution_options={"_sa_orm_load_options": self.load_options},
  File "/home/airflow/.local/lib/python3.7/site-packages/sqlalchemy/orm/session.py", line 1688, in execute
    conn = self._connection_for_bind(bind)
  File "/home/airflow/.local/lib/python3.7/site-packages/sqlalchemy/orm/session.py", line 1530, in _connection_for_bind
    engine, execution_options
  File "/home/airflow/.local/lib/python3.7/site-packages/sqlalchemy/orm/session.py", line 747, in _connection_for_bind
    conn = bind.connect()
  File "/home/airflow/.local/lib/python3.7/site-packages/sqlalchemy/engine/base.py", line 3197, in connect
    return self._connection_cls(self, close_with_result=close_with_result)
  File "/home/airflow/.local/lib/python3.7/site-packages/sqlalchemy/engine/base.py", line 96, in __init__
    else engine.raw_connection()
  File "/home/airflow/.local/lib/python3.7/site-packages/sqlalchemy/engine/base.py", line 3276, in raw_connection
    return self._wrap_pool_connect(self.pool.connect, _connection)
  File "/home/airflow/.local/lib/python3.7/site-packages/sqlalchemy/engine/base.py", line 3247, in _wrap_pool_connect
    e, dialect, self
  File "/home/airflow/.local/lib/python3.7/site-packages/sqlalchemy/engine/base.py", line 2101, in _handle_dbapi_exception_noconnection
    sqlalchemy_exception, with_traceback=exc_info[2], from_=e
  File "/home/airflow/.local/lib/python3.7/site-packages/sqlalchemy/util/compat.py", line 207, in raise_
    raise exception
  File "/home/airflow/.local/lib/python3.7/site-packages/sqlalchemy/engine/base.py", line 3243, in _wrap_pool_connect
    return fn()
  File "/home/airflow/.local/lib/python3.7/site-packages/sqlalchemy/pool/base.py", line 310, in connect
    return _ConnectionFairy._checkout(self)
  File "/home/airflow/.local/lib/python3.7/site-packages/sqlalchemy/pool/base.py", line 868, in _checkout
    fairy = _ConnectionRecord.checkout(pool)
  File "/home/airflow/.local/lib/python3.7/site-packages/sqlalchemy/pool/base.py", line 476, in checkout
    rec = pool._do_get()
  File "/home/airflow/.local/lib/python3.7/site-packages/sqlalchemy/pool/impl.py", line 146, in _do_get
    self._dec_overflow()
  File "/home/airflow/.local/lib/python3.7/site-packages/sqlalchemy/util/langhelpers.py", line 72, in __exit__
    with_traceback=exc_tb,
  File "/home/airflow/.local/lib/python3.7/site-packages/sqlalchemy/util/compat.py", line 207, in raise_
    raise exception
  File "/home/airflow/.local/lib/python3.7/site-packages/sqlalchemy/pool/impl.py", line 143, in _do_get
    return self._create_connection()
  File "/home/airflow/.local/lib/python3.7/site-packages/sqlalchemy/pool/base.py", line 256, in _create_connection
    return _ConnectionRecord(self)
  File "/home/airflow/.local/lib/python3.7/site-packages/sqlalchemy/pool/base.py", line 371, in __init__
    self.__connect()
  File "/home/airflow/.local/lib/python3.7/site-packages/sqlalchemy/pool/base.py", line 666, in __connect
    pool.logger.debug("Error on connect(): %s", e)
  File "/home/airflow/.local/lib/python3.7/site-packages/sqlalchemy/util/langhelpers.py", line 72, in __exit__
    with_traceback=exc_tb,
  File "/home/airflow/.local/lib/python3.7/site-packages/sqlalchemy/util/compat.py", line 207, in raise_
    raise exception
  File "/home/airflow/.local/lib/python3.7/site-packages/sqlalchemy/pool/base.py", line 661, in __connect
    self.dbapi_connection = connection = pool._invoke_creator(self)
  File "/home/airflow/.local/lib/python3.7/site-packages/sqlalchemy/engine/create.py", line 590, in connect
    return dialect.connect(*cargs, **cparams)
  File "/home/airflow/.local/lib/python3.7/site-packages/sqlalchemy/engine/default.py", line 584, in connect
    return self.dbapi.connect(*cargs, **cparams)
  File "/home/airflow/.local/lib/python3.7/site-packages/psycopg2/__init__.py", line 122, in connect
    conn = _connect(dsn, connection_factory=connection_factory, **kwasync)
sqlalchemy.exc.OperationalError: (psycopg2.OperationalError) could not translate host name "postgres" to address: Temporary failure in name resolution

(Background on this error at: https://sqlalche.me/e/14/e3q8)
[2024-05-24T12:01:52.545+0000] {processor.py:156} INFO - Started process (PID=166) to work on /opt/airflow/dags/airflow_first_dag.py
[2024-05-24T12:01:52.548+0000] {processor.py:758} INFO - Processing file /opt/airflow/dags/airflow_first_dag.py for tasks to queue
[2024-05-24T12:01:52.550+0000] {logging_mixin.py:117} INFO - [2024-05-24T12:01:52.549+0000] {dagbag.py:525} INFO - Filling up the DagBag from /opt/airflow/dags/airflow_first_dag.py
[2024-05-24T12:02:02.955+0000] {processor.py:768} INFO - DAG(s) dict_keys(['airflow_first_dag']) retrieved from /opt/airflow/dags/airflow_first_dag.py
[2024-05-24T12:02:38.437+0000] {processor.py:181} ERROR - Got an exception! Propagating...
Traceback (most recent call last):
  File "/home/airflow/.local/lib/python3.7/site-packages/sqlalchemy/engine/base.py", line 3243, in _wrap_pool_connect
    return fn()
  File "/home/airflow/.local/lib/python3.7/site-packages/sqlalchemy/pool/base.py", line 310, in connect
    return _ConnectionFairy._checkout(self)
  File "/home/airflow/.local/lib/python3.7/site-packages/sqlalchemy/pool/base.py", line 868, in _checkout
    fairy = _ConnectionRecord.checkout(pool)
  File "/home/airflow/.local/lib/python3.7/site-packages/sqlalchemy/pool/base.py", line 476, in checkout
    rec = pool._do_get()
  File "/home/airflow/.local/lib/python3.7/site-packages/sqlalchemy/pool/impl.py", line 146, in _do_get
    self._dec_overflow()
  File "/home/airflow/.local/lib/python3.7/site-packages/sqlalchemy/util/langhelpers.py", line 72, in __exit__
    with_traceback=exc_tb,
  File "/home/airflow/.local/lib/python3.7/site-packages/sqlalchemy/util/compat.py", line 207, in raise_
    raise exception
  File "/home/airflow/.local/lib/python3.7/site-packages/sqlalchemy/pool/impl.py", line 143, in _do_get
    return self._create_connection()
  File "/home/airflow/.local/lib/python3.7/site-packages/sqlalchemy/pool/base.py", line 256, in _create_connection
    return _ConnectionRecord(self)
  File "/home/airflow/.local/lib/python3.7/site-packages/sqlalchemy/pool/base.py", line 371, in __init__
    self.__connect()
  File "/home/airflow/.local/lib/python3.7/site-packages/sqlalchemy/pool/base.py", line 666, in __connect
    pool.logger.debug("Error on connect(): %s", e)
  File "/home/airflow/.local/lib/python3.7/site-packages/sqlalchemy/util/langhelpers.py", line 72, in __exit__
    with_traceback=exc_tb,
  File "/home/airflow/.local/lib/python3.7/site-packages/sqlalchemy/util/compat.py", line 207, in raise_
    raise exception
  File "/home/airflow/.local/lib/python3.7/site-packages/sqlalchemy/pool/base.py", line 661, in __connect
    self.dbapi_connection = connection = pool._invoke_creator(self)
  File "/home/airflow/.local/lib/python3.7/site-packages/sqlalchemy/engine/create.py", line 590, in connect
    return dialect.connect(*cargs, **cparams)
  File "/home/airflow/.local/lib/python3.7/site-packages/sqlalchemy/engine/default.py", line 584, in connect
    return self.dbapi.connect(*cargs, **cparams)
  File "/home/airflow/.local/lib/python3.7/site-packages/psycopg2/__init__.py", line 122, in connect
    conn = _connect(dsn, connection_factory=connection_factory, **kwasync)
psycopg2.OperationalError: could not translate host name "postgres" to address: Temporary failure in name resolution


The above exception was the direct cause of the following exception:

Traceback (most recent call last):
  File "/home/airflow/.local/lib/python3.7/site-packages/airflow/dag_processing/processor.py", line 177, in _run_file_processor
    _handle_dag_file_processing()
  File "/home/airflow/.local/lib/python3.7/site-packages/airflow/dag_processing/processor.py", line 161, in _handle_dag_file_processing
    callback_requests=callback_requests,
  File "/home/airflow/.local/lib/python3.7/site-packages/airflow/utils/session.py", line 75, in wrapper
    return func(*args, session=session, **kwargs)
  File "/home/airflow/.local/lib/python3.7/site-packages/airflow/dag_processing/processor.py", line 783, in process_file
    dagbag.sync_to_db(processor_subdir=self._dag_directory, session=session)
  File "/home/airflow/.local/lib/python3.7/site-packages/airflow/utils/session.py", line 72, in wrapper
    return func(*args, **kwargs)
  File "/home/airflow/.local/lib/python3.7/site-packages/airflow/models/dagbag.py", line 632, in sync_to_db
    for attempt in run_with_db_retries(logger=self.log):
  File "/home/airflow/.local/lib/python3.7/site-packages/tenacity/__init__.py", line 384, in __iter__
    do = self.iter(retry_state=retry_state)
  File "/home/airflow/.local/lib/python3.7/site-packages/tenacity/__init__.py", line 362, in iter
    raise retry_exc.reraise()
  File "/home/airflow/.local/lib/python3.7/site-packages/tenacity/__init__.py", line 195, in reraise
    raise self.last_attempt.result()
  File "/usr/local/lib/python3.7/concurrent/futures/_base.py", line 428, in result
    return self.__get_result()
  File "/usr/local/lib/python3.7/concurrent/futures/_base.py", line 384, in __get_result
    raise self._exception
  File "/home/airflow/.local/lib/python3.7/site-packages/airflow/models/dagbag.py", line 644, in sync_to_db
    serialize_errors.extend(_serialize_dag_capturing_errors(dag, session))
  File "/home/airflow/.local/lib/python3.7/site-packages/airflow/models/dagbag.py", line 618, in _serialize_dag_capturing_errors
    session=session,
  File "/home/airflow/.local/lib/python3.7/site-packages/airflow/utils/session.py", line 72, in wrapper
    return func(*args, **kwargs)
  File "/home/airflow/.local/lib/python3.7/site-packages/airflow/models/serialized_dag.py", line 150, in write_dag
    (timezone.utcnow() - timedelta(seconds=min_update_interval)) < cls.last_updated,
  File "/home/airflow/.local/lib/python3.7/site-packages/sqlalchemy/orm/query.py", line 2810, in first
    return self.limit(1)._iter().first()
  File "/home/airflow/.local/lib/python3.7/site-packages/sqlalchemy/orm/query.py", line 2897, in _iter
    execution_options={"_sa_orm_load_options": self.load_options},
  File "/home/airflow/.local/lib/python3.7/site-packages/sqlalchemy/orm/session.py", line 1688, in execute
    conn = self._connection_for_bind(bind)
  File "/home/airflow/.local/lib/python3.7/site-packages/sqlalchemy/orm/session.py", line 1530, in _connection_for_bind
    engine, execution_options
  File "/home/airflow/.local/lib/python3.7/site-packages/sqlalchemy/orm/session.py", line 747, in _connection_for_bind
    conn = bind.connect()
  File "/home/airflow/.local/lib/python3.7/site-packages/sqlalchemy/engine/base.py", line 3197, in connect
    return self._connection_cls(self, close_with_result=close_with_result)
  File "/home/airflow/.local/lib/python3.7/site-packages/sqlalchemy/engine/base.py", line 96, in __init__
    else engine.raw_connection()
  File "/home/airflow/.local/lib/python3.7/site-packages/sqlalchemy/engine/base.py", line 3276, in raw_connection
    return self._wrap_pool_connect(self.pool.connect, _connection)
  File "/home/airflow/.local/lib/python3.7/site-packages/sqlalchemy/engine/base.py", line 3247, in _wrap_pool_connect
    e, dialect, self
  File "/home/airflow/.local/lib/python3.7/site-packages/sqlalchemy/engine/base.py", line 2101, in _handle_dbapi_exception_noconnection
    sqlalchemy_exception, with_traceback=exc_info[2], from_=e
  File "/home/airflow/.local/lib/python3.7/site-packages/sqlalchemy/util/compat.py", line 207, in raise_
    raise exception
  File "/home/airflow/.local/lib/python3.7/site-packages/sqlalchemy/engine/base.py", line 3243, in _wrap_pool_connect
    return fn()
  File "/home/airflow/.local/lib/python3.7/site-packages/sqlalchemy/pool/base.py", line 310, in connect
    return _ConnectionFairy._checkout(self)
  File "/home/airflow/.local/lib/python3.7/site-packages/sqlalchemy/pool/base.py", line 868, in _checkout
    fairy = _ConnectionRecord.checkout(pool)
  File "/home/airflow/.local/lib/python3.7/site-packages/sqlalchemy/pool/base.py", line 476, in checkout
    rec = pool._do_get()
  File "/home/airflow/.local/lib/python3.7/site-packages/sqlalchemy/pool/impl.py", line 146, in _do_get
    self._dec_overflow()
  File "/home/airflow/.local/lib/python3.7/site-packages/sqlalchemy/util/langhelpers.py", line 72, in __exit__
    with_traceback=exc_tb,
  File "/home/airflow/.local/lib/python3.7/site-packages/sqlalchemy/util/compat.py", line 207, in raise_
    raise exception
  File "/home/airflow/.local/lib/python3.7/site-packages/sqlalchemy/pool/impl.py", line 143, in _do_get
    return self._create_connection()
  File "/home/airflow/.local/lib/python3.7/site-packages/sqlalchemy/pool/base.py", line 256, in _create_connection
    return _ConnectionRecord(self)
  File "/home/airflow/.local/lib/python3.7/site-packages/sqlalchemy/pool/base.py", line 371, in __init__
    self.__connect()
  File "/home/airflow/.local/lib/python3.7/site-packages/sqlalchemy/pool/base.py", line 666, in __connect
    pool.logger.debug("Error on connect(): %s", e)
  File "/home/airflow/.local/lib/python3.7/site-packages/sqlalchemy/util/langhelpers.py", line 72, in __exit__
    with_traceback=exc_tb,
  File "/home/airflow/.local/lib/python3.7/site-packages/sqlalchemy/util/compat.py", line 207, in raise_
    raise exception
  File "/home/airflow/.local/lib/python3.7/site-packages/sqlalchemy/pool/base.py", line 661, in __connect
    self.dbapi_connection = connection = pool._invoke_creator(self)
  File "/home/airflow/.local/lib/python3.7/site-packages/sqlalchemy/engine/create.py", line 590, in connect
    return dialect.connect(*cargs, **cparams)
  File "/home/airflow/.local/lib/python3.7/site-packages/sqlalchemy/engine/default.py", line 584, in connect
    return self.dbapi.connect(*cargs, **cparams)
  File "/home/airflow/.local/lib/python3.7/site-packages/psycopg2/__init__.py", line 122, in connect
    conn = _connect(dsn, connection_factory=connection_factory, **kwasync)
sqlalchemy.exc.OperationalError: (psycopg2.OperationalError) could not translate host name "postgres" to address: Temporary failure in name resolution

(Background on this error at: https://sqlalche.me/e/14/e3q8)
[2024-05-24T12:03:23.594+0000] {processor.py:156} INFO - Started process (PID=169) to work on /opt/airflow/dags/airflow_first_dag.py
[2024-05-24T12:03:23.595+0000] {processor.py:758} INFO - Processing file /opt/airflow/dags/airflow_first_dag.py for tasks to queue
[2024-05-24T12:03:23.595+0000] {logging_mixin.py:117} INFO - [2024-05-24T12:03:23.595+0000] {dagbag.py:525} INFO - Filling up the DagBag from /opt/airflow/dags/airflow_first_dag.py
[2024-05-24T12:03:23.686+0000] {processor.py:768} INFO - DAG(s) dict_keys(['airflow_first_dag']) retrieved from /opt/airflow/dags/airflow_first_dag.py
[2024-05-24T12:03:57.033+0000] {processor.py:181} ERROR - Got an exception! Propagating...
Traceback (most recent call last):
  File "/home/airflow/.local/lib/python3.7/site-packages/sqlalchemy/engine/base.py", line 3243, in _wrap_pool_connect
    return fn()
  File "/home/airflow/.local/lib/python3.7/site-packages/sqlalchemy/pool/base.py", line 310, in connect
    return _ConnectionFairy._checkout(self)
  File "/home/airflow/.local/lib/python3.7/site-packages/sqlalchemy/pool/base.py", line 868, in _checkout
    fairy = _ConnectionRecord.checkout(pool)
  File "/home/airflow/.local/lib/python3.7/site-packages/sqlalchemy/pool/base.py", line 476, in checkout
    rec = pool._do_get()
  File "/home/airflow/.local/lib/python3.7/site-packages/sqlalchemy/pool/impl.py", line 146, in _do_get
    self._dec_overflow()
  File "/home/airflow/.local/lib/python3.7/site-packages/sqlalchemy/util/langhelpers.py", line 72, in __exit__
    with_traceback=exc_tb,
  File "/home/airflow/.local/lib/python3.7/site-packages/sqlalchemy/util/compat.py", line 207, in raise_
    raise exception
  File "/home/airflow/.local/lib/python3.7/site-packages/sqlalchemy/pool/impl.py", line 143, in _do_get
    return self._create_connection()
  File "/home/airflow/.local/lib/python3.7/site-packages/sqlalchemy/pool/base.py", line 256, in _create_connection
    return _ConnectionRecord(self)
  File "/home/airflow/.local/lib/python3.7/site-packages/sqlalchemy/pool/base.py", line 371, in __init__
    self.__connect()
  File "/home/airflow/.local/lib/python3.7/site-packages/sqlalchemy/pool/base.py", line 666, in __connect
    pool.logger.debug("Error on connect(): %s", e)
  File "/home/airflow/.local/lib/python3.7/site-packages/sqlalchemy/util/langhelpers.py", line 72, in __exit__
    with_traceback=exc_tb,
  File "/home/airflow/.local/lib/python3.7/site-packages/sqlalchemy/util/compat.py", line 207, in raise_
    raise exception
  File "/home/airflow/.local/lib/python3.7/site-packages/sqlalchemy/pool/base.py", line 661, in __connect
    self.dbapi_connection = connection = pool._invoke_creator(self)
  File "/home/airflow/.local/lib/python3.7/site-packages/sqlalchemy/engine/create.py", line 590, in connect
    return dialect.connect(*cargs, **cparams)
  File "/home/airflow/.local/lib/python3.7/site-packages/sqlalchemy/engine/default.py", line 584, in connect
    return self.dbapi.connect(*cargs, **cparams)
  File "/home/airflow/.local/lib/python3.7/site-packages/psycopg2/__init__.py", line 122, in connect
    conn = _connect(dsn, connection_factory=connection_factory, **kwasync)
psycopg2.OperationalError: could not translate host name "postgres" to address: Temporary failure in name resolution


The above exception was the direct cause of the following exception:

Traceback (most recent call last):
  File "/home/airflow/.local/lib/python3.7/site-packages/airflow/dag_processing/processor.py", line 177, in _run_file_processor
    _handle_dag_file_processing()
  File "/home/airflow/.local/lib/python3.7/site-packages/airflow/dag_processing/processor.py", line 161, in _handle_dag_file_processing
    callback_requests=callback_requests,
  File "/home/airflow/.local/lib/python3.7/site-packages/airflow/utils/session.py", line 75, in wrapper
    return func(*args, session=session, **kwargs)
  File "/home/airflow/.local/lib/python3.7/site-packages/airflow/dag_processing/processor.py", line 783, in process_file
    dagbag.sync_to_db(processor_subdir=self._dag_directory, session=session)
  File "/home/airflow/.local/lib/python3.7/site-packages/airflow/utils/session.py", line 72, in wrapper
    return func(*args, **kwargs)
  File "/home/airflow/.local/lib/python3.7/site-packages/airflow/models/dagbag.py", line 632, in sync_to_db
    for attempt in run_with_db_retries(logger=self.log):
  File "/home/airflow/.local/lib/python3.7/site-packages/tenacity/__init__.py", line 384, in __iter__
    do = self.iter(retry_state=retry_state)
  File "/home/airflow/.local/lib/python3.7/site-packages/tenacity/__init__.py", line 362, in iter
    raise retry_exc.reraise()
  File "/home/airflow/.local/lib/python3.7/site-packages/tenacity/__init__.py", line 195, in reraise
    raise self.last_attempt.result()
  File "/usr/local/lib/python3.7/concurrent/futures/_base.py", line 428, in result
    return self.__get_result()
  File "/usr/local/lib/python3.7/concurrent/futures/_base.py", line 384, in __get_result
    raise self._exception
  File "/home/airflow/.local/lib/python3.7/site-packages/airflow/models/dagbag.py", line 644, in sync_to_db
    serialize_errors.extend(_serialize_dag_capturing_errors(dag, session))
  File "/home/airflow/.local/lib/python3.7/site-packages/airflow/models/dagbag.py", line 618, in _serialize_dag_capturing_errors
    session=session,
  File "/home/airflow/.local/lib/python3.7/site-packages/airflow/utils/session.py", line 72, in wrapper
    return func(*args, **kwargs)
  File "/home/airflow/.local/lib/python3.7/site-packages/airflow/models/serialized_dag.py", line 150, in write_dag
    (timezone.utcnow() - timedelta(seconds=min_update_interval)) < cls.last_updated,
  File "/home/airflow/.local/lib/python3.7/site-packages/sqlalchemy/orm/query.py", line 2810, in first
    return self.limit(1)._iter().first()
  File "/home/airflow/.local/lib/python3.7/site-packages/sqlalchemy/orm/query.py", line 2897, in _iter
    execution_options={"_sa_orm_load_options": self.load_options},
  File "/home/airflow/.local/lib/python3.7/site-packages/sqlalchemy/orm/session.py", line 1688, in execute
    conn = self._connection_for_bind(bind)
  File "/home/airflow/.local/lib/python3.7/site-packages/sqlalchemy/orm/session.py", line 1530, in _connection_for_bind
    engine, execution_options
  File "/home/airflow/.local/lib/python3.7/site-packages/sqlalchemy/orm/session.py", line 747, in _connection_for_bind
    conn = bind.connect()
  File "/home/airflow/.local/lib/python3.7/site-packages/sqlalchemy/engine/base.py", line 3197, in connect
    return self._connection_cls(self, close_with_result=close_with_result)
  File "/home/airflow/.local/lib/python3.7/site-packages/sqlalchemy/engine/base.py", line 96, in __init__
    else engine.raw_connection()
  File "/home/airflow/.local/lib/python3.7/site-packages/sqlalchemy/engine/base.py", line 3276, in raw_connection
    return self._wrap_pool_connect(self.pool.connect, _connection)
  File "/home/airflow/.local/lib/python3.7/site-packages/sqlalchemy/engine/base.py", line 3247, in _wrap_pool_connect
    e, dialect, self
  File "/home/airflow/.local/lib/python3.7/site-packages/sqlalchemy/engine/base.py", line 2101, in _handle_dbapi_exception_noconnection
    sqlalchemy_exception, with_traceback=exc_info[2], from_=e
  File "/home/airflow/.local/lib/python3.7/site-packages/sqlalchemy/util/compat.py", line 207, in raise_
    raise exception
  File "/home/airflow/.local/lib/python3.7/site-packages/sqlalchemy/engine/base.py", line 3243, in _wrap_pool_connect
    return fn()
  File "/home/airflow/.local/lib/python3.7/site-packages/sqlalchemy/pool/base.py", line 310, in connect
    return _ConnectionFairy._checkout(self)
  File "/home/airflow/.local/lib/python3.7/site-packages/sqlalchemy/pool/base.py", line 868, in _checkout
    fairy = _ConnectionRecord.checkout(pool)
  File "/home/airflow/.local/lib/python3.7/site-packages/sqlalchemy/pool/base.py", line 476, in checkout
    rec = pool._do_get()
  File "/home/airflow/.local/lib/python3.7/site-packages/sqlalchemy/pool/impl.py", line 146, in _do_get
    self._dec_overflow()
  File "/home/airflow/.local/lib/python3.7/site-packages/sqlalchemy/util/langhelpers.py", line 72, in __exit__
    with_traceback=exc_tb,
  File "/home/airflow/.local/lib/python3.7/site-packages/sqlalchemy/util/compat.py", line 207, in raise_
    raise exception
  File "/home/airflow/.local/lib/python3.7/site-packages/sqlalchemy/pool/impl.py", line 143, in _do_get
    return self._create_connection()
  File "/home/airflow/.local/lib/python3.7/site-packages/sqlalchemy/pool/base.py", line 256, in _create_connection
    return _ConnectionRecord(self)
  File "/home/airflow/.local/lib/python3.7/site-packages/sqlalchemy/pool/base.py", line 371, in __init__
    self.__connect()
  File "/home/airflow/.local/lib/python3.7/site-packages/sqlalchemy/pool/base.py", line 666, in __connect
    pool.logger.debug("Error on connect(): %s", e)
  File "/home/airflow/.local/lib/python3.7/site-packages/sqlalchemy/util/langhelpers.py", line 72, in __exit__
    with_traceback=exc_tb,
  File "/home/airflow/.local/lib/python3.7/site-packages/sqlalchemy/util/compat.py", line 207, in raise_
    raise exception
  File "/home/airflow/.local/lib/python3.7/site-packages/sqlalchemy/pool/base.py", line 661, in __connect
    self.dbapi_connection = connection = pool._invoke_creator(self)
  File "/home/airflow/.local/lib/python3.7/site-packages/sqlalchemy/engine/create.py", line 590, in connect
    return dialect.connect(*cargs, **cparams)
  File "/home/airflow/.local/lib/python3.7/site-packages/sqlalchemy/engine/default.py", line 584, in connect
    return self.dbapi.connect(*cargs, **cparams)
  File "/home/airflow/.local/lib/python3.7/site-packages/psycopg2/__init__.py", line 122, in connect
    conn = _connect(dsn, connection_factory=connection_factory, **kwasync)
sqlalchemy.exc.OperationalError: (psycopg2.OperationalError) could not translate host name "postgres" to address: Temporary failure in name resolution

(Background on this error at: https://sqlalche.me/e/14/e3q8)
[2024-05-24T12:06:44.937+0000] {processor.py:156} INFO - Started process (PID=43) to work on /opt/airflow/dags/airflow_first_dag.py
[2024-05-24T12:06:44.938+0000] {processor.py:758} INFO - Processing file /opt/airflow/dags/airflow_first_dag.py for tasks to queue
[2024-05-24T12:06:44.939+0000] {logging_mixin.py:117} INFO - [2024-05-24T12:06:44.939+0000] {dagbag.py:525} INFO - Filling up the DagBag from /opt/airflow/dags/airflow_first_dag.py
[2024-05-24T12:06:45.026+0000] {processor.py:768} INFO - DAG(s) dict_keys(['airflow_first_dag']) retrieved from /opt/airflow/dags/airflow_first_dag.py
[2024-05-24T12:09:18.357+0000] {processor.py:156} INFO - Started process (PID=46) to work on /opt/airflow/dags/airflow_first_dag.py
[2024-05-24T12:09:18.360+0000] {processor.py:758} INFO - Processing file /opt/airflow/dags/airflow_first_dag.py for tasks to queue
[2024-05-24T12:09:18.361+0000] {logging_mixin.py:117} INFO - [2024-05-24T12:09:18.360+0000] {dagbag.py:525} INFO - Filling up the DagBag from /opt/airflow/dags/airflow_first_dag.py
[2024-05-24T12:09:18.987+0000] {processor.py:768} INFO - DAG(s) dict_keys(['airflow_first_dag']) retrieved from /opt/airflow/dags/airflow_first_dag.py
